2025-08-22 10:54:37,714: INFO: main: Alhumdullillah sb okay h boss!
[2025-08-22 11:12:50,758: INFO: main: Alhumdullillah sb okay h boss!]
[2025-08-22 18:53:12,075: ERROR: main: name 'STAGE_NAME' is not defined]
Traceback (most recent call last):
  File "C:\Users\ABDULLAH RIZWAN\OneDrive\Desktop\Data Sciences\MLOPS\DataScienceProject\main.py", line 5, in <module>
    logger.info(f'>>>>> stage {STAGE_NAME} started >>>>>')
                               ^^^^^^^^^^
NameError: name 'STAGE_NAME' is not defined
[2025-08-22 18:53:42,782: INFO: main: >>>>> stage Data Ingestion Stage started >>>>>]
[2025-08-22 18:53:42,783: ERROR: main: Argument path_to_yaml of type <class 'pathlib.WindowsPath'> to <function read_yaml at 0x000002A1D73D00E0> does not match annotation type <class 'str'>]
Traceback (most recent call last):
  File "C:\Users\ABDULLAH RIZWAN\OneDrive\Desktop\Data Sciences\MLOPS\DataScienceProject\main.py", line 11, in <module>
    obj.initiate_data_ingestion()
  File "C:\Users\ABDULLAH RIZWAN\OneDrive\Desktop\Data Sciences\MLOPS\DataScienceProject\src\DataScienceProject\pipeline\DataIngestionPipeline.py", line 13, in initiate_data_ingestion
    config = ConfigurationManager()
           ^^^^^^^^^^^^^^^^^^^^^^
  File "C:\Users\ABDULLAH RIZWAN\OneDrive\Desktop\Data Sciences\MLOPS\DataScienceProject\src\DataScienceProject\config\configuration.py", line 12, in __init__
    self.config = read_yaml(config_filepath)
                  ^^^^^^^^^^^^^^^^^^^^^^^^^^
  File "C:\Users\ABDULLAH RIZWAN\OneDrive\Desktop\Data Sciences\MLOPS\DataScienceProject\.venv\Lib\site-packages\ensure\main.py", line 870, in __call__
    raise EnsureError(msg.format(arg=arg, f=self.f, t=templ, valt=type(value)))
ensure.main.EnsureError: Argument path_to_yaml of type <class 'pathlib.WindowsPath'> to <function read_yaml at 0x000002A1D73D00E0> does not match annotation type <class 'str'>
[2025-08-22 18:54:16,466: INFO: main: >>>>> stage Data Ingestion Stage started >>>>>]
[2025-08-22 18:54:16,467: ERROR: main: Argument path_to_yaml of type <class 'pathlib.WindowsPath'> to <function read_yaml at 0x00000262903A00E0> does not match annotation type <class 'str'>]
Traceback (most recent call last):
  File "C:\Users\ABDULLAH RIZWAN\OneDrive\Desktop\Data Sciences\MLOPS\DataScienceProject\main.py", line 11, in <module>
    obj.initiate_data_ingestion()
  File "C:\Users\ABDULLAH RIZWAN\OneDrive\Desktop\Data Sciences\MLOPS\DataScienceProject\src\DataScienceProject\pipeline\DataIngestionPipeline.py", line 13, in initiate_data_ingestion
    config = ConfigurationManager()
           ^^^^^^^^^^^^^^^^^^^^^^
  File "C:\Users\ABDULLAH RIZWAN\OneDrive\Desktop\Data Sciences\MLOPS\DataScienceProject\src\DataScienceProject\config\configuration.py", line 12, in __init__
    self.config = read_yaml(config_filepath)
                  ^^^^^^^^^^^^^^^^^^^^^^^^^^
  File "C:\Users\ABDULLAH RIZWAN\OneDrive\Desktop\Data Sciences\MLOPS\DataScienceProject\.venv\Lib\site-packages\ensure\main.py", line 870, in __call__
    raise EnsureError(msg.format(arg=arg, f=self.f, t=templ, valt=type(value)))
ensure.main.EnsureError: Argument path_to_yaml of type <class 'pathlib.WindowsPath'> to <function read_yaml at 0x00000262903A00E0> does not match annotation type <class 'str'>
[2025-08-22 18:55:32,743: INFO: main: >>>>> stage Data Ingestion Stage started >>>>>]
[2025-08-22 18:55:32,747: INFO: common: Yaml file: config\config.yaml is loaded successfully]
[2025-08-22 18:55:32,749: INFO: common: Yaml file: params.yaml is loaded successfully]
[2025-08-22 18:55:32,750: INFO: common: Yaml file: params.yaml is loaded successfully]
[2025-08-22 18:55:32,751: ERROR: main: create_directories() missing 1 required positional argument: 'verbose']
Traceback (most recent call last):
  File "C:\Users\ABDULLAH RIZWAN\OneDrive\Desktop\Data Sciences\MLOPS\DataScienceProject\main.py", line 11, in <module>
    obj.initiate_data_ingestion()
  File "C:\Users\ABDULLAH RIZWAN\OneDrive\Desktop\Data Sciences\MLOPS\DataScienceProject\src\DataScienceProject\pipeline\DataIngestionPipeline.py", line 13, in initiate_data_ingestion
    config = ConfigurationManager()
           ^^^^^^^^^^^^^^^^^^^^^^
  File "C:\Users\ABDULLAH RIZWAN\OneDrive\Desktop\Data Sciences\MLOPS\DataScienceProject\src\DataScienceProject\config\configuration.py", line 16, in __init__
    create_directories([self.config.artifacts_root])
  File "C:\Users\ABDULLAH RIZWAN\OneDrive\Desktop\Data Sciences\MLOPS\DataScienceProject\.venv\Lib\site-packages\ensure\main.py", line 835, in __call__
    return self.f(*args, **kwargs)
           ^^^^^^^^^^^^^^^^^^^^^^^
TypeError: create_directories() missing 1 required positional argument: 'verbose'
[2025-08-22 18:56:17,830: INFO: main: >>>>> stage Data Ingestion Stage started >>>>>]
[2025-08-22 18:56:17,838: INFO: common: Yaml file: config\config.yaml is loaded successfully]
[2025-08-22 18:56:17,896: INFO: common: Yaml file: params.yaml is loaded successfully]
[2025-08-22 18:56:17,971: INFO: common: Yaml file: params.yaml is loaded successfully]
[2025-08-22 18:56:18,049: ERROR: common: makedirs() got an unexpected keyword argument 'exists_ok']
Traceback (most recent call last):
  File "C:\Users\ABDULLAH RIZWAN\OneDrive\Desktop\Data Sciences\MLOPS\DataScienceProject\src\DataScienceProject\utils\common.py", line 30, in create_directories
    os.makedirs(path_to_directory,exists_ok=True)
TypeError: makedirs() got an unexpected keyword argument 'exists_ok'
[2025-08-22 18:56:18,084: ERROR: main: makedirs() got an unexpected keyword argument 'exists_ok']
Traceback (most recent call last):
  File "C:\Users\ABDULLAH RIZWAN\OneDrive\Desktop\Data Sciences\MLOPS\DataScienceProject\main.py", line 11, in <module>
    obj.initiate_data_ingestion()
  File "C:\Users\ABDULLAH RIZWAN\OneDrive\Desktop\Data Sciences\MLOPS\DataScienceProject\src\DataScienceProject\pipeline\DataIngestionPipeline.py", line 13, in initiate_data_ingestion
    config = ConfigurationManager()
           ^^^^^^^^^^^^^^^^^^^^^^
  File "C:\Users\ABDULLAH RIZWAN\OneDrive\Desktop\Data Sciences\MLOPS\DataScienceProject\src\DataScienceProject\config\configuration.py", line 17, in __init__
    create_directories([self.config.artifacts_root],verbose=True)
  File "C:\Users\ABDULLAH RIZWAN\OneDrive\Desktop\Data Sciences\MLOPS\DataScienceProject\.venv\Lib\site-packages\ensure\main.py", line 835, in __call__
    return self.f(*args, **kwargs)
           ^^^^^^^^^^^^^^^^^^^^^^^
  File "C:\Users\ABDULLAH RIZWAN\OneDrive\Desktop\Data Sciences\MLOPS\DataScienceProject\src\DataScienceProject\utils\common.py", line 35, in create_directories
    raise e
  File "C:\Users\ABDULLAH RIZWAN\OneDrive\Desktop\Data Sciences\MLOPS\DataScienceProject\src\DataScienceProject\utils\common.py", line 30, in create_directories
    os.makedirs(path_to_directory,exists_ok=True)
TypeError: makedirs() got an unexpected keyword argument 'exists_ok'
[2025-08-22 18:57:24,332: INFO: main: >>>>> stage Data Ingestion Stage started >>>>>]
[2025-08-22 18:57:24,350: INFO: common: Yaml file: config\config.yaml is loaded successfully]
[2025-08-22 18:57:24,398: INFO: common: Yaml file: params.yaml is loaded successfully]
[2025-08-22 18:57:24,412: INFO: common: Yaml file: params.yaml is loaded successfully]
[2025-08-22 18:57:24,471: INFO: common: Directory created at artifacts]
[2025-08-22 18:57:24,507: INFO: common: Directory created at artifacts/data_ingestion]
[2025-08-22 18:57:26,189: INFO: data_ingestion: File artifacts/data_ingestion/data.zip downloaded with the following info: Date: Fri, 22 Aug 2025 13:57:26 GMT
Content-Type: text/html; charset=utf-8
Vary: X-PJAX, X-PJAX-Container, Turbo-Visit, Turbo-Frame, X-Requested-With,Accept-Encoding, Accept, X-Requested-With
x-repository-download: git clone https://github.com/krishnaik06/datasets.git
x-raw-download: https://raw.githubusercontent.com/krishnaik06/datasets/main/winequality-data.zip
ETag: W/"bcf64efea65b22e585040a6027ed0ae4"
Cache-Control: max-age=0, private, must-revalidate
Strict-Transport-Security: max-age=31536000; includeSubdomains; preload
X-Frame-Options: deny
X-Content-Type-Options: nosniff
X-XSS-Protection: 0
Referrer-Policy: no-referrer-when-downgrade
Content-Security-Policy: default-src 'none'; base-uri 'self'; child-src github.githubassets.com github.com/assets-cdn/worker/ github.com/assets/ gist.github.com/assets-cdn/worker/; connect-src 'self' uploads.github.com www.githubstatus.com collector.github.com raw.githubusercontent.com api.github.com github-cloud.s3.amazonaws.com github-production-repository-file-5c1aeb.s3.amazonaws.com github-production-upload-manifest-file-7fdce7.s3.amazonaws.com github-production-user-asset-6210df.s3.amazonaws.com *.rel.tunnels.api.visualstudio.com wss://*.rel.tunnels.api.visualstudio.com objects-origin.githubusercontent.com copilot-proxy.githubusercontent.com proxy.individual.githubcopilot.com proxy.business.githubcopilot.com proxy.enterprise.githubcopilot.com *.actions.githubusercontent.com wss://*.actions.githubusercontent.com productionresultssa0.blob.core.windows.net/ productionresultssa1.blob.core.windows.net/ productionresultssa2.blob.core.windows.net/ productionresultssa3.blob.core.windows.net/ productionresultssa4.blob.core.windows.net/ productionresultssa5.blob.core.windows.net/ productionresultssa6.blob.core.windows.net/ productionresultssa7.blob.core.windows.net/ productionresultssa8.blob.core.windows.net/ productionresultssa9.blob.core.windows.net/ productionresultssa10.blob.core.windows.net/ productionresultssa11.blob.core.windows.net/ productionresultssa12.blob.core.windows.net/ productionresultssa13.blob.core.windows.net/ productionresultssa14.blob.core.windows.net/ productionresultssa15.blob.core.windows.net/ productionresultssa16.blob.core.windows.net/ productionresultssa17.blob.core.windows.net/ productionresultssa18.blob.core.windows.net/ productionresultssa19.blob.core.windows.net/ github-production-repository-image-32fea6.s3.amazonaws.com github-production-release-asset-2e65be.s3.amazonaws.com insights.github.com wss://alive.github.com wss://alive-staging.github.com api.githubcopilot.com api.individual.githubcopilot.com api.business.githubcopilot.com api.enterprise.githubcopilot.com; font-src github.githubassets.com; form-action 'self' github.com gist.github.com copilot-workspace.githubnext.com objects-origin.githubusercontent.com; frame-ancestors 'none'; frame-src viewscreen.githubusercontent.com notebooks.githubusercontent.com; img-src 'self' data: blob: github.githubassets.com media.githubusercontent.com camo.githubusercontent.com identicons.github.com avatars.githubusercontent.com private-avatars.githubusercontent.com github-cloud.s3.amazonaws.com objects.githubusercontent.com release-assets.githubusercontent.com secured-user-images.githubusercontent.com/ user-images.githubusercontent.com/ private-user-images.githubusercontent.com opengraph.githubassets.com copilotprodattachments.blob.core.windows.net/github-production-copilot-attachments/ github-production-user-asset-6210df.s3.amazonaws.com customer-stories-feed.github.com spotlights-feed.github.com objects-origin.githubusercontent.com *.githubusercontent.com; manifest-src 'self'; media-src github.com user-images.githubusercontent.com/ secured-user-images.githubusercontent.com/ private-user-images.githubusercontent.com github-production-user-asset-6210df.s3.amazonaws.com gist.github.com; script-src github.githubassets.com; style-src 'unsafe-inline' github.githubassets.com; upgrade-insecure-requests; worker-src github.githubassets.com github.com/assets-cdn/worker/ github.com/assets/ gist.github.com/assets-cdn/worker/
Server: github.com
Accept-Ranges: bytes
Set-Cookie: _gh_sess=iPCuXkNqhagPgJXWaV0m5tJneS4KRJdcFEYjT5%2FRQWqGD%2B6Vxv0egaeXoD7eAlHRUuhznc3NiOIOGH%2FK%2BEHMC4NEtnvavzmbSRtyLTt%2FtBf45jIul%2FHjv0DdNekA1TngPvIyhzO431puJ1qBrqN%2B8g2DZM0SUfA4NxC7mrP8VOfGED3CJCaKKTKh5NcBhWyfdsAIyodPuZbUQz%2Bd1FvorwxZnssURCrQvwh8VxJ1Bq9wKZh9Owp9KR78UgLp%2FX3gQps5APqcz0sIWU%2FJfQeLCQ%3D%3D--fkpBtf6pptNgygQW--SxFWBBBFnwntwRqE7YwZgQ%3D%3D; Path=/; HttpOnly; Secure; SameSite=Lax
Set-Cookie: _octo=GH1.1.801944078.1755871045; Path=/; Domain=github.com; Expires=Sat, 22 Aug 2026 13:57:25 GMT; Secure; SameSite=Lax
Set-Cookie: logged_in=no; Path=/; Domain=github.com; Expires=Sat, 22 Aug 2026 13:57:25 GMT; HttpOnly; Secure; SameSite=Lax
X-GitHub-Request-Id: 42EE:10A146:5130D0:5AB093:68A87745
connection: close
Transfer-Encoding: chunked

]
[2025-08-22 18:57:26,464: ERROR: main: File is not a zip file]
Traceback (most recent call last):
  File "C:\Users\ABDULLAH RIZWAN\OneDrive\Desktop\Data Sciences\MLOPS\DataScienceProject\main.py", line 11, in <module>
    obj.initiate_data_ingestion()
  File "C:\Users\ABDULLAH RIZWAN\OneDrive\Desktop\Data Sciences\MLOPS\DataScienceProject\src\DataScienceProject\pipeline\DataIngestionPipeline.py", line 17, in initiate_data_ingestion
    data_ingestion.extract_zip_file()
  File "C:\Users\ABDULLAH RIZWAN\OneDrive\Desktop\Data Sciences\MLOPS\DataScienceProject\src\DataScienceProject\components\data_ingestion.py", line 23, in extract_zip_file
    with zipfile.ZipFile(self.config.local_data_file, 'r') as zip_ref:
         ^^^^^^^^^^^^^^^^^^^^^^^^^^^^^^^^^^^^^^^^^^^^^^^^^
  File "D:\anaconda\Lib\zipfile.py", line 1302, in __init__
    self._RealGetContents()
  File "D:\anaconda\Lib\zipfile.py", line 1369, in _RealGetContents
    raise BadZipFile("File is not a zip file")
zipfile.BadZipFile: File is not a zip file
[2025-08-22 19:00:56,598: INFO: main: >>>>> stage Data Ingestion Stage started >>>>>]
[2025-08-22 19:00:56,608: INFO: common: Yaml file: config\config.yaml is loaded successfully]
[2025-08-22 19:00:56,621: INFO: common: Yaml file: params.yaml is loaded successfully]
[2025-08-22 19:00:56,623: INFO: common: Yaml file: params.yaml is loaded successfully]
[2025-08-22 19:00:56,626: INFO: common: Directory created at artifacts]
[2025-08-22 19:00:56,628: INFO: common: Directory created at artifacts/data_ingestion]
[2025-08-22 19:00:58,809: INFO: data_ingestion: File artifacts/data_ingestion/data.zip downloaded with the following info: Date: Fri, 22 Aug 2025 14:00:58 GMT
Content-Type: text/html; charset=utf-8
Vary: X-PJAX, X-PJAX-Container, Turbo-Visit, Turbo-Frame, X-Requested-With,Accept-Encoding, Accept, X-Requested-With
x-repository-download: git clone https://github.com/krishnaik06/datasets.git
x-raw-download: https://raw.githubusercontent.com/krishnaik06/datasets/main/winequality-data.zip
ETag: W/"0cc843f32dea9ba3f05e3f5b3dee26b8"
Cache-Control: max-age=0, private, must-revalidate
Strict-Transport-Security: max-age=31536000; includeSubdomains; preload
X-Frame-Options: deny
X-Content-Type-Options: nosniff
X-XSS-Protection: 0
Referrer-Policy: no-referrer-when-downgrade
Content-Security-Policy: default-src 'none'; base-uri 'self'; child-src github.githubassets.com github.com/assets-cdn/worker/ github.com/assets/ gist.github.com/assets-cdn/worker/; connect-src 'self' uploads.github.com www.githubstatus.com collector.github.com raw.githubusercontent.com api.github.com github-cloud.s3.amazonaws.com github-production-repository-file-5c1aeb.s3.amazonaws.com github-production-upload-manifest-file-7fdce7.s3.amazonaws.com github-production-user-asset-6210df.s3.amazonaws.com *.rel.tunnels.api.visualstudio.com wss://*.rel.tunnels.api.visualstudio.com objects-origin.githubusercontent.com copilot-proxy.githubusercontent.com proxy.individual.githubcopilot.com proxy.business.githubcopilot.com proxy.enterprise.githubcopilot.com *.actions.githubusercontent.com wss://*.actions.githubusercontent.com productionresultssa0.blob.core.windows.net/ productionresultssa1.blob.core.windows.net/ productionresultssa2.blob.core.windows.net/ productionresultssa3.blob.core.windows.net/ productionresultssa4.blob.core.windows.net/ productionresultssa5.blob.core.windows.net/ productionresultssa6.blob.core.windows.net/ productionresultssa7.blob.core.windows.net/ productionresultssa8.blob.core.windows.net/ productionresultssa9.blob.core.windows.net/ productionresultssa10.blob.core.windows.net/ productionresultssa11.blob.core.windows.net/ productionresultssa12.blob.core.windows.net/ productionresultssa13.blob.core.windows.net/ productionresultssa14.blob.core.windows.net/ productionresultssa15.blob.core.windows.net/ productionresultssa16.blob.core.windows.net/ productionresultssa17.blob.core.windows.net/ productionresultssa18.blob.core.windows.net/ productionresultssa19.blob.core.windows.net/ github-production-repository-image-32fea6.s3.amazonaws.com github-production-release-asset-2e65be.s3.amazonaws.com insights.github.com wss://alive.github.com wss://alive-staging.github.com api.githubcopilot.com api.individual.githubcopilot.com api.business.githubcopilot.com api.enterprise.githubcopilot.com; font-src github.githubassets.com; form-action 'self' github.com gist.github.com copilot-workspace.githubnext.com objects-origin.githubusercontent.com; frame-ancestors 'none'; frame-src viewscreen.githubusercontent.com notebooks.githubusercontent.com; img-src 'self' data: blob: github.githubassets.com media.githubusercontent.com camo.githubusercontent.com identicons.github.com avatars.githubusercontent.com private-avatars.githubusercontent.com github-cloud.s3.amazonaws.com objects.githubusercontent.com release-assets.githubusercontent.com secured-user-images.githubusercontent.com/ user-images.githubusercontent.com/ private-user-images.githubusercontent.com opengraph.githubassets.com copilotprodattachments.blob.core.windows.net/github-production-copilot-attachments/ github-production-user-asset-6210df.s3.amazonaws.com customer-stories-feed.github.com spotlights-feed.github.com objects-origin.githubusercontent.com *.githubusercontent.com; manifest-src 'self'; media-src github.com user-images.githubusercontent.com/ secured-user-images.githubusercontent.com/ private-user-images.githubusercontent.com github-production-user-asset-6210df.s3.amazonaws.com gist.github.com; script-src github.githubassets.com; style-src 'unsafe-inline' github.githubassets.com; upgrade-insecure-requests; worker-src github.githubassets.com github.com/assets-cdn/worker/ github.com/assets/ gist.github.com/assets-cdn/worker/
Server: github.com
Accept-Ranges: bytes
Set-Cookie: _gh_sess=5zcfPGRLwbDlXq7wuriveV47jYb34sq%2BVimwkDDTBS6Q2Bzhw1W0lsdr4UqPRnb808uENSkO24tbZfHTeiI%2Bs82K7HJTcjec9a0H9GmtoLyMhaeG9vyo57Up%2Fishx1ClzagxyFsgaZxY8F5O0E2FF5X3Dn3w8Oge67IgeRLXaoSMZki7Iq1rRnu72%2B7VuByl6MGGoxJwRXEG9%2FuEozF4D9zJJ%2F8ZV1XmKQjh0egSOJxMapwdo7znHfvNzpI4XTCGiFsMbCWbwcLQvrNPvKvSVw%3D%3D--Li8QO5yywh%2FRC1Vm--OS49sw%2FlXUe%2FemFaEMO7Xw%3D%3D; Path=/; HttpOnly; Secure; SameSite=Lax
Set-Cookie: _octo=GH1.1.127869588.1755871258; Path=/; Domain=github.com; Expires=Sat, 22 Aug 2026 14:00:58 GMT; Secure; SameSite=Lax
Set-Cookie: logged_in=no; Path=/; Domain=github.com; Expires=Sat, 22 Aug 2026 14:00:58 GMT; HttpOnly; Secure; SameSite=Lax
X-GitHub-Request-Id: 4486:112C5C:514B22:5AE8E5:68A8781A
connection: close
Transfer-Encoding: chunked

]
[2025-08-22 19:00:59,018: ERROR: main: File is not a zip file]
Traceback (most recent call last):
  File "C:\Users\ABDULLAH RIZWAN\OneDrive\Desktop\Data Sciences\MLOPS\DataScienceProject\main.py", line 11, in <module>
    obj.initiate_data_ingestion()
  File "C:\Users\ABDULLAH RIZWAN\OneDrive\Desktop\Data Sciences\MLOPS\DataScienceProject\src\DataScienceProject\pipeline\DataIngestionPipeline.py", line 17, in initiate_data_ingestion
    data_ingestion.extract_zip_file()
  File "C:\Users\ABDULLAH RIZWAN\OneDrive\Desktop\Data Sciences\MLOPS\DataScienceProject\src\DataScienceProject\components\data_ingestion.py", line 23, in extract_zip_file
    with zipfile.ZipFile(self.config.local_data_file, 'r') as zip_ref:
         ^^^^^^^^^^^^^^^^^^^^^^^^^^^^^^^^^^^^^^^^^^^^^^^^^
  File "D:\anaconda\Lib\zipfile.py", line 1302, in __init__
    self._RealGetContents()
  File "D:\anaconda\Lib\zipfile.py", line 1369, in _RealGetContents
    raise BadZipFile("File is not a zip file")
zipfile.BadZipFile: File is not a zip file
[2025-08-23 07:55:15,599: INFO: main: >>>>> stage Data Ingestion Stage started >>>>>]
[2025-08-23 07:55:15,628: INFO: common: Yaml file: config\config.yaml is loaded successfully]
[2025-08-23 07:55:15,658: INFO: common: Yaml file: params.yaml is loaded successfully]
[2025-08-23 07:55:15,660: INFO: common: Yaml file: params.yaml is loaded successfully]
[2025-08-23 07:55:15,662: INFO: common: Directory created at artifacts]
[2025-08-23 07:55:15,663: INFO: common: Directory created at artifacts/data_ingestion]
[2025-08-23 07:55:16,821: INFO: data_ingestion: File artifacts/data_ingestion/data.zip downloaded with the following info: Date: Sat, 23 Aug 2025 02:55:17 GMT
Content-Type: text/html; charset=utf-8
Vary: X-PJAX, X-PJAX-Container, Turbo-Visit, Turbo-Frame, X-Requested-With,Accept-Encoding, Accept, X-Requested-With
x-repository-download: git clone https://github.com/krishnaik06/datasets.git
x-raw-download: https://raw.githubusercontent.com/krishnaik06/datasets/main/winequality-data.zip
ETag: W/"d02f71ae949a04b1ca27149ab7e0ea53"
Cache-Control: max-age=0, private, must-revalidate
Strict-Transport-Security: max-age=31536000; includeSubdomains; preload
X-Frame-Options: deny
X-Content-Type-Options: nosniff
X-XSS-Protection: 0
Referrer-Policy: no-referrer-when-downgrade
Content-Security-Policy: default-src 'none'; base-uri 'self'; child-src github.githubassets.com github.com/assets-cdn/worker/ github.com/assets/ gist.github.com/assets-cdn/worker/; connect-src 'self' uploads.github.com www.githubstatus.com collector.github.com raw.githubusercontent.com api.github.com github-cloud.s3.amazonaws.com github-production-repository-file-5c1aeb.s3.amazonaws.com github-production-upload-manifest-file-7fdce7.s3.amazonaws.com github-production-user-asset-6210df.s3.amazonaws.com *.rel.tunnels.api.visualstudio.com wss://*.rel.tunnels.api.visualstudio.com objects-origin.githubusercontent.com copilot-proxy.githubusercontent.com proxy.individual.githubcopilot.com proxy.business.githubcopilot.com proxy.enterprise.githubcopilot.com *.actions.githubusercontent.com wss://*.actions.githubusercontent.com productionresultssa0.blob.core.windows.net/ productionresultssa1.blob.core.windows.net/ productionresultssa2.blob.core.windows.net/ productionresultssa3.blob.core.windows.net/ productionresultssa4.blob.core.windows.net/ productionresultssa5.blob.core.windows.net/ productionresultssa6.blob.core.windows.net/ productionresultssa7.blob.core.windows.net/ productionresultssa8.blob.core.windows.net/ productionresultssa9.blob.core.windows.net/ productionresultssa10.blob.core.windows.net/ productionresultssa11.blob.core.windows.net/ productionresultssa12.blob.core.windows.net/ productionresultssa13.blob.core.windows.net/ productionresultssa14.blob.core.windows.net/ productionresultssa15.blob.core.windows.net/ productionresultssa16.blob.core.windows.net/ productionresultssa17.blob.core.windows.net/ productionresultssa18.blob.core.windows.net/ productionresultssa19.blob.core.windows.net/ github-production-repository-image-32fea6.s3.amazonaws.com github-production-release-asset-2e65be.s3.amazonaws.com insights.github.com wss://alive.github.com wss://alive-staging.github.com api.githubcopilot.com api.individual.githubcopilot.com api.business.githubcopilot.com api.enterprise.githubcopilot.com; font-src github.githubassets.com; form-action 'self' github.com gist.github.com copilot-workspace.githubnext.com objects-origin.githubusercontent.com; frame-ancestors 'none'; frame-src viewscreen.githubusercontent.com notebooks.githubusercontent.com; img-src 'self' data: blob: github.githubassets.com media.githubusercontent.com camo.githubusercontent.com identicons.github.com avatars.githubusercontent.com private-avatars.githubusercontent.com github-cloud.s3.amazonaws.com objects.githubusercontent.com release-assets.githubusercontent.com secured-user-images.githubusercontent.com/ user-images.githubusercontent.com/ private-user-images.githubusercontent.com opengraph.githubassets.com copilotprodattachments.blob.core.windows.net/github-production-copilot-attachments/ github-production-user-asset-6210df.s3.amazonaws.com customer-stories-feed.github.com spotlights-feed.github.com objects-origin.githubusercontent.com *.githubusercontent.com; manifest-src 'self'; media-src github.com user-images.githubusercontent.com/ secured-user-images.githubusercontent.com/ private-user-images.githubusercontent.com github-production-user-asset-6210df.s3.amazonaws.com gist.github.com; script-src github.githubassets.com; style-src 'unsafe-inline' github.githubassets.com; upgrade-insecure-requests; worker-src github.githubassets.com github.com/assets-cdn/worker/ github.com/assets/ gist.github.com/assets-cdn/worker/
Server: github.com
Accept-Ranges: bytes
Set-Cookie: _gh_sess=FB1Imh8S5QrYHoQXzzf4mKVPD1qblrlvrv%2F0GOLclkupg1sGNJWqEwzE5ra6jlFG1fDFU0i9QwRc9S9DEPuqcDboMZulKLBerGBM3YepWLHVZmAZKVo76uLvtzdGaTXdUbfKuou8IofMCaP80DuJO7t0PkYVsQUYnJgBbducdyekEN9ASdo5SvHfyBRLDrPe9O34cYA9hl9PGrCmqQ6XF%2FZzcajRGxmeJ59V94T4p7lt%2FC5HbPYBZIYDEFj7%2BXtrGyScKXswFY%2FWg40SuLRmrQ%3D%3D--tEwolbtQTLv%2B21dO--s98pLulD1lX8hwAKwTRZtg%3D%3D; Path=/; HttpOnly; Secure; SameSite=Lax
Set-Cookie: _octo=GH1.1.1328515705.1755917716; Path=/; Domain=github.com; Expires=Sun, 23 Aug 2026 02:55:16 GMT; Secure; SameSite=Lax
Set-Cookie: logged_in=no; Path=/; Domain=github.com; Expires=Sun, 23 Aug 2026 02:55:16 GMT; HttpOnly; Secure; SameSite=Lax
X-GitHub-Request-Id: 99F3:E0EB5:FBA64:1891FD:68A92D94
connection: close
Transfer-Encoding: chunked

]
[2025-08-23 07:55:17,187: ERROR: main: File is not a zip file]
Traceback (most recent call last):
  File "C:\Users\ABDULLAH RIZWAN\OneDrive\Desktop\Data Sciences\MLOPS\DataScienceProject\main.py", line 11, in <module>
    obj.initiate_data_ingestion()
  File "C:\Users\ABDULLAH RIZWAN\OneDrive\Desktop\Data Sciences\MLOPS\DataScienceProject\src\DataScienceProject\pipeline\DataIngestionPipeline.py", line 17, in initiate_data_ingestion
    data_ingestion.extract_zip_file()
  File "C:\Users\ABDULLAH RIZWAN\OneDrive\Desktop\Data Sciences\MLOPS\DataScienceProject\src\DataScienceProject\components\data_ingestion.py", line 24, in extract_zip_file
    with zipfile.ZipFile(self.config.local_data_file, 'r') as zip_ref:
         ^^^^^^^^^^^^^^^^^^^^^^^^^^^^^^^^^^^^^^^^^^^^^^^^^
  File "D:\anaconda\Lib\zipfile.py", line 1302, in __init__
    self._RealGetContents()
  File "D:\anaconda\Lib\zipfile.py", line 1369, in _RealGetContents
    raise BadZipFile("File is not a zip file")
zipfile.BadZipFile: File is not a zip file
[2025-08-23 08:05:36,948: INFO: main: >>>>> stage Data Ingestion Stage started >>>>>]
[2025-08-23 08:05:36,954: INFO: common: Yaml file: config\config.yaml is loaded successfully]
[2025-08-23 08:05:36,961: INFO: common: Yaml file: params.yaml is loaded successfully]
[2025-08-23 08:05:36,962: INFO: common: Yaml file: params.yaml is loaded successfully]
[2025-08-23 08:05:36,963: INFO: common: Directory created at artifacts]
[2025-08-23 08:05:36,964: INFO: common: Directory created at artifacts/data_ingestion]
[2025-08-23 08:05:36,965: INFO: data_ingestion: File already exists]
[2025-08-23 08:05:36,967: ERROR: main: name 'config' is not defined]
Traceback (most recent call last):
  File "C:\Users\ABDULLAH RIZWAN\OneDrive\Desktop\Data Sciences\MLOPS\DataScienceProject\main.py", line 11, in <module>
    obj.initiate_data_ingestion()
  File "C:\Users\ABDULLAH RIZWAN\OneDrive\Desktop\Data Sciences\MLOPS\DataScienceProject\src\DataScienceProject\pipeline\DataIngestionPipeline.py", line 17, in initiate_data_ingestion
    data_ingestion.extract_zip_file()
  File "C:\Users\ABDULLAH RIZWAN\OneDrive\Desktop\Data Sciences\MLOPS\DataScienceProject\src\DataScienceProject\components\data_ingestion.py", line 24, in extract_zip_file
    print(type(config.local_data_file))
               ^^^^^^
NameError: name 'config' is not defined
[2025-08-23 08:05:55,909: INFO: main: >>>>> stage Data Ingestion Stage started >>>>>]
[2025-08-23 08:05:55,925: INFO: common: Yaml file: config\config.yaml is loaded successfully]
[2025-08-23 08:05:55,928: INFO: common: Yaml file: params.yaml is loaded successfully]
[2025-08-23 08:05:55,930: INFO: common: Yaml file: params.yaml is loaded successfully]
[2025-08-23 08:05:55,931: INFO: common: Directory created at artifacts]
[2025-08-23 08:05:55,931: INFO: common: Directory created at artifacts/data_ingestion]
[2025-08-23 08:05:55,933: INFO: data_ingestion: File already exists]
[2025-08-23 08:05:55,981: ERROR: main: File is not a zip file]
Traceback (most recent call last):
  File "C:\Users\ABDULLAH RIZWAN\OneDrive\Desktop\Data Sciences\MLOPS\DataScienceProject\main.py", line 11, in <module>
    obj.initiate_data_ingestion()
  File "C:\Users\ABDULLAH RIZWAN\OneDrive\Desktop\Data Sciences\MLOPS\DataScienceProject\src\DataScienceProject\pipeline\DataIngestionPipeline.py", line 17, in initiate_data_ingestion
    data_ingestion.extract_zip_file()
  File "C:\Users\ABDULLAH RIZWAN\OneDrive\Desktop\Data Sciences\MLOPS\DataScienceProject\src\DataScienceProject\components\data_ingestion.py", line 26, in extract_zip_file
    with zipfile.ZipFile(self.config.local_data_file, 'r') as zip_ref:
         ^^^^^^^^^^^^^^^^^^^^^^^^^^^^^^^^^^^^^^^^^^^^^^^^^
  File "D:\anaconda\Lib\zipfile.py", line 1302, in __init__
    self._RealGetContents()
  File "D:\anaconda\Lib\zipfile.py", line 1369, in _RealGetContents
    raise BadZipFile("File is not a zip file")
zipfile.BadZipFile: File is not a zip file
[2025-08-23 08:24:04,926: INFO: main: >>>>> stage Data Ingestion Stage started >>>>>]
[2025-08-23 08:24:04,929: INFO: common: Yaml file: config\config.yaml is loaded successfully]
[2025-08-23 08:24:04,932: INFO: common: Yaml file: params.yaml is loaded successfully]
[2025-08-23 08:24:04,934: INFO: common: Yaml file: params.yaml is loaded successfully]
[2025-08-23 08:24:04,935: INFO: common: Directory created at artifacts]
[2025-08-23 08:24:04,936: INFO: common: Directory created at artifacts/data_ingestion]
[2025-08-23 08:24:05,782: INFO: data_ingestion: File artifacts/data_ingestion/data.zip downloaded with the following info: Connection: close
Content-Length: 23329
Cache-Control: max-age=300
Content-Security-Policy: default-src 'none'; style-src 'unsafe-inline'; sandbox
Content-Type: application/zip
ETag: "c69888a4ae59bc5a893392785a938ccd4937981c06ba8a9d6a21aa52b4ab5b6e"
Strict-Transport-Security: max-age=31536000
X-Content-Type-Options: nosniff
X-Frame-Options: deny
X-XSS-Protection: 1; mode=block
X-GitHub-Request-Id: 607E:316EC2:23381C:2A863E:68A93456
Accept-Ranges: bytes
Date: Sat, 23 Aug 2025 03:24:06 GMT
Via: 1.1 varnish
X-Served-By: cache-mrs1050095-MRS
X-Cache: MISS
X-Cache-Hits: 0
X-Timer: S1755919446.385429,VS0,VE204
Vary: Authorization,Accept-Encoding
Access-Control-Allow-Origin: *
Cross-Origin-Resource-Policy: cross-origin
X-Fastly-Request-ID: b399ebf6baaf7b9304bc30499c4b3d57bf4d36e6
Expires: Sat, 23 Aug 2025 03:29:06 GMT
Source-Age: 0

]
[2025-08-23 08:24:05,825: INFO: main: >>>>> stage Data Ingestion Stage completed >>>>>]
[2025-08-23 08:24:05,830: INFO: main: Alhumdullillah sb okay h boss!]
[2025-08-23 09:52:28,284: INFO: main: >>>>> stage Data Ingestion Stage started >>>>>]
[2025-08-23 09:52:28,290: INFO: common: Yaml file: config\config.yaml is loaded successfully]
[2025-08-23 09:52:28,295: INFO: common: Yaml file: params.yaml is loaded successfully]
[2025-08-23 09:52:28,297: INFO: common: Yaml file: params.yaml is loaded successfully]
[2025-08-23 09:52:28,298: INFO: common: Directory created at artifacts]
[2025-08-23 09:52:28,299: INFO: common: Directory created at artifacts/data_ingestion]
[2025-08-23 09:52:28,300: INFO: data_ingestion: File already exists]
[2025-08-23 09:52:28,363: INFO: main: >>>>> stage Data Ingestion Stage completed >>>>>]
[2025-08-23 09:52:28,364: INFO: main: Alhumdullillah sb okay h boss!]
[2025-08-23 09:52:28,364: INFO: main: >>>>> stage Data Validation Stage started >>>>>]
[2025-08-23 09:52:28,369: INFO: common: Yaml file: config\config.yaml is loaded successfully]
[2025-08-23 09:52:28,371: INFO: common: Yaml file: params.yaml is loaded successfully]
[2025-08-23 09:52:28,373: INFO: common: Yaml file: params.yaml is loaded successfully]
[2025-08-23 09:52:28,373: INFO: common: Directory created at artifacts]
[2025-08-23 09:52:28,374: ERROR: main: "'ConfigBox' object has no attribute 'columns'"]
Traceback (most recent call last):
  File "box\\box.py", line 594, in box.box.Box.__getitem__
KeyError: 'COLUMNS'

The above exception was the direct cause of the following exception:

Traceback (most recent call last):
  File "box\\box.py", line 633, in box.box.Box.__getattr__
  File "box\\box.py", line 621, in box.box.Box.__getitem__
box.exceptions.BoxKeyError: "'COLUMNS'"

During handling of the above exception, another exception occurred:

Traceback (most recent call last):
  File "box\\box.py", line 635, in box.box.Box.__getattr__
AttributeError: 'ConfigBox' object has no attribute 'COLUMNS'

The above exception was the direct cause of the following exception:

Traceback (most recent call last):
  File "box\\config_box.py", line 29, in box.config_box.ConfigBox.__getattr__
  File "box\\box.py", line 649, in box.box.Box.__getattr__
box.exceptions.BoxKeyError: "'ConfigBox' object has no attribute 'COLUMNS'"

During handling of the above exception, another exception occurred:

Traceback (most recent call last):
  File "box\\box.py", line 594, in box.box.Box.__getitem__
KeyError: 'columns'

The above exception was the direct cause of the following exception:

Traceback (most recent call last):
  File "box\\box.py", line 633, in box.box.Box.__getattr__
  File "box\\box.py", line 621, in box.box.Box.__getitem__
box.exceptions.BoxKeyError: "'columns'"

During handling of the above exception, another exception occurred:

Traceback (most recent call last):
  File "box\\box.py", line 635, in box.box.Box.__getattr__
AttributeError: 'ConfigBox' object has no attribute 'columns'

The above exception was the direct cause of the following exception:

Traceback (most recent call last):
  File "C:\Users\ABDULLAH RIZWAN\OneDrive\Desktop\Data Sciences\MLOPS\DataScienceProject\main.py", line 25, in <module>
    obj.initiate_data_validation()
  File "C:\Users\ABDULLAH RIZWAN\OneDrive\Desktop\Data Sciences\MLOPS\DataScienceProject\src\DataScienceProject\pipeline\DataValidationPipeline.py", line 13, in initiate_data_validation
    data_validation_config = config.get_data_validation_config()
                             ^^^^^^^^^^^^^^^^^^^^^^^^^^^^^^^^^^^
  File "C:\Users\ABDULLAH RIZWAN\OneDrive\Desktop\Data Sciences\MLOPS\DataScienceProject\src\DataScienceProject\config\configuration.py", line 34, in get_data_validation_config
    schema = self.schema.COLUMNS
             ^^^^^^^^^^^^^^^^^^^
  File "box\\config_box.py", line 31, in box.config_box.ConfigBox.__getattr__
  File "box\\box.py", line 649, in box.box.Box.__getattr__
box.exceptions.BoxKeyError: "'ConfigBox' object has no attribute 'columns'"
[2025-08-23 09:56:08,399: INFO: main: >>>>> stage Data Ingestion Stage started >>>>>]
[2025-08-23 09:56:08,404: INFO: common: Yaml file: config\config.yaml is loaded successfully]
[2025-08-23 09:56:08,406: INFO: common: Yaml file: params.yaml is loaded successfully]
[2025-08-23 09:56:08,411: INFO: common: Yaml file: schema.yaml is loaded successfully]
[2025-08-23 09:56:08,413: INFO: common: Directory created at artifacts]
[2025-08-23 09:56:08,415: INFO: common: Directory created at artifacts/data_ingestion]
[2025-08-23 09:56:08,415: INFO: data_ingestion: File already exists]
[2025-08-23 09:56:08,423: INFO: main: >>>>> stage Data Ingestion Stage completed >>>>>]
[2025-08-23 09:56:08,424: INFO: main: Alhumdullillah sb okay h boss!]
[2025-08-23 09:56:08,425: INFO: main: >>>>> stage Data Validation Stage started >>>>>]
[2025-08-23 09:56:08,437: INFO: common: Yaml file: config\config.yaml is loaded successfully]
[2025-08-23 09:56:08,439: INFO: common: Yaml file: params.yaml is loaded successfully]
[2025-08-23 09:56:08,453: INFO: common: Yaml file: schema.yaml is loaded successfully]
[2025-08-23 09:56:08,468: INFO: common: Directory created at artifacts]
[2025-08-23 09:56:08,469: ERROR: main: create_directories() missing 1 required positional argument: 'verbose']
Traceback (most recent call last):
  File "C:\Users\ABDULLAH RIZWAN\OneDrive\Desktop\Data Sciences\MLOPS\DataScienceProject\main.py", line 25, in <module>
    obj.initiate_data_validation()
  File "C:\Users\ABDULLAH RIZWAN\OneDrive\Desktop\Data Sciences\MLOPS\DataScienceProject\src\DataScienceProject\pipeline\DataValidationPipeline.py", line 13, in initiate_data_validation
    data_validation_config = config.get_data_validation_config()
                             ^^^^^^^^^^^^^^^^^^^^^^^^^^^^^^^^^^^
  File "C:\Users\ABDULLAH RIZWAN\OneDrive\Desktop\Data Sciences\MLOPS\DataScienceProject\src\DataScienceProject\config\configuration.py", line 36, in get_data_validation_config
    create_directories([config.root_dir])
  File "C:\Users\ABDULLAH RIZWAN\OneDrive\Desktop\Data Sciences\MLOPS\DataScienceProject\.venv\Lib\site-packages\ensure\main.py", line 835, in __call__
    return self.f(*args, **kwargs)
           ^^^^^^^^^^^^^^^^^^^^^^^
TypeError: create_directories() missing 1 required positional argument: 'verbose'
[2025-08-23 09:56:55,289: INFO: main: >>>>> stage Data Ingestion Stage started >>>>>]
[2025-08-23 09:56:55,297: INFO: common: Yaml file: config\config.yaml is loaded successfully]
[2025-08-23 09:56:55,299: INFO: common: Yaml file: params.yaml is loaded successfully]
[2025-08-23 09:56:55,307: INFO: common: Yaml file: schema.yaml is loaded successfully]
[2025-08-23 09:56:55,308: INFO: common: Directory created at artifacts]
[2025-08-23 09:56:55,310: INFO: common: Directory created at artifacts/data_ingestion]
[2025-08-23 09:56:55,310: INFO: data_ingestion: File already exists]
[2025-08-23 09:56:55,318: INFO: main: >>>>> stage Data Ingestion Stage completed >>>>>]
[2025-08-23 09:56:55,325: INFO: main: Alhumdullillah sb okay h boss!]
[2025-08-23 09:56:55,325: INFO: main: >>>>> stage Data Validation Stage started >>>>>]
[2025-08-23 09:56:55,337: INFO: common: Yaml file: config\config.yaml is loaded successfully]
[2025-08-23 09:56:55,339: INFO: common: Yaml file: params.yaml is loaded successfully]
[2025-08-23 09:56:55,363: INFO: common: Yaml file: schema.yaml is loaded successfully]
[2025-08-23 09:56:55,387: INFO: common: Directory created at artifacts]
[2025-08-23 09:56:55,389: INFO: common: Directory created at artifacts/data_validation]
[2025-08-23 09:56:55,390: ERROR: main: "'ConfigBox' object has no attribute 'unzip_data_dir'"]
Traceback (most recent call last):
  File "box\\box.py", line 594, in box.box.Box.__getitem__
KeyError: 'unzip_data_dir'

The above exception was the direct cause of the following exception:

Traceback (most recent call last):
  File "box\\box.py", line 633, in box.box.Box.__getattr__
  File "box\\box.py", line 621, in box.box.Box.__getitem__
box.exceptions.BoxKeyError: "'unzip_data_dir'"

During handling of the above exception, another exception occurred:

Traceback (most recent call last):
  File "box\\box.py", line 635, in box.box.Box.__getattr__
AttributeError: 'ConfigBox' object has no attribute 'unzip_data_dir'

The above exception was the direct cause of the following exception:

Traceback (most recent call last):
  File "box\\config_box.py", line 29, in box.config_box.ConfigBox.__getattr__
  File "box\\box.py", line 649, in box.box.Box.__getattr__
box.exceptions.BoxKeyError: "'ConfigBox' object has no attribute 'unzip_data_dir'"

During handling of the above exception, another exception occurred:

Traceback (most recent call last):
  File "box\\box.py", line 594, in box.box.Box.__getitem__
KeyError: 'unzip_data_dir'

The above exception was the direct cause of the following exception:

Traceback (most recent call last):
  File "box\\box.py", line 633, in box.box.Box.__getattr__
  File "box\\box.py", line 621, in box.box.Box.__getitem__
box.exceptions.BoxKeyError: "'unzip_data_dir'"

During handling of the above exception, another exception occurred:

Traceback (most recent call last):
  File "box\\box.py", line 635, in box.box.Box.__getattr__
AttributeError: 'ConfigBox' object has no attribute 'unzip_data_dir'

The above exception was the direct cause of the following exception:

Traceback (most recent call last):
  File "C:\Users\ABDULLAH RIZWAN\OneDrive\Desktop\Data Sciences\MLOPS\DataScienceProject\main.py", line 25, in <module>
    obj.initiate_data_validation()
  File "C:\Users\ABDULLAH RIZWAN\OneDrive\Desktop\Data Sciences\MLOPS\DataScienceProject\src\DataScienceProject\pipeline\DataValidationPipeline.py", line 13, in initiate_data_validation
    data_validation_config = config.get_data_validation_config()
                             ^^^^^^^^^^^^^^^^^^^^^^^^^^^^^^^^^^^
  File "C:\Users\ABDULLAH RIZWAN\OneDrive\Desktop\Data Sciences\MLOPS\DataScienceProject\src\DataScienceProject\config\configuration.py", line 41, in get_data_validation_config
    unzip_data_dir=config.unzip_data_dir,
                   ^^^^^^^^^^^^^^^^^^^^^
  File "box\\config_box.py", line 31, in box.config_box.ConfigBox.__getattr__
  File "box\\box.py", line 649, in box.box.Box.__getattr__
box.exceptions.BoxKeyError: "'ConfigBox' object has no attribute 'unzip_data_dir'"
[2025-08-23 09:57:46,818: INFO: main: >>>>> stage Data Ingestion Stage started >>>>>]
[2025-08-23 09:57:46,822: INFO: common: Yaml file: config\config.yaml is loaded successfully]
[2025-08-23 09:57:46,824: INFO: common: Yaml file: params.yaml is loaded successfully]
[2025-08-23 09:57:46,831: INFO: common: Yaml file: schema.yaml is loaded successfully]
[2025-08-23 09:57:46,833: INFO: common: Directory created at artifacts]
[2025-08-23 09:57:46,835: INFO: common: Directory created at artifacts/data_ingestion]
[2025-08-23 09:57:46,836: INFO: data_ingestion: File already exists]
[2025-08-23 09:57:46,851: INFO: main: >>>>> stage Data Ingestion Stage completed >>>>>]
[2025-08-23 09:57:46,854: INFO: main: Alhumdullillah sb okay h boss!]
[2025-08-23 09:57:46,856: INFO: main: >>>>> stage Data Validation Stage started >>>>>]
[2025-08-23 09:57:46,870: INFO: common: Yaml file: config\config.yaml is loaded successfully]
[2025-08-23 09:57:46,873: INFO: common: Yaml file: params.yaml is loaded successfully]
[2025-08-23 09:57:46,886: INFO: common: Yaml file: schema.yaml is loaded successfully]
[2025-08-23 09:57:46,891: INFO: common: Directory created at artifacts]
[2025-08-23 09:57:46,892: INFO: common: Directory created at artifacts/data_validation]
[2025-08-23 09:57:46,893: ERROR: main: 'DataValidation' object has no attribute 'congif']
Traceback (most recent call last):
  File "C:\Users\ABDULLAH RIZWAN\OneDrive\Desktop\Data Sciences\MLOPS\DataScienceProject\main.py", line 25, in <module>
    obj.initiate_data_validation()
  File "C:\Users\ABDULLAH RIZWAN\OneDrive\Desktop\Data Sciences\MLOPS\DataScienceProject\src\DataScienceProject\pipeline\DataValidationPipeline.py", line 15, in initiate_data_validation
    data_validation.validate_all_columns()
  File "C:\Users\ABDULLAH RIZWAN\OneDrive\Desktop\Data Sciences\MLOPS\DataScienceProject\src\DataScienceProject\components\data_validation.py", line 31, in validate_all_columns
    raise e
  File "C:\Users\ABDULLAH RIZWAN\OneDrive\Desktop\Data Sciences\MLOPS\DataScienceProject\src\DataScienceProject\components\data_validation.py", line 14, in validate_all_columns
    data = pd.read_csv(self.congif.unzip_data_dir)
                       ^^^^^^^^^^^
AttributeError: 'DataValidation' object has no attribute 'congif'
[2025-08-23 09:58:32,910: INFO: main: >>>>> stage Data Ingestion Stage started >>>>>]
[2025-08-23 09:58:32,913: INFO: common: Yaml file: config\config.yaml is loaded successfully]
[2025-08-23 09:58:32,915: INFO: common: Yaml file: params.yaml is loaded successfully]
[2025-08-23 09:58:32,919: INFO: common: Yaml file: schema.yaml is loaded successfully]
[2025-08-23 09:58:32,920: INFO: common: Directory created at artifacts]
[2025-08-23 09:58:32,922: INFO: common: Directory created at artifacts/data_ingestion]
[2025-08-23 09:58:32,923: INFO: data_ingestion: File already exists]
[2025-08-23 09:58:32,930: INFO: main: >>>>> stage Data Ingestion Stage completed >>>>>]
[2025-08-23 09:58:32,931: INFO: main: Alhumdullillah sb okay h boss!]
[2025-08-23 09:58:32,931: INFO: main: >>>>> stage Data Validation Stage started >>>>>]
[2025-08-23 09:58:32,934: INFO: common: Yaml file: config\config.yaml is loaded successfully]
[2025-08-23 09:58:32,936: INFO: common: Yaml file: params.yaml is loaded successfully]
[2025-08-23 09:58:32,943: INFO: common: Yaml file: schema.yaml is loaded successfully]
[2025-08-23 09:58:32,949: INFO: common: Directory created at artifacts]
[2025-08-23 09:58:32,950: INFO: common: Directory created at artifacts/data_validation]
[2025-08-23 09:58:33,078: INFO: main: >>>>> stage Data Validation Stage completed >>>>>]
[2025-08-23 12:02:36,432: INFO: main: >>>>> stage Data Ingestion Stage started >>>>>]
[2025-08-23 12:02:36,439: INFO: common: Yaml file: config\config.yaml is loaded successfully]
[2025-08-23 12:02:36,446: INFO: common: Yaml file: params.yaml is loaded successfully]
[2025-08-23 12:02:36,451: INFO: common: Yaml file: schema.yaml is loaded successfully]
[2025-08-23 12:02:36,452: INFO: common: Directory created at artifacts]
[2025-08-23 12:02:36,454: INFO: common: Directory created at artifacts/data_ingestion]
[2025-08-23 12:02:36,454: INFO: data_ingestion: File already exists]
[2025-08-23 12:02:36,470: INFO: main: >>>>> stage Data Ingestion Stage completed >>>>>]
[2025-08-23 12:02:36,483: INFO: main: Alhumdullillah sb okay h boss!]
[2025-08-23 12:02:36,493: INFO: main: >>>>> stage Data Validation Stage started >>>>>]
[2025-08-23 12:02:36,530: INFO: common: Yaml file: config\config.yaml is loaded successfully]
[2025-08-23 12:02:36,537: INFO: common: Yaml file: params.yaml is loaded successfully]
[2025-08-23 12:02:36,547: INFO: common: Yaml file: schema.yaml is loaded successfully]
[2025-08-23 12:02:36,549: INFO: common: Directory created at artifacts]
[2025-08-23 12:02:36,557: INFO: common: Directory created at artifacts/data_validation]
[2025-08-23 12:02:36,661: INFO: main: >>>>> stage Data Validation Stage completed >>>>>]
[2025-08-23 12:02:36,662: INFO: main: >>>>> stage Data Transformation Stage started >>>>>]
[2025-08-23 12:02:36,662: ERROR: main: name 'Path' is not defined]
Traceback (most recent call last):
  File "C:\Users\ABDULLAH RIZWAN\OneDrive\Desktop\Data Sciences\MLOPS\DataScienceProject\main.py", line 37, in <module>
    obj.initiate_data_transformation()
  File "C:\Users\ABDULLAH RIZWAN\OneDrive\Desktop\Data Sciences\MLOPS\DataScienceProject\src\DataScienceProject\pipeline\DataTransformationPipeline.py", line 22, in initiate_data_transformation
    raise e
  File "C:\Users\ABDULLAH RIZWAN\OneDrive\Desktop\Data Sciences\MLOPS\DataScienceProject\src\DataScienceProject\pipeline\DataTransformationPipeline.py", line 11, in initiate_data_transformation
    with open(Path('artifacts/data_validation/STATUS_FILE.txt'),'r') as f:
              ^^^^
NameError: name 'Path' is not defined
[2025-08-23 12:03:00,734: INFO: main: >>>>> stage Data Ingestion Stage started >>>>>]
[2025-08-23 12:03:00,738: INFO: common: Yaml file: config\config.yaml is loaded successfully]
[2025-08-23 12:03:00,739: INFO: common: Yaml file: params.yaml is loaded successfully]
[2025-08-23 12:03:00,744: INFO: common: Yaml file: schema.yaml is loaded successfully]
[2025-08-23 12:03:00,745: INFO: common: Directory created at artifacts]
[2025-08-23 12:03:00,746: INFO: common: Directory created at artifacts/data_ingestion]
[2025-08-23 12:03:00,747: INFO: data_ingestion: File already exists]
[2025-08-23 12:03:00,753: INFO: main: >>>>> stage Data Ingestion Stage completed >>>>>]
[2025-08-23 12:03:00,753: INFO: main: Alhumdullillah sb okay h boss!]
[2025-08-23 12:03:00,754: INFO: main: >>>>> stage Data Validation Stage started >>>>>]
[2025-08-23 12:03:00,757: INFO: common: Yaml file: config\config.yaml is loaded successfully]
[2025-08-23 12:03:00,759: INFO: common: Yaml file: params.yaml is loaded successfully]
[2025-08-23 12:03:00,765: INFO: common: Yaml file: schema.yaml is loaded successfully]
[2025-08-23 12:03:00,766: INFO: common: Directory created at artifacts]
[2025-08-23 12:03:00,768: INFO: common: Directory created at artifacts/data_validation]
[2025-08-23 12:03:00,837: INFO: main: >>>>> stage Data Validation Stage completed >>>>>]
[2025-08-23 12:03:00,838: INFO: main: >>>>> stage Data Transformation Stage started >>>>>]
[2025-08-23 12:03:00,840: ERROR: main: [Errno 2] No such file or directory: 'artifacts\\data_validation\\STATUS_FILE.txt']
Traceback (most recent call last):
  File "C:\Users\ABDULLAH RIZWAN\OneDrive\Desktop\Data Sciences\MLOPS\DataScienceProject\main.py", line 37, in <module>
    obj.initiate_data_transformation()
  File "C:\Users\ABDULLAH RIZWAN\OneDrive\Desktop\Data Sciences\MLOPS\DataScienceProject\src\DataScienceProject\pipeline\DataTransformationPipeline.py", line 23, in initiate_data_transformation
    raise e
  File "C:\Users\ABDULLAH RIZWAN\OneDrive\Desktop\Data Sciences\MLOPS\DataScienceProject\src\DataScienceProject\pipeline\DataTransformationPipeline.py", line 12, in initiate_data_transformation
    with open(Path('artifacts/data_validation/STATUS_FILE.txt'),'r') as f:
         ^^^^^^^^^^^^^^^^^^^^^^^^^^^^^^^^^^^^^^^^^^^^^^^^^^^^^^^^^^^
FileNotFoundError: [Errno 2] No such file or directory: 'artifacts\\data_validation\\STATUS_FILE.txt'
[2025-08-23 12:04:08,208: INFO: main: >>>>> stage Data Ingestion Stage started >>>>>]
[2025-08-23 12:04:08,213: INFO: common: Yaml file: config\config.yaml is loaded successfully]
[2025-08-23 12:04:08,215: INFO: common: Yaml file: params.yaml is loaded successfully]
[2025-08-23 12:04:08,222: INFO: common: Yaml file: schema.yaml is loaded successfully]
[2025-08-23 12:04:08,224: INFO: common: Directory created at artifacts]
[2025-08-23 12:04:08,226: INFO: common: Directory created at artifacts/data_ingestion]
[2025-08-23 12:04:08,226: INFO: data_ingestion: File already exists]
[2025-08-23 12:04:08,240: INFO: main: >>>>> stage Data Ingestion Stage completed >>>>>]
[2025-08-23 12:04:08,244: INFO: main: Alhumdullillah sb okay h boss!]
[2025-08-23 12:04:08,245: INFO: main: >>>>> stage Data Validation Stage started >>>>>]
[2025-08-23 12:04:08,253: INFO: common: Yaml file: config\config.yaml is loaded successfully]
[2025-08-23 12:04:08,255: INFO: common: Yaml file: params.yaml is loaded successfully]
[2025-08-23 12:04:08,262: INFO: common: Yaml file: schema.yaml is loaded successfully]
[2025-08-23 12:04:08,265: INFO: common: Directory created at artifacts]
[2025-08-23 12:04:08,266: INFO: common: Directory created at artifacts/data_validation]
[2025-08-23 12:04:08,349: INFO: main: >>>>> stage Data Validation Stage completed >>>>>]
[2025-08-23 12:04:08,349: INFO: main: >>>>> stage Data Transformation Stage started >>>>>]
[2025-08-23 12:04:08,358: INFO: common: Yaml file: config\config.yaml is loaded successfully]
[2025-08-23 12:04:08,361: INFO: common: Yaml file: params.yaml is loaded successfully]
[2025-08-23 12:04:08,366: INFO: common: Yaml file: schema.yaml is loaded successfully]
[2025-08-23 12:04:08,367: INFO: common: Directory created at artifacts]
[2025-08-23 12:04:08,369: ERROR: main: 'ConfigurationManager' object has no attribute 'get_data_transformation']
Traceback (most recent call last):
  File "C:\Users\ABDULLAH RIZWAN\OneDrive\Desktop\Data Sciences\MLOPS\DataScienceProject\main.py", line 37, in <module>
    obj.initiate_data_transformation()
  File "C:\Users\ABDULLAH RIZWAN\OneDrive\Desktop\Data Sciences\MLOPS\DataScienceProject\src\DataScienceProject\pipeline\DataTransformationPipeline.py", line 23, in initiate_data_transformation
    raise e
  File "C:\Users\ABDULLAH RIZWAN\OneDrive\Desktop\Data Sciences\MLOPS\DataScienceProject\src\DataScienceProject\pipeline\DataTransformationPipeline.py", line 17, in initiate_data_transformation
    data_transformation_config = config.get_data_transformation()
                                 ^^^^^^^^^^^^^^^^^^^^^^^^^^^^^^
AttributeError: 'ConfigurationManager' object has no attribute 'get_data_transformation'
[2025-08-23 12:05:31,530: INFO: main: >>>>> stage Data Ingestion Stage started >>>>>]
[2025-08-23 12:05:31,534: INFO: common: Yaml file: config\config.yaml is loaded successfully]
[2025-08-23 12:05:31,536: INFO: common: Yaml file: params.yaml is loaded successfully]
[2025-08-23 12:05:31,540: INFO: common: Yaml file: schema.yaml is loaded successfully]
[2025-08-23 12:05:31,541: INFO: common: Directory created at artifacts]
[2025-08-23 12:05:31,543: INFO: common: Directory created at artifacts/data_ingestion]
[2025-08-23 12:05:31,543: INFO: data_ingestion: File already exists]
[2025-08-23 12:05:31,548: INFO: main: >>>>> stage Data Ingestion Stage completed >>>>>]
[2025-08-23 12:05:31,550: INFO: main: Alhumdullillah sb okay h boss!]
[2025-08-23 12:05:31,551: INFO: main: >>>>> stage Data Validation Stage started >>>>>]
[2025-08-23 12:05:31,554: INFO: common: Yaml file: config\config.yaml is loaded successfully]
[2025-08-23 12:05:31,556: INFO: common: Yaml file: params.yaml is loaded successfully]
[2025-08-23 12:05:31,560: INFO: common: Yaml file: schema.yaml is loaded successfully]
[2025-08-23 12:05:31,562: INFO: common: Directory created at artifacts]
[2025-08-23 12:05:31,563: INFO: common: Directory created at artifacts/data_validation]
[2025-08-23 12:05:31,637: INFO: main: >>>>> stage Data Validation Stage completed >>>>>]
[2025-08-23 12:05:31,638: INFO: main: >>>>> stage Data Transformation Stage started >>>>>]
[2025-08-23 12:05:31,644: INFO: common: Yaml file: config\config.yaml is loaded successfully]
[2025-08-23 12:05:31,646: INFO: common: Yaml file: params.yaml is loaded successfully]
[2025-08-23 12:05:31,649: INFO: common: Yaml file: schema.yaml is loaded successfully]
[2025-08-23 12:05:31,650: INFO: common: Directory created at artifacts]
[2025-08-23 12:05:31,651: INFO: common: Directory created at artifacts/data_transformation]
[2025-08-23 12:05:31,750: INFO: data_transformation: Spliting completed]
[2025-08-23 12:05:31,751: INFO: data_transformation: Train shape: (1199, 12)]
[2025-08-23 12:05:31,751: ERROR: main: name 'loger' is not defined]
Traceback (most recent call last):
  File "C:\Users\ABDULLAH RIZWAN\OneDrive\Desktop\Data Sciences\MLOPS\DataScienceProject\main.py", line 37, in <module>
    obj.initiate_data_transformation()
  File "C:\Users\ABDULLAH RIZWAN\OneDrive\Desktop\Data Sciences\MLOPS\DataScienceProject\src\DataScienceProject\pipeline\DataTransformationPipeline.py", line 23, in initiate_data_transformation
    raise e
  File "C:\Users\ABDULLAH RIZWAN\OneDrive\Desktop\Data Sciences\MLOPS\DataScienceProject\src\DataScienceProject\pipeline\DataTransformationPipeline.py", line 19, in initiate_data_transformation
    data_transformation.train_test_spliting()
  File "C:\Users\ABDULLAH RIZWAN\OneDrive\Desktop\Data Sciences\MLOPS\DataScienceProject\src\DataScienceProject\components\data_transformation.py", line 22, in train_test_spliting
    loger.info(f'Test  shape: {test.shape}')
    ^^^^^
NameError: name 'loger' is not defined
[2025-08-23 12:06:04,401: INFO: main: >>>>> stage Data Ingestion Stage started >>>>>]
[2025-08-23 12:06:04,407: INFO: common: Yaml file: config\config.yaml is loaded successfully]
[2025-08-23 12:06:04,409: INFO: common: Yaml file: params.yaml is loaded successfully]
[2025-08-23 12:06:04,415: INFO: common: Yaml file: schema.yaml is loaded successfully]
[2025-08-23 12:06:04,417: INFO: common: Directory created at artifacts]
[2025-08-23 12:06:04,418: INFO: common: Directory created at artifacts/data_ingestion]
[2025-08-23 12:06:04,418: INFO: data_ingestion: File already exists]
[2025-08-23 12:06:04,428: INFO: main: >>>>> stage Data Ingestion Stage completed >>>>>]
[2025-08-23 12:06:04,429: INFO: main: Alhumdullillah sb okay h boss!]
[2025-08-23 12:06:04,434: INFO: main: >>>>> stage Data Validation Stage started >>>>>]
[2025-08-23 12:06:04,507: INFO: common: Yaml file: config\config.yaml is loaded successfully]
[2025-08-23 12:06:04,535: INFO: common: Yaml file: params.yaml is loaded successfully]
[2025-08-23 12:06:04,553: INFO: common: Yaml file: schema.yaml is loaded successfully]
[2025-08-23 12:06:04,607: INFO: common: Directory created at artifacts]
[2025-08-23 12:06:04,619: INFO: common: Directory created at artifacts/data_validation]
[2025-08-23 12:06:04,722: INFO: main: >>>>> stage Data Validation Stage completed >>>>>]
[2025-08-23 12:06:04,723: INFO: main: >>>>> stage Data Transformation Stage started >>>>>]
[2025-08-23 12:06:04,730: INFO: common: Yaml file: config\config.yaml is loaded successfully]
[2025-08-23 12:06:04,732: INFO: common: Yaml file: params.yaml is loaded successfully]
[2025-08-23 12:06:04,736: INFO: common: Yaml file: schema.yaml is loaded successfully]
[2025-08-23 12:06:04,738: INFO: common: Directory created at artifacts]
[2025-08-23 12:06:04,739: INFO: common: Directory created at artifacts/data_transformation]
[2025-08-23 12:06:04,828: INFO: data_transformation: Spliting completed]
[2025-08-23 12:06:04,830: INFO: data_transformation: Train shape: (1199, 12)]
[2025-08-23 12:06:04,832: INFO: data_transformation: Test  shape: (400, 12)]
[2025-08-23 12:06:04,832: INFO: main: >>>>> stage Data Transformation Stage completed >>>>>]
[2025-08-23 12:06:53,230: INFO: main: >>>>> stage Data Ingestion Stage started >>>>>]
[2025-08-23 12:06:53,234: INFO: common: Yaml file: config\config.yaml is loaded successfully]
[2025-08-23 12:06:53,235: INFO: common: Yaml file: params.yaml is loaded successfully]
[2025-08-23 12:06:53,238: INFO: common: Yaml file: schema.yaml is loaded successfully]
[2025-08-23 12:06:53,239: INFO: common: Directory created at artifacts]
[2025-08-23 12:06:53,239: INFO: common: Directory created at artifacts/data_ingestion]
[2025-08-23 12:06:53,239: INFO: data_ingestion: File already exists]
[2025-08-23 12:06:53,243: INFO: main: >>>>> stage Data Ingestion Stage completed >>>>>]
[2025-08-23 12:06:53,244: INFO: main: Alhumdullillah sb okay h boss!]
[2025-08-23 12:06:53,244: INFO: main: >>>>> stage Data Validation Stage started >>>>>]
[2025-08-23 12:06:53,246: INFO: common: Yaml file: config\config.yaml is loaded successfully]
[2025-08-23 12:06:53,248: INFO: common: Yaml file: params.yaml is loaded successfully]
[2025-08-23 12:06:53,252: INFO: common: Yaml file: schema.yaml is loaded successfully]
[2025-08-23 12:06:53,253: INFO: common: Directory created at artifacts]
[2025-08-23 12:06:53,254: INFO: common: Directory created at artifacts/data_validation]
[2025-08-23 12:06:53,321: INFO: main: >>>>> stage Data Validation Stage completed >>>>>]
[2025-08-23 12:06:53,321: INFO: main: >>>>> stage Data Transformation Stage started >>>>>]
[2025-08-23 12:06:53,325: INFO: common: Yaml file: config\config.yaml is loaded successfully]
[2025-08-23 12:06:53,326: INFO: common: Yaml file: params.yaml is loaded successfully]
[2025-08-23 12:06:53,329: INFO: common: Yaml file: schema.yaml is loaded successfully]
[2025-08-23 12:06:53,330: INFO: common: Directory created at artifacts]
[2025-08-23 12:06:53,330: INFO: common: Directory created at artifacts/data_transformation]
[2025-08-23 12:06:53,370: INFO: data_transformation: Spliting completed]
[2025-08-23 12:06:53,371: INFO: data_transformation: Train shape: (1199, 12)]
[2025-08-23 12:06:53,372: INFO: data_transformation: Test  shape: (400, 12)]
[2025-08-23 12:06:53,372: INFO: main: >>>>> stage Data Transformation Stage completed >>>>>]
[2025-08-23 15:50:45,306: INFO: main: >>>>> stage Data Ingestion Stage started >>>>>]
[2025-08-23 15:50:45,313: INFO: common: Yaml file: config\config.yaml is loaded successfully]
[2025-08-23 15:50:45,318: INFO: common: Yaml file: params.yaml is loaded successfully]
[2025-08-23 15:50:45,324: INFO: common: Yaml file: schema.yaml is loaded successfully]
[2025-08-23 15:50:45,326: INFO: common: Directory created at artifacts]
[2025-08-23 15:50:45,327: INFO: common: Directory created at artifacts/data_ingestion]
[2025-08-23 15:50:45,327: INFO: data_ingestion: File already exists]
[2025-08-23 15:50:45,344: INFO: main: >>>>> stage Data Ingestion Stage completed >>>>>]
[2025-08-23 15:50:45,344: INFO: main: Alhumdullillah sb okay h boss!]
[2025-08-23 15:50:45,345: INFO: main: >>>>> stage Data Validation Stage started >>>>>]
[2025-08-23 15:50:45,369: INFO: common: Yaml file: config\config.yaml is loaded successfully]
[2025-08-23 15:50:45,376: INFO: common: Yaml file: params.yaml is loaded successfully]
[2025-08-23 15:50:45,391: INFO: common: Yaml file: schema.yaml is loaded successfully]
[2025-08-23 15:50:45,397: INFO: common: Directory created at artifacts]
[2025-08-23 15:50:45,400: INFO: common: Directory created at artifacts/data_validation]
[2025-08-23 15:50:45,541: INFO: main: >>>>> stage Data Validation Stage completed >>>>>]
[2025-08-23 15:50:45,542: INFO: main: >>>>> stage Data Transformation Stage started >>>>>]
[2025-08-23 15:50:45,556: INFO: common: Yaml file: config\config.yaml is loaded successfully]
[2025-08-23 15:50:45,559: INFO: common: Yaml file: params.yaml is loaded successfully]
[2025-08-23 15:50:45,565: INFO: common: Yaml file: schema.yaml is loaded successfully]
[2025-08-23 15:50:45,567: INFO: common: Directory created at artifacts]
[2025-08-23 15:50:45,571: INFO: common: Directory created at artifacts/data_transformation]
[2025-08-23 15:50:45,667: INFO: data_transformation: Spliting completed]
[2025-08-23 15:50:45,669: INFO: data_transformation: Train shape: (1199, 12)]
[2025-08-23 15:50:45,670: INFO: data_transformation: Test  shape: (400, 12)]
[2025-08-23 15:50:45,672: INFO: main: >>>>> stage Data Transformation Stage completed >>>>>]
[2025-08-23 15:50:45,672: INFO: main: >>>>> stage Model Training Stage started >>>>>]
[2025-08-23 15:50:45,673: ERROR: main: name 'ModelTrainingPipeline' is not defined]
Traceback (most recent call last):
  File "C:\Users\ABDULLAH RIZWAN\OneDrive\Desktop\Data Sciences\MLOPS\DataScienceProject\main.py", line 49, in <module>
    obj = ModelTrainingPipeline()
          ^^^^^^^^^^^^^^^^^^^^^
NameError: name 'ModelTrainingPipeline' is not defined
[2025-08-23 15:51:28,883: INFO: main: >>>>> stage Data Ingestion Stage started >>>>>]
[2025-08-23 15:51:28,891: INFO: common: Yaml file: config\config.yaml is loaded successfully]
[2025-08-23 15:51:28,894: INFO: common: Yaml file: params.yaml is loaded successfully]
[2025-08-23 15:51:28,904: INFO: common: Yaml file: schema.yaml is loaded successfully]
[2025-08-23 15:51:28,906: INFO: common: Directory created at artifacts]
[2025-08-23 15:51:28,907: INFO: common: Directory created at artifacts/data_ingestion]
[2025-08-23 15:51:28,908: INFO: data_ingestion: File already exists]
[2025-08-23 15:51:28,942: INFO: main: >>>>> stage Data Ingestion Stage completed >>>>>]
[2025-08-23 15:51:28,943: INFO: main: Alhumdullillah sb okay h boss!]
[2025-08-23 15:51:28,943: INFO: main: >>>>> stage Data Validation Stage started >>>>>]
[2025-08-23 15:51:28,974: INFO: common: Yaml file: config\config.yaml is loaded successfully]
[2025-08-23 15:51:28,978: INFO: common: Yaml file: params.yaml is loaded successfully]
[2025-08-23 15:51:29,006: INFO: common: Yaml file: schema.yaml is loaded successfully]
[2025-08-23 15:51:29,012: INFO: common: Directory created at artifacts]
[2025-08-23 15:51:29,017: INFO: common: Directory created at artifacts/data_validation]
[2025-08-23 15:51:29,133: INFO: main: >>>>> stage Data Validation Stage completed >>>>>]
[2025-08-23 15:51:29,134: INFO: main: >>>>> stage Data Transformation Stage started >>>>>]
[2025-08-23 15:51:29,142: INFO: common: Yaml file: config\config.yaml is loaded successfully]
[2025-08-23 15:51:29,146: INFO: common: Yaml file: params.yaml is loaded successfully]
[2025-08-23 15:51:29,154: INFO: common: Yaml file: schema.yaml is loaded successfully]
[2025-08-23 15:51:29,156: INFO: common: Directory created at artifacts]
[2025-08-23 15:51:29,158: INFO: common: Directory created at artifacts/data_transformation]
[2025-08-23 15:51:29,226: INFO: data_transformation: Spliting completed]
[2025-08-23 15:51:29,227: INFO: data_transformation: Train shape: (1199, 12)]
[2025-08-23 15:51:29,234: INFO: data_transformation: Test  shape: (400, 12)]
[2025-08-23 15:51:29,235: INFO: main: >>>>> stage Data Transformation Stage completed >>>>>]
[2025-08-23 15:51:29,235: INFO: main: >>>>> stage Model Training Stage started >>>>>]
[2025-08-23 15:51:29,245: ERROR: main: ModelTrainerPipeline.initiate_model_trainer_pipeline() takes 0 positional arguments but 1 was given]
Traceback (most recent call last):
  File "C:\Users\ABDULLAH RIZWAN\OneDrive\Desktop\Data Sciences\MLOPS\DataScienceProject\main.py", line 50, in <module>
    obj.initiate_model_trainer_pipeline()
TypeError: ModelTrainerPipeline.initiate_model_trainer_pipeline() takes 0 positional arguments but 1 was given
[2025-08-23 15:56:13,838: INFO: main: >>>>> stage Data Ingestion Stage started >>>>>]
[2025-08-23 15:56:13,877: INFO: common: Yaml file: config\config.yaml is loaded successfully]
[2025-08-23 15:56:13,923: INFO: common: Yaml file: params.yaml is loaded successfully]
[2025-08-23 15:56:13,965: INFO: common: Yaml file: schema.yaml is loaded successfully]
[2025-08-23 15:56:13,967: INFO: common: Directory created at artifacts]
[2025-08-23 15:56:13,968: INFO: common: Directory created at artifacts/data_ingestion]
[2025-08-23 15:56:13,969: INFO: data_ingestion: File already exists]
[2025-08-23 15:56:13,977: INFO: main: >>>>> stage Data Ingestion Stage completed >>>>>]
[2025-08-23 15:56:13,978: INFO: main: Alhumdullillah sb okay h boss!]
[2025-08-23 15:56:13,980: INFO: main: >>>>> stage Data Validation Stage started >>>>>]
[2025-08-23 15:56:14,034: INFO: common: Yaml file: config\config.yaml is loaded successfully]
[2025-08-23 15:56:14,092: INFO: common: Yaml file: params.yaml is loaded successfully]
[2025-08-23 15:56:14,098: INFO: common: Yaml file: schema.yaml is loaded successfully]
[2025-08-23 15:56:14,101: INFO: common: Directory created at artifacts]
[2025-08-23 15:56:14,102: INFO: common: Directory created at artifacts/data_validation]
[2025-08-23 15:56:14,217: INFO: main: >>>>> stage Data Validation Stage completed >>>>>]
[2025-08-23 15:56:14,220: INFO: main: >>>>> stage Data Transformation Stage started >>>>>]
[2025-08-23 15:56:14,239: INFO: common: Yaml file: config\config.yaml is loaded successfully]
[2025-08-23 15:56:14,244: INFO: common: Yaml file: params.yaml is loaded successfully]
[2025-08-23 15:56:14,258: INFO: common: Yaml file: schema.yaml is loaded successfully]
[2025-08-23 15:56:14,261: INFO: common: Directory created at artifacts]
[2025-08-23 15:56:14,263: INFO: common: Directory created at artifacts/data_transformation]
[2025-08-23 15:56:14,369: INFO: data_transformation: Spliting completed]
[2025-08-23 15:56:14,372: INFO: data_transformation: Train shape: (1199, 12)]
[2025-08-23 15:56:14,373: INFO: data_transformation: Test  shape: (400, 12)]
[2025-08-23 15:56:14,374: INFO: main: >>>>> stage Data Transformation Stage completed >>>>>]
[2025-08-23 15:56:14,375: INFO: main: >>>>> stage Model Training Stage started >>>>>]
[2025-08-23 15:56:14,386: INFO: common: Yaml file: config\config.yaml is loaded successfully]
[2025-08-23 15:56:14,406: INFO: common: Yaml file: params.yaml is loaded successfully]
[2025-08-23 15:56:14,442: INFO: common: Yaml file: schema.yaml is loaded successfully]
[2025-08-23 15:56:14,445: INFO: common: Directory created at artifacts]
[2025-08-23 15:56:14,458: INFO: common: Directory created at artifacts/model_trainer]
[2025-08-23 15:56:14,466: ERROR: main: "'ConfigBox' object has no attribute 'train_path'"]
Traceback (most recent call last):
  File "box\\box.py", line 594, in box.box.Box.__getitem__
KeyError: 'train_path'

The above exception was the direct cause of the following exception:

Traceback (most recent call last):
  File "box\\box.py", line 633, in box.box.Box.__getattr__
  File "box\\box.py", line 621, in box.box.Box.__getitem__
box.exceptions.BoxKeyError: "'train_path'"

During handling of the above exception, another exception occurred:

Traceback (most recent call last):
  File "box\\box.py", line 635, in box.box.Box.__getattr__
AttributeError: 'ConfigBox' object has no attribute 'train_path'

The above exception was the direct cause of the following exception:

Traceback (most recent call last):
  File "box\\config_box.py", line 29, in box.config_box.ConfigBox.__getattr__
  File "box\\box.py", line 649, in box.box.Box.__getattr__
box.exceptions.BoxKeyError: "'ConfigBox' object has no attribute 'train_path'"

During handling of the above exception, another exception occurred:

Traceback (most recent call last):
  File "box\\box.py", line 594, in box.box.Box.__getitem__
KeyError: 'train_path'

The above exception was the direct cause of the following exception:

Traceback (most recent call last):
  File "box\\box.py", line 633, in box.box.Box.__getattr__
  File "box\\box.py", line 621, in box.box.Box.__getitem__
box.exceptions.BoxKeyError: "'train_path'"

During handling of the above exception, another exception occurred:

Traceback (most recent call last):
  File "box\\box.py", line 635, in box.box.Box.__getattr__
AttributeError: 'ConfigBox' object has no attribute 'train_path'

The above exception was the direct cause of the following exception:

Traceback (most recent call last):
  File "C:\Users\ABDULLAH RIZWAN\OneDrive\Desktop\Data Sciences\MLOPS\DataScienceProject\main.py", line 50, in <module>
    obj.initiate_model_trainer_pipeline()
  File "C:\Users\ABDULLAH RIZWAN\OneDrive\Desktop\Data Sciences\MLOPS\DataScienceProject\src\DataScienceProject\pipeline\ModelTrainerPipeline.py", line 16, in initiate_model_trainer_pipeline
    raise e
  File "C:\Users\ABDULLAH RIZWAN\OneDrive\Desktop\Data Sciences\MLOPS\DataScienceProject\src\DataScienceProject\pipeline\ModelTrainerPipeline.py", line 12, in initiate_model_trainer_pipeline
    model_trainer_config = config.get_model_trainer_config()
                           ^^^^^^^^^^^^^^^^^^^^^^^^^^^^^^^^^
  File "C:\Users\ABDULLAH RIZWAN\OneDrive\Desktop\Data Sciences\MLOPS\DataScienceProject\src\DataScienceProject\config\configuration.py", line 68, in get_model_trainer_config
    train_path = config.train_path,
                 ^^^^^^^^^^^^^^^^^
  File "box\\config_box.py", line 31, in box.config_box.ConfigBox.__getattr__
  File "box\\box.py", line 649, in box.box.Box.__getattr__
box.exceptions.BoxKeyError: "'ConfigBox' object has no attribute 'train_path'"
[2025-08-23 15:58:37,901: INFO: main: >>>>> stage Data Ingestion Stage started >>>>>]
[2025-08-23 15:58:37,909: INFO: common: Yaml file: config\config.yaml is loaded successfully]
[2025-08-23 15:58:37,914: INFO: common: Yaml file: params.yaml is loaded successfully]
[2025-08-23 15:58:37,926: INFO: common: Yaml file: schema.yaml is loaded successfully]
[2025-08-23 15:58:37,929: INFO: common: Directory created at artifacts]
[2025-08-23 15:58:37,937: INFO: common: Directory created at artifacts/data_ingestion]
[2025-08-23 15:58:37,947: INFO: data_ingestion: File already exists]
[2025-08-23 15:58:37,994: INFO: main: >>>>> stage Data Ingestion Stage completed >>>>>]
[2025-08-23 15:58:38,015: INFO: main: Alhumdullillah sb okay h boss!]
[2025-08-23 15:58:38,055: INFO: main: >>>>> stage Data Validation Stage started >>>>>]
[2025-08-23 15:58:38,125: INFO: common: Yaml file: config\config.yaml is loaded successfully]
[2025-08-23 15:58:38,159: INFO: common: Yaml file: params.yaml is loaded successfully]
[2025-08-23 15:58:38,207: INFO: common: Yaml file: schema.yaml is loaded successfully]
[2025-08-23 15:58:38,215: INFO: common: Directory created at artifacts]
[2025-08-23 15:58:38,229: INFO: common: Directory created at artifacts/data_validation]
[2025-08-23 15:58:38,308: INFO: main: >>>>> stage Data Validation Stage completed >>>>>]
[2025-08-23 15:58:38,311: INFO: main: >>>>> stage Data Transformation Stage started >>>>>]
[2025-08-23 15:58:38,324: INFO: common: Yaml file: config\config.yaml is loaded successfully]
[2025-08-23 15:58:38,330: INFO: common: Yaml file: params.yaml is loaded successfully]
[2025-08-23 15:58:38,356: INFO: common: Yaml file: schema.yaml is loaded successfully]
[2025-08-23 15:58:38,405: INFO: common: Directory created at artifacts]
[2025-08-23 15:58:38,442: INFO: common: Directory created at artifacts/data_transformation]
[2025-08-23 15:58:38,604: INFO: data_transformation: Spliting completed]
[2025-08-23 15:58:38,605: INFO: data_transformation: Train shape: (1199, 12)]
[2025-08-23 15:58:38,616: INFO: data_transformation: Test  shape: (400, 12)]
[2025-08-23 15:58:38,619: INFO: main: >>>>> stage Data Transformation Stage completed >>>>>]
[2025-08-23 15:58:38,621: INFO: main: >>>>> stage Model Training Stage started >>>>>]
[2025-08-23 15:58:38,638: INFO: common: Yaml file: config\config.yaml is loaded successfully]
[2025-08-23 15:58:38,694: INFO: common: Yaml file: params.yaml is loaded successfully]
[2025-08-23 15:58:38,755: INFO: common: Yaml file: schema.yaml is loaded successfully]
[2025-08-23 15:58:38,783: INFO: common: Directory created at artifacts]
[2025-08-23 15:58:38,834: INFO: common: Directory created at artifacts/model_trainer]
[2025-08-23 15:58:38,874: ERROR: main: "'ConfigBox' object has no attribute 'train_path'"]
Traceback (most recent call last):
  File "box\\box.py", line 594, in box.box.Box.__getitem__
KeyError: 'train_path'

The above exception was the direct cause of the following exception:

Traceback (most recent call last):
  File "box\\box.py", line 633, in box.box.Box.__getattr__
  File "box\\box.py", line 621, in box.box.Box.__getitem__
box.exceptions.BoxKeyError: "'train_path'"

During handling of the above exception, another exception occurred:

Traceback (most recent call last):
  File "box\\box.py", line 635, in box.box.Box.__getattr__
AttributeError: 'ConfigBox' object has no attribute 'train_path'

The above exception was the direct cause of the following exception:

Traceback (most recent call last):
  File "box\\config_box.py", line 29, in box.config_box.ConfigBox.__getattr__
  File "box\\box.py", line 649, in box.box.Box.__getattr__
box.exceptions.BoxKeyError: "'ConfigBox' object has no attribute 'train_path'"

During handling of the above exception, another exception occurred:

Traceback (most recent call last):
  File "box\\box.py", line 594, in box.box.Box.__getitem__
KeyError: 'train_path'

The above exception was the direct cause of the following exception:

Traceback (most recent call last):
  File "box\\box.py", line 633, in box.box.Box.__getattr__
  File "box\\box.py", line 621, in box.box.Box.__getitem__
box.exceptions.BoxKeyError: "'train_path'"

During handling of the above exception, another exception occurred:

Traceback (most recent call last):
  File "box\\box.py", line 635, in box.box.Box.__getattr__
AttributeError: 'ConfigBox' object has no attribute 'train_path'

The above exception was the direct cause of the following exception:

Traceback (most recent call last):
  File "C:\Users\ABDULLAH RIZWAN\OneDrive\Desktop\Data Sciences\MLOPS\DataScienceProject\main.py", line 50, in <module>
    obj.initiate_model_trainer_pipeline()
  File "C:\Users\ABDULLAH RIZWAN\OneDrive\Desktop\Data Sciences\MLOPS\DataScienceProject\src\DataScienceProject\pipeline\ModelTrainerPipeline.py", line 16, in initiate_model_trainer_pipeline
    raise e
  File "C:\Users\ABDULLAH RIZWAN\OneDrive\Desktop\Data Sciences\MLOPS\DataScienceProject\src\DataScienceProject\pipeline\ModelTrainerPipeline.py", line 12, in initiate_model_trainer_pipeline
    model_trainer_config = config.get_model_trainer_config()
                           ^^^^^^^^^^^^^^^^^^^^^^^^^^^^^^^^^
  File "C:\Users\ABDULLAH RIZWAN\OneDrive\Desktop\Data Sciences\MLOPS\DataScienceProject\src\DataScienceProject\config\configuration.py", line 68, in get_model_trainer_config
    train_data_path = config.train_path,
                      ^^^^^^^^^^^^^^^^^
  File "box\\config_box.py", line 31, in box.config_box.ConfigBox.__getattr__
  File "box\\box.py", line 649, in box.box.Box.__getattr__
box.exceptions.BoxKeyError: "'ConfigBox' object has no attribute 'train_path'"
[2025-08-23 16:01:18,706: INFO: main: >>>>> stage Data Ingestion Stage started >>>>>]
[2025-08-23 16:01:18,714: INFO: common: Yaml file: config\config.yaml is loaded successfully]
[2025-08-23 16:01:18,717: INFO: common: Yaml file: params.yaml is loaded successfully]
[2025-08-23 16:01:18,722: INFO: common: Yaml file: schema.yaml is loaded successfully]
[2025-08-23 16:01:18,723: INFO: common: Directory created at artifacts]
[2025-08-23 16:01:18,725: INFO: common: Directory created at artifacts/data_ingestion]
[2025-08-23 16:01:18,726: INFO: data_ingestion: File already exists]
[2025-08-23 16:01:18,735: INFO: main: >>>>> stage Data Ingestion Stage completed >>>>>]
[2025-08-23 16:01:18,736: INFO: main: Alhumdullillah sb okay h boss!]
[2025-08-23 16:01:18,737: INFO: main: >>>>> stage Data Validation Stage started >>>>>]
[2025-08-23 16:01:18,760: INFO: common: Yaml file: config\config.yaml is loaded successfully]
[2025-08-23 16:01:18,775: INFO: common: Yaml file: params.yaml is loaded successfully]
[2025-08-23 16:01:18,792: INFO: common: Yaml file: schema.yaml is loaded successfully]
[2025-08-23 16:01:18,797: INFO: common: Directory created at artifacts]
[2025-08-23 16:01:18,809: INFO: common: Directory created at artifacts/data_validation]
[2025-08-23 16:01:18,914: INFO: main: >>>>> stage Data Validation Stage completed >>>>>]
[2025-08-23 16:01:18,914: INFO: main: >>>>> stage Data Transformation Stage started >>>>>]
[2025-08-23 16:01:18,923: INFO: common: Yaml file: config\config.yaml is loaded successfully]
[2025-08-23 16:01:18,925: INFO: common: Yaml file: params.yaml is loaded successfully]
[2025-08-23 16:01:18,933: INFO: common: Yaml file: schema.yaml is loaded successfully]
[2025-08-23 16:01:18,934: INFO: common: Directory created at artifacts]
[2025-08-23 16:01:18,935: INFO: common: Directory created at artifacts/data_transformation]
[2025-08-23 16:01:19,037: INFO: data_transformation: Spliting completed]
[2025-08-23 16:01:19,037: INFO: data_transformation: Train shape: (1199, 12)]
[2025-08-23 16:01:19,037: INFO: data_transformation: Test  shape: (400, 12)]
[2025-08-23 16:01:19,037: INFO: main: >>>>> stage Data Transformation Stage completed >>>>>]
[2025-08-23 16:01:19,039: INFO: main: >>>>> stage Model Training Stage started >>>>>]
[2025-08-23 16:01:19,046: INFO: common: Yaml file: config\config.yaml is loaded successfully]
[2025-08-23 16:01:19,050: INFO: common: Yaml file: params.yaml is loaded successfully]
[2025-08-23 16:01:19,056: INFO: common: Yaml file: schema.yaml is loaded successfully]
[2025-08-23 16:01:19,057: INFO: common: Directory created at artifacts]
[2025-08-23 16:01:19,058: INFO: common: Directory created at artifacts/model_trainer]
[2025-08-23 16:01:19,059: ERROR: main: "'ConfigBox' object has no attribute 'trget_column'"]
Traceback (most recent call last):
  File "box\\box.py", line 594, in box.box.Box.__getitem__
KeyError: 'trget_column'

The above exception was the direct cause of the following exception:

Traceback (most recent call last):
  File "box\\box.py", line 633, in box.box.Box.__getattr__
  File "box\\box.py", line 621, in box.box.Box.__getitem__
box.exceptions.BoxKeyError: "'trget_column'"

During handling of the above exception, another exception occurred:

Traceback (most recent call last):
  File "box\\box.py", line 635, in box.box.Box.__getattr__
AttributeError: 'ConfigBox' object has no attribute 'trget_column'

The above exception was the direct cause of the following exception:

Traceback (most recent call last):
  File "box\\config_box.py", line 29, in box.config_box.ConfigBox.__getattr__
  File "box\\box.py", line 649, in box.box.Box.__getattr__
box.exceptions.BoxKeyError: "'ConfigBox' object has no attribute 'trget_column'"

During handling of the above exception, another exception occurred:

Traceback (most recent call last):
  File "box\\box.py", line 594, in box.box.Box.__getitem__
KeyError: 'trget_column'

The above exception was the direct cause of the following exception:

Traceback (most recent call last):
  File "box\\box.py", line 633, in box.box.Box.__getattr__
  File "box\\box.py", line 621, in box.box.Box.__getitem__
box.exceptions.BoxKeyError: "'trget_column'"

During handling of the above exception, another exception occurred:

Traceback (most recent call last):
  File "box\\box.py", line 635, in box.box.Box.__getattr__
AttributeError: 'ConfigBox' object has no attribute 'trget_column'

The above exception was the direct cause of the following exception:

Traceback (most recent call last):
  File "C:\Users\ABDULLAH RIZWAN\OneDrive\Desktop\Data Sciences\MLOPS\DataScienceProject\main.py", line 50, in <module>
    obj.initiate_model_trainer_pipeline()
  File "C:\Users\ABDULLAH RIZWAN\OneDrive\Desktop\Data Sciences\MLOPS\DataScienceProject\src\DataScienceProject\pipeline\ModelTrainerPipeline.py", line 16, in initiate_model_trainer_pipeline
    raise e
  File "C:\Users\ABDULLAH RIZWAN\OneDrive\Desktop\Data Sciences\MLOPS\DataScienceProject\src\DataScienceProject\pipeline\ModelTrainerPipeline.py", line 12, in initiate_model_trainer_pipeline
    model_trainer_config = config.get_model_trainer_config()
                           ^^^^^^^^^^^^^^^^^^^^^^^^^^^^^^^^^
  File "C:\Users\ABDULLAH RIZWAN\OneDrive\Desktop\Data Sciences\MLOPS\DataScienceProject\src\DataScienceProject\config\configuration.py", line 73, in get_model_trainer_config
    target_column = schema.trget_column
                    ^^^^^^^^^^^^^^^^^^^
  File "box\\config_box.py", line 31, in box.config_box.ConfigBox.__getattr__
  File "box\\box.py", line 649, in box.box.Box.__getattr__
box.exceptions.BoxKeyError: "'ConfigBox' object has no attribute 'trget_column'"
[2025-08-23 16:02:43,644: INFO: main: >>>>> stage Data Ingestion Stage started >>>>>]
[2025-08-23 16:02:43,654: INFO: common: Yaml file: config\config.yaml is loaded successfully]
[2025-08-23 16:02:43,656: INFO: common: Yaml file: params.yaml is loaded successfully]
[2025-08-23 16:02:43,662: INFO: common: Yaml file: schema.yaml is loaded successfully]
[2025-08-23 16:02:43,665: INFO: common: Directory created at artifacts]
[2025-08-23 16:02:43,666: INFO: common: Directory created at artifacts/data_ingestion]
[2025-08-23 16:02:43,667: INFO: data_ingestion: File already exists]
[2025-08-23 16:02:43,678: INFO: main: >>>>> stage Data Ingestion Stage completed >>>>>]
[2025-08-23 16:02:43,683: INFO: main: Alhumdullillah sb okay h boss!]
[2025-08-23 16:02:43,685: INFO: main: >>>>> stage Data Validation Stage started >>>>>]
[2025-08-23 16:02:43,712: INFO: common: Yaml file: config\config.yaml is loaded successfully]
[2025-08-23 16:02:43,715: INFO: common: Yaml file: params.yaml is loaded successfully]
[2025-08-23 16:02:43,724: INFO: common: Yaml file: schema.yaml is loaded successfully]
[2025-08-23 16:02:43,727: INFO: common: Directory created at artifacts]
[2025-08-23 16:02:43,728: INFO: common: Directory created at artifacts/data_validation]
[2025-08-23 16:02:43,839: INFO: main: >>>>> stage Data Validation Stage completed >>>>>]
[2025-08-23 16:02:43,842: INFO: main: >>>>> stage Data Transformation Stage started >>>>>]
[2025-08-23 16:02:43,873: INFO: common: Yaml file: config\config.yaml is loaded successfully]
[2025-08-23 16:02:43,876: INFO: common: Yaml file: params.yaml is loaded successfully]
[2025-08-23 16:02:43,898: INFO: common: Yaml file: schema.yaml is loaded successfully]
[2025-08-23 16:02:43,902: INFO: common: Directory created at artifacts]
[2025-08-23 16:02:43,903: INFO: common: Directory created at artifacts/data_transformation]
[2025-08-23 16:02:43,964: INFO: data_transformation: Spliting completed]
[2025-08-23 16:02:43,971: INFO: data_transformation: Train shape: (1199, 12)]
[2025-08-23 16:02:43,974: INFO: data_transformation: Test  shape: (400, 12)]
[2025-08-23 16:02:43,977: INFO: main: >>>>> stage Data Transformation Stage completed >>>>>]
[2025-08-23 16:02:43,978: INFO: main: >>>>> stage Model Training Stage started >>>>>]
[2025-08-23 16:02:43,986: INFO: common: Yaml file: config\config.yaml is loaded successfully]
[2025-08-23 16:02:43,990: INFO: common: Yaml file: params.yaml is loaded successfully]
[2025-08-23 16:02:44,005: INFO: common: Yaml file: schema.yaml is loaded successfully]
[2025-08-23 16:02:44,010: INFO: common: Directory created at artifacts]
[2025-08-23 16:02:44,013: INFO: common: Directory created at artifacts/model_trainer]
[2025-08-23 16:02:44,014: ERROR: main: "'ConfigBox' object has no attribute 'target_column'"]
Traceback (most recent call last):
  File "box\\box.py", line 594, in box.box.Box.__getitem__
KeyError: 'TARGET_COLUMN'

The above exception was the direct cause of the following exception:

Traceback (most recent call last):
  File "box\\box.py", line 633, in box.box.Box.__getattr__
  File "box\\box.py", line 621, in box.box.Box.__getitem__
box.exceptions.BoxKeyError: "'TARGET_COLUMN'"

During handling of the above exception, another exception occurred:

Traceback (most recent call last):
  File "box\\box.py", line 635, in box.box.Box.__getattr__
AttributeError: 'ConfigBox' object has no attribute 'TARGET_COLUMN'

The above exception was the direct cause of the following exception:

Traceback (most recent call last):
  File "box\\config_box.py", line 29, in box.config_box.ConfigBox.__getattr__
  File "box\\box.py", line 649, in box.box.Box.__getattr__
box.exceptions.BoxKeyError: "'ConfigBox' object has no attribute 'TARGET_COLUMN'"

During handling of the above exception, another exception occurred:

Traceback (most recent call last):
  File "box\\box.py", line 594, in box.box.Box.__getitem__
KeyError: 'target_column'

The above exception was the direct cause of the following exception:

Traceback (most recent call last):
  File "box\\box.py", line 633, in box.box.Box.__getattr__
  File "box\\box.py", line 621, in box.box.Box.__getitem__
box.exceptions.BoxKeyError: "'target_column'"

During handling of the above exception, another exception occurred:

Traceback (most recent call last):
  File "box\\box.py", line 635, in box.box.Box.__getattr__
AttributeError: 'ConfigBox' object has no attribute 'target_column'

The above exception was the direct cause of the following exception:

Traceback (most recent call last):
  File "C:\Users\ABDULLAH RIZWAN\OneDrive\Desktop\Data Sciences\MLOPS\DataScienceProject\main.py", line 50, in <module>
    obj.initiate_model_trainer_pipeline()
  File "C:\Users\ABDULLAH RIZWAN\OneDrive\Desktop\Data Sciences\MLOPS\DataScienceProject\src\DataScienceProject\pipeline\ModelTrainerPipeline.py", line 16, in initiate_model_trainer_pipeline
    raise e
  File "C:\Users\ABDULLAH RIZWAN\OneDrive\Desktop\Data Sciences\MLOPS\DataScienceProject\src\DataScienceProject\pipeline\ModelTrainerPipeline.py", line 12, in initiate_model_trainer_pipeline
    model_trainer_config = config.get_model_trainer_config()
                           ^^^^^^^^^^^^^^^^^^^^^^^^^^^^^^^^^
  File "C:\Users\ABDULLAH RIZWAN\OneDrive\Desktop\Data Sciences\MLOPS\DataScienceProject\src\DataScienceProject\config\configuration.py", line 73, in get_model_trainer_config
    target_column = schema.TARGET_COLUMN
                    ^^^^^^^^^^^^^^^^^^^^
  File "box\\config_box.py", line 31, in box.config_box.ConfigBox.__getattr__
  File "box\\box.py", line 649, in box.box.Box.__getattr__
box.exceptions.BoxKeyError: "'ConfigBox' object has no attribute 'target_column'"
[2025-08-23 16:04:31,076: INFO: main: >>>>> stage Data Ingestion Stage started >>>>>]
[2025-08-23 16:04:31,086: INFO: common: Yaml file: config\config.yaml is loaded successfully]
[2025-08-23 16:04:31,090: INFO: common: Yaml file: params.yaml is loaded successfully]
[2025-08-23 16:04:31,095: INFO: common: Yaml file: schema.yaml is loaded successfully]
[2025-08-23 16:04:31,098: INFO: common: Directory created at artifacts]
[2025-08-23 16:04:31,100: INFO: common: Directory created at artifacts/data_ingestion]
[2025-08-23 16:04:31,101: INFO: data_ingestion: File already exists]
[2025-08-23 16:04:31,114: INFO: main: >>>>> stage Data Ingestion Stage completed >>>>>]
[2025-08-23 16:04:31,115: INFO: main: Alhumdullillah sb okay h boss!]
[2025-08-23 16:04:31,126: INFO: main: >>>>> stage Data Validation Stage started >>>>>]
[2025-08-23 16:04:31,148: INFO: common: Yaml file: config\config.yaml is loaded successfully]
[2025-08-23 16:04:31,181: INFO: common: Yaml file: params.yaml is loaded successfully]
[2025-08-23 16:04:31,196: INFO: common: Yaml file: schema.yaml is loaded successfully]
[2025-08-23 16:04:31,199: INFO: common: Directory created at artifacts]
[2025-08-23 16:04:31,205: INFO: common: Directory created at artifacts/data_validation]
[2025-08-23 16:04:31,291: INFO: main: >>>>> stage Data Validation Stage completed >>>>>]
[2025-08-23 16:04:31,295: INFO: main: >>>>> stage Data Transformation Stage started >>>>>]
[2025-08-23 16:04:31,312: INFO: common: Yaml file: config\config.yaml is loaded successfully]
[2025-08-23 16:04:31,321: INFO: common: Yaml file: params.yaml is loaded successfully]
[2025-08-23 16:04:31,331: INFO: common: Yaml file: schema.yaml is loaded successfully]
[2025-08-23 16:04:31,344: INFO: common: Directory created at artifacts]
[2025-08-23 16:04:31,351: INFO: common: Directory created at artifacts/data_transformation]
[2025-08-23 16:04:31,482: INFO: data_transformation: Spliting completed]
[2025-08-23 16:04:31,483: INFO: data_transformation: Train shape: (1199, 12)]
[2025-08-23 16:04:31,484: INFO: data_transformation: Test  shape: (400, 12)]
[2025-08-23 16:04:31,486: INFO: main: >>>>> stage Data Transformation Stage completed >>>>>]
[2025-08-23 16:04:31,486: INFO: main: >>>>> stage Model Training Stage started >>>>>]
[2025-08-23 16:04:31,497: INFO: common: Yaml file: config\config.yaml is loaded successfully]
[2025-08-23 16:04:31,502: INFO: common: Yaml file: params.yaml is loaded successfully]
[2025-08-23 16:04:31,522: INFO: common: Yaml file: schema.yaml is loaded successfully]
[2025-08-23 16:04:31,528: INFO: common: Directory created at artifacts]
[2025-08-23 16:04:31,538: INFO: common: Directory created at artifacts/model_trainer]
[2025-08-23 16:04:31,546: ERROR: main: "'ConfigBox' object has no attribute 'target_column'"]
Traceback (most recent call last):
  File "box\\box.py", line 594, in box.box.Box.__getitem__
KeyError: 'TARGET_COLUMN'

The above exception was the direct cause of the following exception:

Traceback (most recent call last):
  File "box\\box.py", line 633, in box.box.Box.__getattr__
  File "box\\box.py", line 621, in box.box.Box.__getitem__
box.exceptions.BoxKeyError: "'TARGET_COLUMN'"

During handling of the above exception, another exception occurred:

Traceback (most recent call last):
  File "box\\box.py", line 635, in box.box.Box.__getattr__
AttributeError: 'ConfigBox' object has no attribute 'TARGET_COLUMN'

The above exception was the direct cause of the following exception:

Traceback (most recent call last):
  File "box\\config_box.py", line 29, in box.config_box.ConfigBox.__getattr__
  File "box\\box.py", line 649, in box.box.Box.__getattr__
box.exceptions.BoxKeyError: "'ConfigBox' object has no attribute 'TARGET_COLUMN'"

During handling of the above exception, another exception occurred:

Traceback (most recent call last):
  File "box\\box.py", line 594, in box.box.Box.__getitem__
KeyError: 'target_column'

The above exception was the direct cause of the following exception:

Traceback (most recent call last):
  File "box\\box.py", line 633, in box.box.Box.__getattr__
  File "box\\box.py", line 621, in box.box.Box.__getitem__
box.exceptions.BoxKeyError: "'target_column'"

During handling of the above exception, another exception occurred:

Traceback (most recent call last):
  File "box\\box.py", line 635, in box.box.Box.__getattr__
AttributeError: 'ConfigBox' object has no attribute 'target_column'

The above exception was the direct cause of the following exception:

Traceback (most recent call last):
  File "C:\Users\ABDULLAH RIZWAN\OneDrive\Desktop\Data Sciences\MLOPS\DataScienceProject\main.py", line 50, in <module>
    obj.initiate_model_trainer_pipeline()
  File "C:\Users\ABDULLAH RIZWAN\OneDrive\Desktop\Data Sciences\MLOPS\DataScienceProject\src\DataScienceProject\pipeline\ModelTrainerPipeline.py", line 16, in initiate_model_trainer_pipeline
    raise e
  File "C:\Users\ABDULLAH RIZWAN\OneDrive\Desktop\Data Sciences\MLOPS\DataScienceProject\src\DataScienceProject\pipeline\ModelTrainerPipeline.py", line 12, in initiate_model_trainer_pipeline
    model_trainer_config = config.get_model_trainer_config()
                           ^^^^^^^^^^^^^^^^^^^^^^^^^^^^^^^^^
  File "C:\Users\ABDULLAH RIZWAN\OneDrive\Desktop\Data Sciences\MLOPS\DataScienceProject\src\DataScienceProject\config\configuration.py", line 73, in get_model_trainer_config
    target_column = schema.TARGET_COLUMN
                    ^^^^^^^^^^^^^^^^^^^^
  File "box\\config_box.py", line 31, in box.config_box.ConfigBox.__getattr__
  File "box\\box.py", line 649, in box.box.Box.__getattr__
box.exceptions.BoxKeyError: "'ConfigBox' object has no attribute 'target_column'"
[2025-08-23 16:05:46,247: INFO: main: >>>>> stage Data Ingestion Stage started >>>>>]
[2025-08-23 16:05:46,256: INFO: common: Yaml file: config\config.yaml is loaded successfully]
[2025-08-23 16:05:46,259: INFO: common: Yaml file: params.yaml is loaded successfully]
[2025-08-23 16:05:46,266: INFO: common: Yaml file: schema.yaml is loaded successfully]
[2025-08-23 16:05:46,269: INFO: common: Directory created at artifacts]
[2025-08-23 16:05:46,270: INFO: common: Directory created at artifacts/data_ingestion]
[2025-08-23 16:05:46,271: INFO: data_ingestion: File already exists]
[2025-08-23 16:05:46,282: INFO: main: >>>>> stage Data Ingestion Stage completed >>>>>]
[2025-08-23 16:05:46,284: INFO: main: Alhumdullillah sb okay h boss!]
[2025-08-23 16:05:46,284: INFO: main: >>>>> stage Data Validation Stage started >>>>>]
[2025-08-23 16:05:46,307: INFO: common: Yaml file: config\config.yaml is loaded successfully]
[2025-08-23 16:05:46,337: INFO: common: Yaml file: params.yaml is loaded successfully]
[2025-08-23 16:05:46,378: INFO: common: Yaml file: schema.yaml is loaded successfully]
[2025-08-23 16:05:46,387: INFO: common: Directory created at artifacts]
[2025-08-23 16:05:46,391: INFO: common: Directory created at artifacts/data_validation]
[2025-08-23 16:05:46,499: INFO: main: >>>>> stage Data Validation Stage completed >>>>>]
[2025-08-23 16:05:46,500: INFO: main: >>>>> stage Data Transformation Stage started >>>>>]
[2025-08-23 16:05:46,508: INFO: common: Yaml file: config\config.yaml is loaded successfully]
[2025-08-23 16:05:46,512: INFO: common: Yaml file: params.yaml is loaded successfully]
[2025-08-23 16:05:46,517: INFO: common: Yaml file: schema.yaml is loaded successfully]
[2025-08-23 16:05:46,519: INFO: common: Directory created at artifacts]
[2025-08-23 16:05:46,520: INFO: common: Directory created at artifacts/data_transformation]
[2025-08-23 16:05:46,625: INFO: data_transformation: Spliting completed]
[2025-08-23 16:05:46,626: INFO: data_transformation: Train shape: (1199, 12)]
[2025-08-23 16:05:46,627: INFO: data_transformation: Test  shape: (400, 12)]
[2025-08-23 16:05:46,627: INFO: main: >>>>> stage Data Transformation Stage completed >>>>>]
[2025-08-23 16:05:46,630: INFO: main: >>>>> stage Model Training Stage started >>>>>]
[2025-08-23 16:05:46,636: INFO: common: Yaml file: config\config.yaml is loaded successfully]
[2025-08-23 16:05:46,641: INFO: common: Yaml file: params.yaml is loaded successfully]
[2025-08-23 16:05:46,649: INFO: common: Yaml file: schema.yaml is loaded successfully]
[2025-08-23 16:05:46,651: INFO: common: Directory created at artifacts]
[2025-08-23 16:05:46,652: INFO: common: Directory created at artifacts/model_trainer]
[2025-08-23 16:05:46,653: ERROR: main: name 'slef' is not defined]
Traceback (most recent call last):
  File "C:\Users\ABDULLAH RIZWAN\OneDrive\Desktop\Data Sciences\MLOPS\DataScienceProject\main.py", line 50, in <module>
    obj.initiate_model_trainer_pipeline()
  File "C:\Users\ABDULLAH RIZWAN\OneDrive\Desktop\Data Sciences\MLOPS\DataScienceProject\src\DataScienceProject\pipeline\ModelTrainerPipeline.py", line 16, in initiate_model_trainer_pipeline
    raise e
  File "C:\Users\ABDULLAH RIZWAN\OneDrive\Desktop\Data Sciences\MLOPS\DataScienceProject\src\DataScienceProject\pipeline\ModelTrainerPipeline.py", line 13, in initiate_model_trainer_pipeline
    model_trainer = ModelTrainer(config = model_trainer_config)
                    ^^^^^^^^^^^^^^^^^^^^^^^^^^^^^^^^^^^^^^^^^^^
  File "C:\Users\ABDULLAH RIZWAN\OneDrive\Desktop\Data Sciences\MLOPS\DataScienceProject\src\DataScienceProject\components\model_trainer.py", line 10, in __init__
    slef.config = ModelTrainerConfig
    ^^^^
NameError: name 'slef' is not defined
[2025-08-23 16:07:00,587: INFO: main: >>>>> stage Data Ingestion Stage started >>>>>]
[2025-08-23 16:07:00,595: INFO: common: Yaml file: config\config.yaml is loaded successfully]
[2025-08-23 16:07:00,597: INFO: common: Yaml file: params.yaml is loaded successfully]
[2025-08-23 16:07:00,604: INFO: common: Yaml file: schema.yaml is loaded successfully]
[2025-08-23 16:07:00,606: INFO: common: Directory created at artifacts]
[2025-08-23 16:07:00,606: INFO: common: Directory created at artifacts/data_ingestion]
[2025-08-23 16:07:00,608: INFO: data_ingestion: File already exists]
[2025-08-23 16:07:00,620: INFO: main: >>>>> stage Data Ingestion Stage completed >>>>>]
[2025-08-23 16:07:00,620: INFO: main: Alhumdullillah sb okay h boss!]
[2025-08-23 16:07:00,637: INFO: main: >>>>> stage Data Validation Stage started >>>>>]
[2025-08-23 16:07:00,670: INFO: common: Yaml file: config\config.yaml is loaded successfully]
[2025-08-23 16:07:00,674: INFO: common: Yaml file: params.yaml is loaded successfully]
[2025-08-23 16:07:00,692: INFO: common: Yaml file: schema.yaml is loaded successfully]
[2025-08-23 16:07:00,703: INFO: common: Directory created at artifacts]
[2025-08-23 16:07:00,705: INFO: common: Directory created at artifacts/data_validation]
[2025-08-23 16:07:00,814: INFO: main: >>>>> stage Data Validation Stage completed >>>>>]
[2025-08-23 16:07:00,814: INFO: main: >>>>> stage Data Transformation Stage started >>>>>]
[2025-08-23 16:07:00,821: INFO: common: Yaml file: config\config.yaml is loaded successfully]
[2025-08-23 16:07:00,823: INFO: common: Yaml file: params.yaml is loaded successfully]
[2025-08-23 16:07:00,829: INFO: common: Yaml file: schema.yaml is loaded successfully]
[2025-08-23 16:07:00,830: INFO: common: Directory created at artifacts]
[2025-08-23 16:07:00,832: INFO: common: Directory created at artifacts/data_transformation]
[2025-08-23 16:07:00,925: INFO: data_transformation: Spliting completed]
[2025-08-23 16:07:00,925: INFO: data_transformation: Train shape: (1199, 12)]
[2025-08-23 16:07:00,926: INFO: data_transformation: Test  shape: (400, 12)]
[2025-08-23 16:07:00,927: INFO: main: >>>>> stage Data Transformation Stage completed >>>>>]
[2025-08-23 16:07:00,928: INFO: main: >>>>> stage Model Training Stage started >>>>>]
[2025-08-23 16:07:00,936: INFO: common: Yaml file: config\config.yaml is loaded successfully]
[2025-08-23 16:07:00,941: INFO: common: Yaml file: params.yaml is loaded successfully]
[2025-08-23 16:07:00,951: INFO: common: Yaml file: schema.yaml is loaded successfully]
[2025-08-23 16:07:00,954: INFO: common: Directory created at artifacts]
[2025-08-23 16:07:00,955: INFO: common: Directory created at artifacts/model_trainer]
[2025-08-23 16:07:00,956: ERROR: main: name 'read_csv' is not defined]
Traceback (most recent call last):
  File "C:\Users\ABDULLAH RIZWAN\OneDrive\Desktop\Data Sciences\MLOPS\DataScienceProject\main.py", line 50, in <module>
    obj.initiate_model_trainer_pipeline()
  File "C:\Users\ABDULLAH RIZWAN\OneDrive\Desktop\Data Sciences\MLOPS\DataScienceProject\src\DataScienceProject\pipeline\ModelTrainerPipeline.py", line 16, in initiate_model_trainer_pipeline
    raise e
  File "C:\Users\ABDULLAH RIZWAN\OneDrive\Desktop\Data Sciences\MLOPS\DataScienceProject\src\DataScienceProject\pipeline\ModelTrainerPipeline.py", line 14, in initiate_model_trainer_pipeline
    model_trainer.train()
  File "C:\Users\ABDULLAH RIZWAN\OneDrive\Desktop\Data Sciences\MLOPS\DataScienceProject\src\DataScienceProject\components\model_trainer.py", line 13, in train
    train_data = read_csv(self.config.train_data_path)
                 ^^^^^^^^
NameError: name 'read_csv' is not defined
[2025-08-23 16:07:28,137: INFO: main: >>>>> stage Data Ingestion Stage started >>>>>]
[2025-08-23 16:07:28,142: INFO: common: Yaml file: config\config.yaml is loaded successfully]
[2025-08-23 16:07:28,144: INFO: common: Yaml file: params.yaml is loaded successfully]
[2025-08-23 16:07:28,147: INFO: common: Yaml file: schema.yaml is loaded successfully]
[2025-08-23 16:07:28,148: INFO: common: Directory created at artifacts]
[2025-08-23 16:07:28,151: INFO: common: Directory created at artifacts/data_ingestion]
[2025-08-23 16:07:28,152: INFO: data_ingestion: File already exists]
[2025-08-23 16:07:28,168: INFO: main: >>>>> stage Data Ingestion Stage completed >>>>>]
[2025-08-23 16:07:28,174: INFO: main: Alhumdullillah sb okay h boss!]
[2025-08-23 16:07:28,174: INFO: main: >>>>> stage Data Validation Stage started >>>>>]
[2025-08-23 16:07:28,214: INFO: common: Yaml file: config\config.yaml is loaded successfully]
[2025-08-23 16:07:28,247: INFO: common: Yaml file: params.yaml is loaded successfully]
[2025-08-23 16:07:28,298: INFO: common: Yaml file: schema.yaml is loaded successfully]
[2025-08-23 16:07:28,335: INFO: common: Directory created at artifacts]
[2025-08-23 16:07:28,337: INFO: common: Directory created at artifacts/data_validation]
[2025-08-23 16:07:28,474: INFO: main: >>>>> stage Data Validation Stage completed >>>>>]
[2025-08-23 16:07:28,475: INFO: main: >>>>> stage Data Transformation Stage started >>>>>]
[2025-08-23 16:07:28,486: INFO: common: Yaml file: config\config.yaml is loaded successfully]
[2025-08-23 16:07:28,491: INFO: common: Yaml file: params.yaml is loaded successfully]
[2025-08-23 16:07:28,496: INFO: common: Yaml file: schema.yaml is loaded successfully]
[2025-08-23 16:07:28,497: INFO: common: Directory created at artifacts]
[2025-08-23 16:07:28,497: INFO: common: Directory created at artifacts/data_transformation]
[2025-08-23 16:07:28,623: INFO: data_transformation: Spliting completed]
[2025-08-23 16:07:28,624: INFO: data_transformation: Train shape: (1199, 12)]
[2025-08-23 16:07:28,625: INFO: data_transformation: Test  shape: (400, 12)]
[2025-08-23 16:07:28,626: INFO: main: >>>>> stage Data Transformation Stage completed >>>>>]
[2025-08-23 16:07:28,627: INFO: main: >>>>> stage Model Training Stage started >>>>>]
[2025-08-23 16:07:28,635: INFO: common: Yaml file: config\config.yaml is loaded successfully]
[2025-08-23 16:07:28,637: INFO: common: Yaml file: params.yaml is loaded successfully]
[2025-08-23 16:07:28,642: INFO: common: Yaml file: schema.yaml is loaded successfully]
[2025-08-23 16:07:28,645: INFO: common: Directory created at artifacts]
[2025-08-23 16:07:28,646: INFO: common: Directory created at artifacts/model_trainer]
[2025-08-23 16:07:28,646: ERROR: main: type object 'ModelTrainerConfig' has no attribute 'train_data_path']
Traceback (most recent call last):
  File "C:\Users\ABDULLAH RIZWAN\OneDrive\Desktop\Data Sciences\MLOPS\DataScienceProject\main.py", line 50, in <module>
    obj.initiate_model_trainer_pipeline()
  File "C:\Users\ABDULLAH RIZWAN\OneDrive\Desktop\Data Sciences\MLOPS\DataScienceProject\src\DataScienceProject\pipeline\ModelTrainerPipeline.py", line 16, in initiate_model_trainer_pipeline
    raise e
  File "C:\Users\ABDULLAH RIZWAN\OneDrive\Desktop\Data Sciences\MLOPS\DataScienceProject\src\DataScienceProject\pipeline\ModelTrainerPipeline.py", line 14, in initiate_model_trainer_pipeline
    model_trainer.train()
  File "C:\Users\ABDULLAH RIZWAN\OneDrive\Desktop\Data Sciences\MLOPS\DataScienceProject\src\DataScienceProject\components\model_trainer.py", line 13, in train
    train_data = pd.read_csv(self.config.train_data_path)
                             ^^^^^^^^^^^^^^^^^^^^^^^^^^^
AttributeError: type object 'ModelTrainerConfig' has no attribute 'train_data_path'
[2025-08-23 16:08:13,836: INFO: main: >>>>> stage Data Ingestion Stage started >>>>>]
[2025-08-23 16:08:13,845: INFO: common: Yaml file: config\config.yaml is loaded successfully]
[2025-08-23 16:08:13,848: INFO: common: Yaml file: params.yaml is loaded successfully]
[2025-08-23 16:08:13,853: INFO: common: Yaml file: schema.yaml is loaded successfully]
[2025-08-23 16:08:13,854: INFO: common: Directory created at artifacts]
[2025-08-23 16:08:13,855: INFO: common: Directory created at artifacts/data_ingestion]
[2025-08-23 16:08:13,856: INFO: data_ingestion: File already exists]
[2025-08-23 16:08:13,866: INFO: main: >>>>> stage Data Ingestion Stage completed >>>>>]
[2025-08-23 16:08:13,867: INFO: main: Alhumdullillah sb okay h boss!]
[2025-08-23 16:08:13,868: INFO: main: >>>>> stage Data Validation Stage started >>>>>]
[2025-08-23 16:08:13,905: INFO: common: Yaml file: config\config.yaml is loaded successfully]
[2025-08-23 16:08:13,912: INFO: common: Yaml file: params.yaml is loaded successfully]
[2025-08-23 16:08:13,922: INFO: common: Yaml file: schema.yaml is loaded successfully]
[2025-08-23 16:08:13,924: INFO: common: Directory created at artifacts]
[2025-08-23 16:08:13,925: INFO: common: Directory created at artifacts/data_validation]
[2025-08-23 16:08:14,123: INFO: main: >>>>> stage Data Validation Stage completed >>>>>]
[2025-08-23 16:08:14,144: INFO: main: >>>>> stage Data Transformation Stage started >>>>>]
[2025-08-23 16:08:14,195: INFO: common: Yaml file: config\config.yaml is loaded successfully]
[2025-08-23 16:08:14,219: INFO: common: Yaml file: params.yaml is loaded successfully]
[2025-08-23 16:08:14,323: INFO: common: Yaml file: schema.yaml is loaded successfully]
[2025-08-23 16:08:14,339: INFO: common: Directory created at artifacts]
[2025-08-23 16:08:14,356: INFO: common: Directory created at artifacts/data_transformation]
[2025-08-23 16:08:14,478: INFO: data_transformation: Spliting completed]
[2025-08-23 16:08:14,479: INFO: data_transformation: Train shape: (1199, 12)]
[2025-08-23 16:08:14,480: INFO: data_transformation: Test  shape: (400, 12)]
[2025-08-23 16:08:14,480: INFO: main: >>>>> stage Data Transformation Stage completed >>>>>]
[2025-08-23 16:08:14,481: INFO: main: >>>>> stage Model Training Stage started >>>>>]
[2025-08-23 16:08:14,486: INFO: common: Yaml file: config\config.yaml is loaded successfully]
[2025-08-23 16:08:14,489: INFO: common: Yaml file: params.yaml is loaded successfully]
[2025-08-23 16:08:14,495: INFO: common: Yaml file: schema.yaml is loaded successfully]
[2025-08-23 16:08:14,497: INFO: common: Directory created at artifacts]
[2025-08-23 16:08:14,499: INFO: common: Directory created at artifacts/model_trainer]
[2025-08-23 16:08:14,500: ERROR: main: type object 'ModelTrainerConfig' has no attribute 'train_path']
Traceback (most recent call last):
  File "C:\Users\ABDULLAH RIZWAN\OneDrive\Desktop\Data Sciences\MLOPS\DataScienceProject\main.py", line 50, in <module>
    obj.initiate_model_trainer_pipeline()
  File "C:\Users\ABDULLAH RIZWAN\OneDrive\Desktop\Data Sciences\MLOPS\DataScienceProject\src\DataScienceProject\pipeline\ModelTrainerPipeline.py", line 16, in initiate_model_trainer_pipeline
    raise e
  File "C:\Users\ABDULLAH RIZWAN\OneDrive\Desktop\Data Sciences\MLOPS\DataScienceProject\src\DataScienceProject\pipeline\ModelTrainerPipeline.py", line 14, in initiate_model_trainer_pipeline
    model_trainer.train()
  File "C:\Users\ABDULLAH RIZWAN\OneDrive\Desktop\Data Sciences\MLOPS\DataScienceProject\src\DataScienceProject\components\model_trainer.py", line 13, in train
    train_data = pd.read_csv(self.config.train_path)
                             ^^^^^^^^^^^^^^^^^^^^^^
AttributeError: type object 'ModelTrainerConfig' has no attribute 'train_path'
[2025-08-23 16:22:52,460: INFO: main: >>>>> stage Data Ingestion Stage started >>>>>]
[2025-08-23 16:22:52,472: INFO: common: Yaml file: config\config.yaml is loaded successfully]
[2025-08-23 16:22:52,477: INFO: common: Yaml file: params.yaml is loaded successfully]
[2025-08-23 16:22:52,485: INFO: common: Yaml file: schema.yaml is loaded successfully]
[2025-08-23 16:22:52,552: INFO: common: Directory created at artifacts]
[2025-08-23 16:22:52,578: INFO: common: Directory created at artifacts/data_ingestion]
[2025-08-23 16:22:52,584: INFO: data_ingestion: File already exists]
[2025-08-23 16:22:52,694: INFO: main: >>>>> stage Data Ingestion Stage completed >>>>>]
[2025-08-23 16:22:52,695: INFO: main: Alhumdullillah sb okay h boss!]
[2025-08-23 16:22:52,695: INFO: main: >>>>> stage Data Validation Stage started >>>>>]
[2025-08-23 16:22:52,705: INFO: common: Yaml file: config\config.yaml is loaded successfully]
[2025-08-23 16:22:52,709: INFO: common: Yaml file: params.yaml is loaded successfully]
[2025-08-23 16:22:52,720: INFO: common: Yaml file: schema.yaml is loaded successfully]
[2025-08-23 16:22:52,724: INFO: common: Directory created at artifacts]
[2025-08-23 16:22:52,726: INFO: common: Directory created at artifacts/data_validation]
[2025-08-23 16:22:52,872: INFO: main: >>>>> stage Data Validation Stage completed >>>>>]
[2025-08-23 16:22:52,874: INFO: main: >>>>> stage Data Transformation Stage started >>>>>]
[2025-08-23 16:22:52,887: INFO: common: Yaml file: config\config.yaml is loaded successfully]
[2025-08-23 16:22:52,912: INFO: common: Yaml file: params.yaml is loaded successfully]
[2025-08-23 16:22:52,947: INFO: common: Yaml file: schema.yaml is loaded successfully]
[2025-08-23 16:22:52,949: INFO: common: Directory created at artifacts]
[2025-08-23 16:22:52,950: INFO: common: Directory created at artifacts/data_transformation]
[2025-08-23 16:22:53,132: INFO: data_transformation: Spliting completed]
[2025-08-23 16:22:53,137: INFO: data_transformation: Train shape: (1199, 12)]
[2025-08-23 16:22:53,140: INFO: data_transformation: Test  shape: (400, 12)]
[2025-08-23 16:22:53,144: INFO: main: >>>>> stage Data Transformation Stage completed >>>>>]
[2025-08-23 16:22:53,145: INFO: main: >>>>> stage Model Training Stage started >>>>>]
[2025-08-23 16:22:53,155: INFO: common: Yaml file: config\config.yaml is loaded successfully]
[2025-08-23 16:22:53,182: INFO: common: Yaml file: params.yaml is loaded successfully]
[2025-08-23 16:22:53,203: INFO: common: Yaml file: schema.yaml is loaded successfully]
[2025-08-23 16:22:53,218: INFO: common: Directory created at artifacts]
[2025-08-23 16:22:53,250: INFO: common: Directory created at artifacts/model_trainer]
[2025-08-23 16:22:53,252: ERROR: main: type object 'ModelTrainerConfig' has no attribute 'train_path']
Traceback (most recent call last):
  File "C:\Users\ABDULLAH RIZWAN\OneDrive\Desktop\Data Sciences\MLOPS\DataScienceProject\main.py", line 50, in <module>
    obj.initiate_model_trainer_pipeline()
  File "C:\Users\ABDULLAH RIZWAN\OneDrive\Desktop\Data Sciences\MLOPS\DataScienceProject\src\DataScienceProject\pipeline\ModelTrainerPipeline.py", line 16, in initiate_model_trainer_pipeline
    raise e
  File "C:\Users\ABDULLAH RIZWAN\OneDrive\Desktop\Data Sciences\MLOPS\DataScienceProject\src\DataScienceProject\pipeline\ModelTrainerPipeline.py", line 14, in initiate_model_trainer_pipeline
    model_trainer.train()
  File "C:\Users\ABDULLAH RIZWAN\OneDrive\Desktop\Data Sciences\MLOPS\DataScienceProject\src\DataScienceProject\components\model_trainer.py", line 13, in train
    train_data = pd.read_csv(self.config.train_path)
                             ^^^^^^^^^^^^^^^^^^^^^^
AttributeError: type object 'ModelTrainerConfig' has no attribute 'train_path'
[2025-08-23 16:26:39,938: INFO: main: >>>>> stage Data Ingestion Stage started >>>>>]
[2025-08-23 16:26:39,945: INFO: common: Yaml file: config\config.yaml is loaded successfully]
[2025-08-23 16:26:39,947: INFO: common: Yaml file: params.yaml is loaded successfully]
[2025-08-23 16:26:39,952: INFO: common: Yaml file: schema.yaml is loaded successfully]
[2025-08-23 16:26:39,953: INFO: common: Directory created at artifacts]
[2025-08-23 16:26:39,954: INFO: common: Directory created at artifacts/data_ingestion]
[2025-08-23 16:26:39,955: INFO: data_ingestion: File already exists]
[2025-08-23 16:26:39,971: INFO: main: >>>>> stage Data Ingestion Stage completed >>>>>]
[2025-08-23 16:26:39,974: INFO: main: Alhumdullillah sb okay h boss!]
[2025-08-23 16:26:39,981: INFO: main: >>>>> stage Data Validation Stage started >>>>>]
[2025-08-23 16:26:39,993: INFO: common: Yaml file: config\config.yaml is loaded successfully]
[2025-08-23 16:26:40,000: INFO: common: Yaml file: params.yaml is loaded successfully]
[2025-08-23 16:26:40,018: INFO: common: Yaml file: schema.yaml is loaded successfully]
[2025-08-23 16:26:40,027: INFO: common: Directory created at artifacts]
[2025-08-23 16:26:40,028: INFO: common: Directory created at artifacts/data_validation]
[2025-08-23 16:26:40,111: INFO: main: >>>>> stage Data Validation Stage completed >>>>>]
[2025-08-23 16:26:40,112: INFO: main: >>>>> stage Data Transformation Stage started >>>>>]
[2025-08-23 16:26:40,132: INFO: common: Yaml file: config\config.yaml is loaded successfully]
[2025-08-23 16:26:40,135: INFO: common: Yaml file: params.yaml is loaded successfully]
[2025-08-23 16:26:40,146: INFO: common: Yaml file: schema.yaml is loaded successfully]
[2025-08-23 16:26:40,148: INFO: common: Directory created at artifacts]
[2025-08-23 16:26:40,153: INFO: common: Directory created at artifacts/data_transformation]
[2025-08-23 16:26:40,250: INFO: data_transformation: Spliting completed]
[2025-08-23 16:26:40,251: INFO: data_transformation: Train shape: (1199, 12)]
[2025-08-23 16:26:40,252: INFO: data_transformation: Test  shape: (400, 12)]
[2025-08-23 16:26:40,252: INFO: main: >>>>> stage Data Transformation Stage completed >>>>>]
[2025-08-23 16:26:40,253: INFO: main: >>>>> stage Model Training Stage started >>>>>]
[2025-08-23 16:26:40,260: INFO: common: Yaml file: config\config.yaml is loaded successfully]
[2025-08-23 16:26:40,263: INFO: common: Yaml file: params.yaml is loaded successfully]
[2025-08-23 16:26:40,267: INFO: common: Yaml file: schema.yaml is loaded successfully]
[2025-08-23 16:26:40,268: INFO: common: Directory created at artifacts]
[2025-08-23 16:26:40,272: INFO: common: Directory created at artifacts/model_trainer]
[2025-08-23 16:26:40,402: ERROR: main: unhashable type: "Box"]
Traceback (most recent call last):
  File "C:\Users\ABDULLAH RIZWAN\OneDrive\Desktop\Data Sciences\MLOPS\DataScienceProject\main.py", line 50, in <module>
    obj.initiate_model_trainer_pipeline()
  File "C:\Users\ABDULLAH RIZWAN\OneDrive\Desktop\Data Sciences\MLOPS\DataScienceProject\src\DataScienceProject\pipeline\ModelTrainerPipeline.py", line 16, in initiate_model_trainer_pipeline
    raise e
  File "C:\Users\ABDULLAH RIZWAN\OneDrive\Desktop\Data Sciences\MLOPS\DataScienceProject\src\DataScienceProject\pipeline\ModelTrainerPipeline.py", line 14, in initiate_model_trainer_pipeline
    model_trainer.train()
  File "C:\Users\ABDULLAH RIZWAN\OneDrive\Desktop\Data Sciences\MLOPS\DataScienceProject\src\DataScienceProject\components\model_trainer.py", line 16, in train
    train_x = train_data.drop([self.config.target_column], axis=1)
              ^^^^^^^^^^^^^^^^^^^^^^^^^^^^^^^^^^^^^^^^^^^^^^^^^^^^
  File "C:\Users\ABDULLAH RIZWAN\OneDrive\Desktop\Data Sciences\MLOPS\DataScienceProject\.venv\Lib\site-packages\pandas\core\frame.py", line 5588, in drop
    return super().drop(
           ^^^^^^^^^^^^^
  File "C:\Users\ABDULLAH RIZWAN\OneDrive\Desktop\Data Sciences\MLOPS\DataScienceProject\.venv\Lib\site-packages\pandas\core\generic.py", line 4807, in drop
    obj = obj._drop_axis(labels, axis, level=level, errors=errors)
          ^^^^^^^^^^^^^^^^^^^^^^^^^^^^^^^^^^^^^^^^^^^^^^^^^^^^^^^^
  File "C:\Users\ABDULLAH RIZWAN\OneDrive\Desktop\Data Sciences\MLOPS\DataScienceProject\.venv\Lib\site-packages\pandas\core\generic.py", line 4849, in _drop_axis
    new_axis = axis.drop(labels, errors=errors)
               ^^^^^^^^^^^^^^^^^^^^^^^^^^^^^^^^
  File "C:\Users\ABDULLAH RIZWAN\OneDrive\Desktop\Data Sciences\MLOPS\DataScienceProject\.venv\Lib\site-packages\pandas\core\indexes\base.py", line 7132, in drop
    indexer = self.get_indexer_for(labels)
              ^^^^^^^^^^^^^^^^^^^^^^^^^^^^
  File "C:\Users\ABDULLAH RIZWAN\OneDrive\Desktop\Data Sciences\MLOPS\DataScienceProject\.venv\Lib\site-packages\pandas\core\indexes\base.py", line 6194, in get_indexer_for
    return self.get_indexer(target)
           ^^^^^^^^^^^^^^^^^^^^^^^^
  File "C:\Users\ABDULLAH RIZWAN\OneDrive\Desktop\Data Sciences\MLOPS\DataScienceProject\.venv\Lib\site-packages\pandas\core\indexes\base.py", line 3960, in get_indexer
    return self._get_indexer(target, method, limit, tolerance)
           ^^^^^^^^^^^^^^^^^^^^^^^^^^^^^^^^^^^^^^^^^^^^^^^^^^^
  File "C:\Users\ABDULLAH RIZWAN\OneDrive\Desktop\Data Sciences\MLOPS\DataScienceProject\.venv\Lib\site-packages\pandas\core\indexes\base.py", line 3987, in _get_indexer
    indexer = self._engine.get_indexer(tgt_values)
              ^^^^^^^^^^^^^^^^^^^^^^^^^^^^^^^^^^^^
  File "pandas/_libs/index.pyx", line 351, in pandas._libs.index.IndexEngine.get_indexer
  File "pandas/_libs/hashtable_class_helper.pxi", line 7139, in pandas._libs.hashtable.PyObjectHashTable.lookup
  File "box\\box.py", line 385, in box.box.Box.__hash__
box.exceptions.BoxTypeError: unhashable type: "Box"
[2025-08-23 16:34:49,423: INFO: main: >>>>> stage Data Ingestion Stage started >>>>>]
[2025-08-23 16:34:49,438: INFO: common: Yaml file: config\config.yaml is loaded successfully]
[2025-08-23 16:34:49,462: INFO: common: Yaml file: params.yaml is loaded successfully]
[2025-08-23 16:34:49,576: INFO: common: Yaml file: schema.yaml is loaded successfully]
[2025-08-23 16:34:49,583: INFO: common: Directory created at artifacts]
[2025-08-23 16:34:49,584: INFO: common: Directory created at artifacts/data_ingestion]
[2025-08-23 16:34:49,585: INFO: data_ingestion: File already exists]
[2025-08-23 16:34:49,602: INFO: main: >>>>> stage Data Ingestion Stage completed >>>>>]
[2025-08-23 16:34:49,605: INFO: main: Alhumdullillah sb okay h boss!]
[2025-08-23 16:34:49,605: INFO: main: >>>>> stage Data Validation Stage started >>>>>]
[2025-08-23 16:34:49,630: INFO: common: Yaml file: config\config.yaml is loaded successfully]
[2025-08-23 16:34:49,648: INFO: common: Yaml file: params.yaml is loaded successfully]
[2025-08-23 16:34:49,696: INFO: common: Yaml file: schema.yaml is loaded successfully]
[2025-08-23 16:34:49,698: INFO: common: Directory created at artifacts]
[2025-08-23 16:34:49,702: INFO: common: Directory created at artifacts/data_validation]
[2025-08-23 16:34:49,811: INFO: main: >>>>> stage Data Validation Stage completed >>>>>]
[2025-08-23 16:34:49,812: INFO: main: >>>>> stage Data Transformation Stage started >>>>>]
[2025-08-23 16:34:49,826: INFO: common: Yaml file: config\config.yaml is loaded successfully]
[2025-08-23 16:34:49,828: INFO: common: Yaml file: params.yaml is loaded successfully]
[2025-08-23 16:34:49,833: INFO: common: Yaml file: schema.yaml is loaded successfully]
[2025-08-23 16:34:49,834: INFO: common: Directory created at artifacts]
[2025-08-23 16:34:49,836: INFO: common: Directory created at artifacts/data_transformation]
[2025-08-23 16:34:49,969: INFO: data_transformation: Spliting completed]
[2025-08-23 16:34:49,970: INFO: data_transformation: Train shape: (1199, 12)]
[2025-08-23 16:34:49,971: INFO: data_transformation: Test  shape: (400, 12)]
[2025-08-23 16:34:49,972: INFO: main: >>>>> stage Data Transformation Stage completed >>>>>]
[2025-08-23 16:34:49,973: INFO: main: >>>>> stage Model Training Stage started >>>>>]
[2025-08-23 16:34:49,981: INFO: common: Yaml file: config\config.yaml is loaded successfully]
[2025-08-23 16:34:49,984: INFO: common: Yaml file: params.yaml is loaded successfully]
[2025-08-23 16:34:49,989: INFO: common: Yaml file: schema.yaml is loaded successfully]
[2025-08-23 16:34:49,992: INFO: common: Directory created at artifacts]
[2025-08-23 16:34:49,993: INFO: common: Directory created at artifacts/model_trainer]
[2025-08-23 16:34:50,174: ERROR: main: '["{\'name\': \'quality\'}"] not found in axis']
Traceback (most recent call last):
  File "C:\Users\ABDULLAH RIZWAN\OneDrive\Desktop\Data Sciences\MLOPS\DataScienceProject\main.py", line 50, in <module>
    obj.initiate_model_trainer_pipeline()
  File "C:\Users\ABDULLAH RIZWAN\OneDrive\Desktop\Data Sciences\MLOPS\DataScienceProject\src\DataScienceProject\pipeline\ModelTrainerPipeline.py", line 16, in initiate_model_trainer_pipeline
    raise e
  File "C:\Users\ABDULLAH RIZWAN\OneDrive\Desktop\Data Sciences\MLOPS\DataScienceProject\src\DataScienceProject\pipeline\ModelTrainerPipeline.py", line 14, in initiate_model_trainer_pipeline
    model_trainer.train()
  File "C:\Users\ABDULLAH RIZWAN\OneDrive\Desktop\Data Sciences\MLOPS\DataScienceProject\src\DataScienceProject\components\model_trainer.py", line 18, in train
    train_x = train_data.drop([target_col], axis=1)
              ^^^^^^^^^^^^^^^^^^^^^^^^^^^^^^^^^^^^^
  File "C:\Users\ABDULLAH RIZWAN\OneDrive\Desktop\Data Sciences\MLOPS\DataScienceProject\.venv\Lib\site-packages\pandas\core\frame.py", line 5588, in drop
    return super().drop(
           ^^^^^^^^^^^^^
  File "C:\Users\ABDULLAH RIZWAN\OneDrive\Desktop\Data Sciences\MLOPS\DataScienceProject\.venv\Lib\site-packages\pandas\core\generic.py", line 4807, in drop
    obj = obj._drop_axis(labels, axis, level=level, errors=errors)
          ^^^^^^^^^^^^^^^^^^^^^^^^^^^^^^^^^^^^^^^^^^^^^^^^^^^^^^^^
  File "C:\Users\ABDULLAH RIZWAN\OneDrive\Desktop\Data Sciences\MLOPS\DataScienceProject\.venv\Lib\site-packages\pandas\core\generic.py", line 4849, in _drop_axis
    new_axis = axis.drop(labels, errors=errors)
               ^^^^^^^^^^^^^^^^^^^^^^^^^^^^^^^^
  File "C:\Users\ABDULLAH RIZWAN\OneDrive\Desktop\Data Sciences\MLOPS\DataScienceProject\.venv\Lib\site-packages\pandas\core\indexes\base.py", line 7136, in drop
    raise KeyError(f"{labels[mask].tolist()} not found in axis")
KeyError: '["{\'name\': \'quality\'}"] not found in axis'
[2025-08-23 16:36:02,464: INFO: main: >>>>> stage Data Ingestion Stage started >>>>>]
[2025-08-23 16:36:02,471: INFO: common: Yaml file: config\config.yaml is loaded successfully]
[2025-08-23 16:36:02,475: INFO: common: Yaml file: params.yaml is loaded successfully]
[2025-08-23 16:36:02,480: INFO: common: Yaml file: schema.yaml is loaded successfully]
[2025-08-23 16:36:02,481: INFO: common: Directory created at artifacts]
[2025-08-23 16:36:02,482: INFO: common: Directory created at artifacts/data_ingestion]
[2025-08-23 16:36:02,482: INFO: data_ingestion: File already exists]
[2025-08-23 16:36:02,492: INFO: main: >>>>> stage Data Ingestion Stage completed >>>>>]
[2025-08-23 16:36:02,545: INFO: main: Alhumdullillah sb okay h boss!]
[2025-08-23 16:36:02,595: INFO: main: >>>>> stage Data Validation Stage started >>>>>]
[2025-08-23 16:36:02,641: INFO: common: Yaml file: config\config.yaml is loaded successfully]
[2025-08-23 16:36:02,677: INFO: common: Yaml file: params.yaml is loaded successfully]
[2025-08-23 16:36:02,696: INFO: common: Yaml file: schema.yaml is loaded successfully]
[2025-08-23 16:36:02,698: INFO: common: Directory created at artifacts]
[2025-08-23 16:36:02,699: INFO: common: Directory created at artifacts/data_validation]
[2025-08-23 16:36:02,825: INFO: main: >>>>> stage Data Validation Stage completed >>>>>]
[2025-08-23 16:36:02,827: INFO: main: >>>>> stage Data Transformation Stage started >>>>>]
[2025-08-23 16:36:02,840: INFO: common: Yaml file: config\config.yaml is loaded successfully]
[2025-08-23 16:36:02,845: INFO: common: Yaml file: params.yaml is loaded successfully]
[2025-08-23 16:36:02,853: INFO: common: Yaml file: schema.yaml is loaded successfully]
[2025-08-23 16:36:02,855: INFO: common: Directory created at artifacts]
[2025-08-23 16:36:02,856: INFO: common: Directory created at artifacts/data_transformation]
[2025-08-23 16:36:03,027: INFO: data_transformation: Spliting completed]
[2025-08-23 16:36:03,027: INFO: data_transformation: Train shape: (1199, 12)]
[2025-08-23 16:36:03,029: INFO: data_transformation: Test  shape: (400, 12)]
[2025-08-23 16:36:03,031: INFO: main: >>>>> stage Data Transformation Stage completed >>>>>]
[2025-08-23 16:36:03,034: INFO: main: >>>>> stage Model Training Stage started >>>>>]
[2025-08-23 16:36:03,046: INFO: common: Yaml file: config\config.yaml is loaded successfully]
[2025-08-23 16:36:03,103: INFO: common: Yaml file: params.yaml is loaded successfully]
[2025-08-23 16:36:03,114: INFO: common: Yaml file: schema.yaml is loaded successfully]
[2025-08-23 16:36:03,129: INFO: common: Directory created at artifacts]
[2025-08-23 16:36:03,154: INFO: common: Directory created at artifacts/model_trainer]
[2025-08-23 16:36:03,178: ERROR: main: "'ConfigBox' object has no attribute 'target_column'"]
Traceback (most recent call last):
  File "box\\box.py", line 594, in box.box.Box.__getitem__
KeyError: 'TARGET_COLUMN'

The above exception was the direct cause of the following exception:

Traceback (most recent call last):
  File "box\\box.py", line 633, in box.box.Box.__getattr__
  File "box\\box.py", line 621, in box.box.Box.__getitem__
box.exceptions.BoxKeyError: "'TARGET_COLUMN'"

During handling of the above exception, another exception occurred:

Traceback (most recent call last):
  File "box\\box.py", line 635, in box.box.Box.__getattr__
AttributeError: 'ConfigBox' object has no attribute 'TARGET_COLUMN'

The above exception was the direct cause of the following exception:

Traceback (most recent call last):
  File "box\\config_box.py", line 29, in box.config_box.ConfigBox.__getattr__
  File "box\\box.py", line 649, in box.box.Box.__getattr__
box.exceptions.BoxKeyError: "'ConfigBox' object has no attribute 'TARGET_COLUMN'"

During handling of the above exception, another exception occurred:

Traceback (most recent call last):
  File "box\\box.py", line 594, in box.box.Box.__getitem__
KeyError: 'target_column'

The above exception was the direct cause of the following exception:

Traceback (most recent call last):
  File "box\\box.py", line 633, in box.box.Box.__getattr__
  File "box\\box.py", line 621, in box.box.Box.__getitem__
box.exceptions.BoxKeyError: "'target_column'"

During handling of the above exception, another exception occurred:

Traceback (most recent call last):
  File "box\\box.py", line 635, in box.box.Box.__getattr__
AttributeError: 'ConfigBox' object has no attribute 'target_column'

The above exception was the direct cause of the following exception:

Traceback (most recent call last):
  File "C:\Users\ABDULLAH RIZWAN\OneDrive\Desktop\Data Sciences\MLOPS\DataScienceProject\main.py", line 50, in <module>
    obj.initiate_model_trainer_pipeline()
  File "C:\Users\ABDULLAH RIZWAN\OneDrive\Desktop\Data Sciences\MLOPS\DataScienceProject\src\DataScienceProject\pipeline\ModelTrainerPipeline.py", line 16, in initiate_model_trainer_pipeline
    raise e
  File "C:\Users\ABDULLAH RIZWAN\OneDrive\Desktop\Data Sciences\MLOPS\DataScienceProject\src\DataScienceProject\pipeline\ModelTrainerPipeline.py", line 12, in initiate_model_trainer_pipeline
    model_trainer_config = config.get_model_trainer_config()
                           ^^^^^^^^^^^^^^^^^^^^^^^^^^^^^^^^^
  File "C:\Users\ABDULLAH RIZWAN\OneDrive\Desktop\Data Sciences\MLOPS\DataScienceProject\src\DataScienceProject\config\configuration.py", line 73, in get_model_trainer_config
    target_column = schema.TARGET_COLUMN
                    ^^^^^^^^^^^^^^^^^^^^
  File "box\\config_box.py", line 31, in box.config_box.ConfigBox.__getattr__
  File "box\\box.py", line 649, in box.box.Box.__getattr__
box.exceptions.BoxKeyError: "'ConfigBox' object has no attribute 'target_column'"
[2025-08-23 16:38:08,313: INFO: main: >>>>> stage Data Ingestion Stage started >>>>>]
[2025-08-23 16:38:08,325: INFO: common: Yaml file: config\config.yaml is loaded successfully]
[2025-08-23 16:38:08,328: INFO: common: Yaml file: params.yaml is loaded successfully]
[2025-08-23 16:38:08,337: INFO: common: Yaml file: schema.yaml is loaded successfully]
[2025-08-23 16:38:08,347: INFO: common: Directory created at artifacts]
[2025-08-23 16:38:08,351: INFO: common: Directory created at artifacts/data_ingestion]
[2025-08-23 16:38:08,374: INFO: data_ingestion: File already exists]
[2025-08-23 16:38:08,417: INFO: main: >>>>> stage Data Ingestion Stage completed >>>>>]
[2025-08-23 16:38:08,564: INFO: main: Alhumdullillah sb okay h boss!]
[2025-08-23 16:38:08,634: INFO: main: >>>>> stage Data Validation Stage started >>>>>]
[2025-08-23 16:38:08,736: INFO: common: Yaml file: config\config.yaml is loaded successfully]
[2025-08-23 16:38:08,807: INFO: common: Yaml file: params.yaml is loaded successfully]
[2025-08-23 16:38:08,877: INFO: common: Yaml file: schema.yaml is loaded successfully]
[2025-08-23 16:38:08,887: INFO: common: Directory created at artifacts]
[2025-08-23 16:38:08,892: INFO: common: Directory created at artifacts/data_validation]
[2025-08-23 16:38:09,025: INFO: main: >>>>> stage Data Validation Stage completed >>>>>]
[2025-08-23 16:38:09,026: INFO: main: >>>>> stage Data Transformation Stage started >>>>>]
[2025-08-23 16:38:09,037: INFO: common: Yaml file: config\config.yaml is loaded successfully]
[2025-08-23 16:38:09,043: INFO: common: Yaml file: params.yaml is loaded successfully]
[2025-08-23 16:38:09,053: INFO: common: Yaml file: schema.yaml is loaded successfully]
[2025-08-23 16:38:09,055: INFO: common: Directory created at artifacts]
[2025-08-23 16:38:09,055: INFO: common: Directory created at artifacts/data_transformation]
[2025-08-23 16:38:09,156: INFO: data_transformation: Spliting completed]
[2025-08-23 16:38:09,158: INFO: data_transformation: Train shape: (1199, 12)]
[2025-08-23 16:38:09,166: INFO: data_transformation: Test  shape: (400, 12)]
[2025-08-23 16:38:09,171: INFO: main: >>>>> stage Data Transformation Stage completed >>>>>]
[2025-08-23 16:38:09,174: INFO: main: >>>>> stage Model Training Stage started >>>>>]
[2025-08-23 16:38:09,191: INFO: common: Yaml file: config\config.yaml is loaded successfully]
[2025-08-23 16:38:09,199: INFO: common: Yaml file: params.yaml is loaded successfully]
[2025-08-23 16:38:09,262: INFO: common: Yaml file: schema.yaml is loaded successfully]
[2025-08-23 16:38:09,306: INFO: common: Directory created at artifacts]
[2025-08-23 16:38:09,334: INFO: common: Directory created at artifacts/model_trainer]
[2025-08-23 16:38:09,486: ERROR: main: name 'l1r' is not defined]
Traceback (most recent call last):
  File "C:\Users\ABDULLAH RIZWAN\OneDrive\Desktop\Data Sciences\MLOPS\DataScienceProject\main.py", line 50, in <module>
    obj.initiate_model_trainer_pipeline()
  File "C:\Users\ABDULLAH RIZWAN\OneDrive\Desktop\Data Sciences\MLOPS\DataScienceProject\src\DataScienceProject\pipeline\ModelTrainerPipeline.py", line 16, in initiate_model_trainer_pipeline
    raise e
  File "C:\Users\ABDULLAH RIZWAN\OneDrive\Desktop\Data Sciences\MLOPS\DataScienceProject\src\DataScienceProject\pipeline\ModelTrainerPipeline.py", line 14, in initiate_model_trainer_pipeline
    model_trainer.train()
  File "C:\Users\ABDULLAH RIZWAN\OneDrive\Desktop\Data Sciences\MLOPS\DataScienceProject\src\DataScienceProject\components\model_trainer.py", line 35, in train
    joblib.dump(l1r, os.path.join(self.config.root_dir, self.config.model_name))
                ^^^
NameError: name 'l1r' is not defined
[2025-08-23 16:38:46,702: INFO: main: >>>>> stage Data Ingestion Stage started >>>>>]
[2025-08-23 16:38:46,709: INFO: common: Yaml file: config\config.yaml is loaded successfully]
[2025-08-23 16:38:46,711: INFO: common: Yaml file: params.yaml is loaded successfully]
[2025-08-23 16:38:46,716: INFO: common: Yaml file: schema.yaml is loaded successfully]
[2025-08-23 16:38:46,717: INFO: common: Directory created at artifacts]
[2025-08-23 16:38:46,718: INFO: common: Directory created at artifacts/data_ingestion]
[2025-08-23 16:38:46,722: INFO: data_ingestion: File already exists]
[2025-08-23 16:38:46,730: INFO: main: >>>>> stage Data Ingestion Stage completed >>>>>]
[2025-08-23 16:38:46,731: INFO: main: Alhumdullillah sb okay h boss!]
[2025-08-23 16:38:46,732: INFO: main: >>>>> stage Data Validation Stage started >>>>>]
[2025-08-23 16:38:46,786: INFO: common: Yaml file: config\config.yaml is loaded successfully]
[2025-08-23 16:38:46,792: INFO: common: Yaml file: params.yaml is loaded successfully]
[2025-08-23 16:38:46,855: INFO: common: Yaml file: schema.yaml is loaded successfully]
[2025-08-23 16:38:46,872: INFO: common: Directory created at artifacts]
[2025-08-23 16:38:46,891: INFO: common: Directory created at artifacts/data_validation]
[2025-08-23 16:38:47,024: INFO: main: >>>>> stage Data Validation Stage completed >>>>>]
[2025-08-23 16:38:47,025: INFO: main: >>>>> stage Data Transformation Stage started >>>>>]
[2025-08-23 16:38:47,034: INFO: common: Yaml file: config\config.yaml is loaded successfully]
[2025-08-23 16:38:47,037: INFO: common: Yaml file: params.yaml is loaded successfully]
[2025-08-23 16:38:47,046: INFO: common: Yaml file: schema.yaml is loaded successfully]
[2025-08-23 16:38:47,047: INFO: common: Directory created at artifacts]
[2025-08-23 16:38:47,049: INFO: common: Directory created at artifacts/data_transformation]
[2025-08-23 16:38:47,160: INFO: data_transformation: Spliting completed]
[2025-08-23 16:38:47,162: INFO: data_transformation: Train shape: (1199, 12)]
[2025-08-23 16:38:47,164: INFO: data_transformation: Test  shape: (400, 12)]
[2025-08-23 16:38:47,165: INFO: main: >>>>> stage Data Transformation Stage completed >>>>>]
[2025-08-23 16:38:47,165: INFO: main: >>>>> stage Model Training Stage started >>>>>]
[2025-08-23 16:38:47,176: INFO: common: Yaml file: config\config.yaml is loaded successfully]
[2025-08-23 16:38:47,182: INFO: common: Yaml file: params.yaml is loaded successfully]
[2025-08-23 16:38:47,191: INFO: common: Yaml file: schema.yaml is loaded successfully]
[2025-08-23 16:38:47,207: INFO: common: Directory created at artifacts]
[2025-08-23 16:38:47,211: INFO: common: Directory created at artifacts/model_trainer]
[2025-08-23 16:38:47,371: INFO: main: >>>>> stage Model Training Stage completed >>>>>]
[2025-08-24 08:56:40,560: INFO: main: >>>>> stage Data Ingestion Stage started >>>>>]
[2025-08-24 08:56:40,575: INFO: common: Yaml file: config\config.yaml is loaded successfully]
[2025-08-24 08:56:40,583: INFO: common: Yaml file: params.yaml is loaded successfully]
[2025-08-24 08:56:40,600: INFO: common: Yaml file: schema.yaml is loaded successfully]
[2025-08-24 08:56:40,605: INFO: common: Directory created at artifacts]
[2025-08-24 08:56:40,607: INFO: common: Directory created at artifacts/data_ingestion]
[2025-08-24 08:56:40,617: INFO: data_ingestion: File already exists]
[2025-08-24 08:56:40,742: INFO: main: >>>>> stage Data Ingestion Stage completed >>>>>]
[2025-08-24 08:56:40,744: INFO: main: Alhumdullillah sb okay h boss!]
[2025-08-24 08:56:40,745: INFO: main: >>>>> stage Data Validation Stage started >>>>>]
[2025-08-24 08:56:40,757: INFO: common: Yaml file: config\config.yaml is loaded successfully]
[2025-08-24 08:56:40,765: INFO: common: Yaml file: params.yaml is loaded successfully]
[2025-08-24 08:56:40,920: INFO: common: Yaml file: schema.yaml is loaded successfully]
[2025-08-24 08:56:40,925: INFO: common: Directory created at artifacts]
[2025-08-24 08:56:40,933: INFO: common: Directory created at artifacts/data_validation]
[2025-08-24 08:56:41,053: INFO: main: >>>>> stage Data Validation Stage completed >>>>>]
[2025-08-24 08:56:41,062: INFO: main: >>>>> stage Data Transformation Stage started >>>>>]
[2025-08-24 08:56:41,111: INFO: common: Yaml file: config\config.yaml is loaded successfully]
[2025-08-24 08:56:41,123: INFO: common: Yaml file: params.yaml is loaded successfully]
[2025-08-24 08:56:41,139: INFO: common: Yaml file: schema.yaml is loaded successfully]
[2025-08-24 08:56:41,144: INFO: common: Directory created at artifacts]
[2025-08-24 08:56:41,151: INFO: common: Directory created at artifacts/data_transformation]
[2025-08-24 08:56:41,355: INFO: data_transformation: Spliting completed]
[2025-08-24 08:56:41,359: INFO: data_transformation: Train shape: (1199, 12)]
[2025-08-24 08:56:41,362: INFO: data_transformation: Test  shape: (400, 12)]
[2025-08-24 08:56:41,364: INFO: main: >>>>> stage Data Transformation Stage completed >>>>>]
[2025-08-24 08:56:41,365: INFO: main: >>>>> stage Model Training Stage started >>>>>]
[2025-08-24 08:56:41,377: INFO: common: Yaml file: config\config.yaml is loaded successfully]
[2025-08-24 08:56:41,380: INFO: common: Yaml file: params.yaml is loaded successfully]
[2025-08-24 08:56:41,394: INFO: common: Yaml file: schema.yaml is loaded successfully]
[2025-08-24 08:56:41,397: INFO: common: Directory created at artifacts]
[2025-08-24 08:56:41,399: INFO: common: Directory created at artifacts/model_trainer]
[2025-08-24 08:56:41,562: INFO: main: >>>>> stage Model Training Stage completed >>>>>]
[2025-08-24 08:56:41,563: INFO: main: >>>>> stage Model Evaluation Stage started >>>>>]
[2025-08-24 08:56:41,578: INFO: common: Yaml file: config\config.yaml is loaded successfully]
[2025-08-24 08:56:41,615: INFO: common: Yaml file: params.yaml is loaded successfully]
[2025-08-24 08:56:41,655: INFO: common: Yaml file: schema.yaml is loaded successfully]
[2025-08-24 08:56:41,665: INFO: common: Directory created at artifacts]
[2025-08-24 08:56:41,675: INFO: common: Directory created at artifacts/model_evaluation]
[2025-08-24 08:56:41,780: ERROR: main: "[('quality',)] not found in axis"]
Traceback (most recent call last):
  File "C:\Users\ABDULLAH RIZWAN\OneDrive\Desktop\Data Sciences\MLOPS\DataScienceProject\main.py", line 63, in <module>
    obj.initiate_model_evaluation_pipeline()
  File "C:\Users\ABDULLAH RIZWAN\OneDrive\Desktop\Data Sciences\MLOPS\DataScienceProject\src\DataScienceProject\pipeline\ModelEvaluationPipeline.py", line 16, in initiate_model_evaluation_pipeline
    raise e
  File "C:\Users\ABDULLAH RIZWAN\OneDrive\Desktop\Data Sciences\MLOPS\DataScienceProject\src\DataScienceProject\pipeline\ModelEvaluationPipeline.py", line 14, in initiate_model_evaluation_pipeline
    model_evaluation.log_into_mlflow()
  File "C:\Users\ABDULLAH RIZWAN\OneDrive\Desktop\Data Sciences\MLOPS\DataScienceProject\src\DataScienceProject\components\model_evaluation.py", line 27, in log_into_mlflow
    test_y = test_data.drop([[self.config.target_column]])
             ^^^^^^^^^^^^^^^^^^^^^^^^^^^^^^^^^^^^^^^^^^^^^
  File "C:\Users\ABDULLAH RIZWAN\OneDrive\Desktop\Data Sciences\MLOPS\DataScienceProject\.venv\Lib\site-packages\pandas\core\frame.py", line 5588, in drop
    return super().drop(
           ^^^^^^^^^^^^^
  File "C:\Users\ABDULLAH RIZWAN\OneDrive\Desktop\Data Sciences\MLOPS\DataScienceProject\.venv\Lib\site-packages\pandas\core\generic.py", line 4807, in drop
    obj = obj._drop_axis(labels, axis, level=level, errors=errors)
          ^^^^^^^^^^^^^^^^^^^^^^^^^^^^^^^^^^^^^^^^^^^^^^^^^^^^^^^^
  File "C:\Users\ABDULLAH RIZWAN\OneDrive\Desktop\Data Sciences\MLOPS\DataScienceProject\.venv\Lib\site-packages\pandas\core\generic.py", line 4849, in _drop_axis
    new_axis = axis.drop(labels, errors=errors)
               ^^^^^^^^^^^^^^^^^^^^^^^^^^^^^^^^
  File "C:\Users\ABDULLAH RIZWAN\OneDrive\Desktop\Data Sciences\MLOPS\DataScienceProject\.venv\Lib\site-packages\pandas\core\indexes\base.py", line 7136, in drop
    raise KeyError(f"{labels[mask].tolist()} not found in axis")
KeyError: "[('quality',)] not found in axis"
[2025-08-24 09:00:44,546: INFO: main: >>>>> stage Data Ingestion Stage started >>>>>]
[2025-08-24 09:00:44,553: INFO: common: Yaml file: config\config.yaml is loaded successfully]
[2025-08-24 09:00:44,558: INFO: common: Yaml file: params.yaml is loaded successfully]
[2025-08-24 09:00:44,563: INFO: common: Yaml file: schema.yaml is loaded successfully]
[2025-08-24 09:00:44,584: INFO: common: Directory created at artifacts]
[2025-08-24 09:00:44,587: INFO: common: Directory created at artifacts/data_ingestion]
[2025-08-24 09:00:44,589: INFO: data_ingestion: File already exists]
[2025-08-24 09:00:44,622: INFO: main: >>>>> stage Data Ingestion Stage completed >>>>>]
[2025-08-24 09:00:44,624: INFO: main: Alhumdullillah sb okay h boss!]
[2025-08-24 09:00:44,625: INFO: main: >>>>> stage Data Validation Stage started >>>>>]
[2025-08-24 09:00:44,662: INFO: common: Yaml file: config\config.yaml is loaded successfully]
[2025-08-24 09:00:44,693: INFO: common: Yaml file: params.yaml is loaded successfully]
[2025-08-24 09:00:44,774: INFO: common: Yaml file: schema.yaml is loaded successfully]
[2025-08-24 09:00:44,790: INFO: common: Directory created at artifacts]
[2025-08-24 09:00:44,794: INFO: common: Directory created at artifacts/data_validation]
[2025-08-24 09:00:44,900: INFO: main: >>>>> stage Data Validation Stage completed >>>>>]
[2025-08-24 09:00:44,900: INFO: main: >>>>> stage Data Transformation Stage started >>>>>]
[2025-08-24 09:00:44,909: INFO: common: Yaml file: config\config.yaml is loaded successfully]
[2025-08-24 09:00:44,911: INFO: common: Yaml file: params.yaml is loaded successfully]
[2025-08-24 09:00:44,915: INFO: common: Yaml file: schema.yaml is loaded successfully]
[2025-08-24 09:00:44,918: INFO: common: Directory created at artifacts]
[2025-08-24 09:00:44,920: INFO: common: Directory created at artifacts/data_transformation]
[2025-08-24 09:00:45,030: INFO: data_transformation: Spliting completed]
[2025-08-24 09:00:45,032: INFO: data_transformation: Train shape: (1199, 12)]
[2025-08-24 09:00:45,034: INFO: data_transformation: Test  shape: (400, 12)]
[2025-08-24 09:00:45,040: INFO: main: >>>>> stage Data Transformation Stage completed >>>>>]
[2025-08-24 09:00:45,042: INFO: main: >>>>> stage Model Training Stage started >>>>>]
[2025-08-24 09:00:45,058: INFO: common: Yaml file: config\config.yaml is loaded successfully]
[2025-08-24 09:00:45,067: INFO: common: Yaml file: params.yaml is loaded successfully]
[2025-08-24 09:00:45,086: INFO: common: Yaml file: schema.yaml is loaded successfully]
[2025-08-24 09:00:45,102: INFO: common: Directory created at artifacts]
[2025-08-24 09:00:45,117: INFO: common: Directory created at artifacts/model_trainer]
[2025-08-24 09:00:45,237: INFO: main: >>>>> stage Model Training Stage completed >>>>>]
[2025-08-24 09:00:45,238: INFO: main: >>>>> stage Model Evaluation Stage started >>>>>]
[2025-08-24 09:00:45,250: INFO: common: Yaml file: config\config.yaml is loaded successfully]
[2025-08-24 09:00:45,254: INFO: common: Yaml file: params.yaml is loaded successfully]
[2025-08-24 09:00:45,260: INFO: common: Yaml file: schema.yaml is loaded successfully]
[2025-08-24 09:00:45,263: INFO: common: Directory created at artifacts]
[2025-08-24 09:00:45,265: INFO: common: Directory created at artifacts/model_evaluation]
[2025-08-24 09:00:53,121: ERROR: main: API request to endpoint /api/2.0/mlflow/runs/create failed with error code 403 != 200. Response body: '']
Traceback (most recent call last):
  File "C:\Users\ABDULLAH RIZWAN\OneDrive\Desktop\Data Sciences\MLOPS\DataScienceProject\main.py", line 63, in <module>
    obj.initiate_model_evaluation_pipeline()
  File "C:\Users\ABDULLAH RIZWAN\OneDrive\Desktop\Data Sciences\MLOPS\DataScienceProject\src\DataScienceProject\pipeline\ModelEvaluationPipeline.py", line 16, in initiate_model_evaluation_pipeline
    raise e
  File "C:\Users\ABDULLAH RIZWAN\OneDrive\Desktop\Data Sciences\MLOPS\DataScienceProject\src\DataScienceProject\pipeline\ModelEvaluationPipeline.py", line 14, in initiate_model_evaluation_pipeline
    model_evaluation.log_into_mlflow()
  File "C:\Users\ABDULLAH RIZWAN\OneDrive\Desktop\Data Sciences\MLOPS\DataScienceProject\src\DataScienceProject\components\model_evaluation.py", line 32, in log_into_mlflow
    with mlflow.start_run():
         ^^^^^^^^^^^^^^^^^^
  File "C:\Users\ABDULLAH RIZWAN\OneDrive\Desktop\Data Sciences\MLOPS\DataScienceProject\.venv\Lib\site-packages\mlflow\tracking\fluent.py", line 446, in start_run
    active_run_obj = client.create_run(
                     ^^^^^^^^^^^^^^^^^^
  File "C:\Users\ABDULLAH RIZWAN\OneDrive\Desktop\Data Sciences\MLOPS\DataScienceProject\.venv\Lib\site-packages\mlflow\tracking\client.py", line 418, in create_run
    return self._tracking_client.create_run(experiment_id, start_time, tags, run_name)
           ^^^^^^^^^^^^^^^^^^^^^^^^^^^^^^^^^^^^^^^^^^^^^^^^^^^^^^^^^^^^^^^^^^^^^^^^^^^
  File "C:\Users\ABDULLAH RIZWAN\OneDrive\Desktop\Data Sciences\MLOPS\DataScienceProject\.venv\Lib\site-packages\mlflow\tracking\_tracking_service\client.py", line 171, in create_run
    return self.store.create_run(
           ^^^^^^^^^^^^^^^^^^^^^^
  File "C:\Users\ABDULLAH RIZWAN\OneDrive\Desktop\Data Sciences\MLOPS\DataScienceProject\.venv\Lib\site-packages\mlflow\store\tracking\rest_store.py", line 220, in create_run
    response_proto = self._call_endpoint(CreateRun, req_body)
                     ^^^^^^^^^^^^^^^^^^^^^^^^^^^^^^^^^^^^^^^^
  File "C:\Users\ABDULLAH RIZWAN\OneDrive\Desktop\Data Sciences\MLOPS\DataScienceProject\.venv\Lib\site-packages\mlflow\store\tracking\rest_store.py", line 90, in _call_endpoint
    return call_endpoint(self.get_host_creds(), endpoint, method, json_body, response_proto)
           ^^^^^^^^^^^^^^^^^^^^^^^^^^^^^^^^^^^^^^^^^^^^^^^^^^^^^^^^^^^^^^^^^^^^^^^^^^^^^^^^^
  File "C:\Users\ABDULLAH RIZWAN\OneDrive\Desktop\Data Sciences\MLOPS\DataScienceProject\.venv\Lib\site-packages\mlflow\utils\rest_utils.py", line 402, in call_endpoint
    response = verify_rest_response(response, endpoint)
               ^^^^^^^^^^^^^^^^^^^^^^^^^^^^^^^^^^^^^^^^
  File "C:\Users\ABDULLAH RIZWAN\OneDrive\Desktop\Data Sciences\MLOPS\DataScienceProject\.venv\Lib\site-packages\mlflow\utils\rest_utils.py", line 265, in verify_rest_response
    raise MlflowException(
mlflow.exceptions.MlflowException: API request to endpoint /api/2.0/mlflow/runs/create failed with error code 403 != 200. Response body: ''
[2025-08-24 09:03:40,723: INFO: main: >>>>> stage Data Ingestion Stage started >>>>>]
[2025-08-24 09:03:40,730: INFO: common: Yaml file: config\config.yaml is loaded successfully]
[2025-08-24 09:03:40,735: INFO: common: Yaml file: params.yaml is loaded successfully]
[2025-08-24 09:03:40,738: INFO: common: Yaml file: schema.yaml is loaded successfully]
[2025-08-24 09:03:40,740: INFO: common: Directory created at artifacts]
[2025-08-24 09:03:40,741: INFO: common: Directory created at artifacts/data_ingestion]
[2025-08-24 09:03:40,741: INFO: data_ingestion: File already exists]
[2025-08-24 09:03:40,755: INFO: main: >>>>> stage Data Ingestion Stage completed >>>>>]
[2025-08-24 09:03:40,758: INFO: main: Alhumdullillah sb okay h boss!]
[2025-08-24 09:03:40,795: INFO: main: >>>>> stage Data Validation Stage started >>>>>]
[2025-08-24 09:03:40,859: INFO: common: Yaml file: config\config.yaml is loaded successfully]
[2025-08-24 09:03:40,876: INFO: common: Yaml file: params.yaml is loaded successfully]
[2025-08-24 09:03:40,963: INFO: common: Yaml file: schema.yaml is loaded successfully]
[2025-08-24 09:03:40,971: INFO: common: Directory created at artifacts]
[2025-08-24 09:03:40,973: INFO: common: Directory created at artifacts/data_validation]
[2025-08-24 09:03:41,078: INFO: main: >>>>> stage Data Validation Stage completed >>>>>]
[2025-08-24 09:03:41,080: INFO: main: >>>>> stage Data Transformation Stage started >>>>>]
[2025-08-24 09:03:41,094: INFO: common: Yaml file: config\config.yaml is loaded successfully]
[2025-08-24 09:03:41,098: INFO: common: Yaml file: params.yaml is loaded successfully]
[2025-08-24 09:03:41,108: INFO: common: Yaml file: schema.yaml is loaded successfully]
[2025-08-24 09:03:41,113: INFO: common: Directory created at artifacts]
[2025-08-24 09:03:41,116: INFO: common: Directory created at artifacts/data_transformation]
[2025-08-24 09:03:41,213: INFO: data_transformation: Spliting completed]
[2025-08-24 09:03:41,216: INFO: data_transformation: Train shape: (1199, 12)]
[2025-08-24 09:03:41,216: INFO: data_transformation: Test  shape: (400, 12)]
[2025-08-24 09:03:41,218: INFO: main: >>>>> stage Data Transformation Stage completed >>>>>]
[2025-08-24 09:03:41,218: INFO: main: >>>>> stage Model Training Stage started >>>>>]
[2025-08-24 09:03:41,224: INFO: common: Yaml file: config\config.yaml is loaded successfully]
[2025-08-24 09:03:41,227: INFO: common: Yaml file: params.yaml is loaded successfully]
[2025-08-24 09:03:41,233: INFO: common: Yaml file: schema.yaml is loaded successfully]
[2025-08-24 09:03:41,235: INFO: common: Directory created at artifacts]
[2025-08-24 09:03:41,239: INFO: common: Directory created at artifacts/model_trainer]
[2025-08-24 09:03:41,432: INFO: main: >>>>> stage Model Training Stage completed >>>>>]
[2025-08-24 09:03:41,433: INFO: main: >>>>> stage Model Evaluation Stage started >>>>>]
[2025-08-24 09:03:41,443: INFO: common: Yaml file: config\config.yaml is loaded successfully]
[2025-08-24 09:03:41,445: INFO: common: Yaml file: params.yaml is loaded successfully]
[2025-08-24 09:03:41,452: INFO: common: Yaml file: schema.yaml is loaded successfully]
[2025-08-24 09:03:41,457: INFO: common: Directory created at artifacts]
[2025-08-24 09:03:41,460: INFO: common: Directory created at artifacts/model_evaluation]
[2025-08-24 09:03:46,003: ERROR: main: API request to endpoint /api/2.0/mlflow/runs/create failed with error code 403 != 200. Response body: '']
Traceback (most recent call last):
  File "C:\Users\ABDULLAH RIZWAN\OneDrive\Desktop\Data Sciences\MLOPS\DataScienceProject\main.py", line 63, in <module>
    obj.initiate_model_evaluation_pipeline()
  File "C:\Users\ABDULLAH RIZWAN\OneDrive\Desktop\Data Sciences\MLOPS\DataScienceProject\src\DataScienceProject\pipeline\ModelEvaluationPipeline.py", line 16, in initiate_model_evaluation_pipeline
    raise e
  File "C:\Users\ABDULLAH RIZWAN\OneDrive\Desktop\Data Sciences\MLOPS\DataScienceProject\src\DataScienceProject\pipeline\ModelEvaluationPipeline.py", line 14, in initiate_model_evaluation_pipeline
    model_evaluation.log_into_mlflow()
  File "C:\Users\ABDULLAH RIZWAN\OneDrive\Desktop\Data Sciences\MLOPS\DataScienceProject\src\DataScienceProject\components\model_evaluation.py", line 32, in log_into_mlflow
    with mlflow.start_run():
         ^^^^^^^^^^^^^^^^^^
  File "C:\Users\ABDULLAH RIZWAN\OneDrive\Desktop\Data Sciences\MLOPS\DataScienceProject\.venv\Lib\site-packages\mlflow\tracking\fluent.py", line 446, in start_run
    active_run_obj = client.create_run(
                     ^^^^^^^^^^^^^^^^^^
  File "C:\Users\ABDULLAH RIZWAN\OneDrive\Desktop\Data Sciences\MLOPS\DataScienceProject\.venv\Lib\site-packages\mlflow\tracking\client.py", line 418, in create_run
    return self._tracking_client.create_run(experiment_id, start_time, tags, run_name)
           ^^^^^^^^^^^^^^^^^^^^^^^^^^^^^^^^^^^^^^^^^^^^^^^^^^^^^^^^^^^^^^^^^^^^^^^^^^^
  File "C:\Users\ABDULLAH RIZWAN\OneDrive\Desktop\Data Sciences\MLOPS\DataScienceProject\.venv\Lib\site-packages\mlflow\tracking\_tracking_service\client.py", line 171, in create_run
    return self.store.create_run(
           ^^^^^^^^^^^^^^^^^^^^^^
  File "C:\Users\ABDULLAH RIZWAN\OneDrive\Desktop\Data Sciences\MLOPS\DataScienceProject\.venv\Lib\site-packages\mlflow\store\tracking\rest_store.py", line 220, in create_run
    response_proto = self._call_endpoint(CreateRun, req_body)
                     ^^^^^^^^^^^^^^^^^^^^^^^^^^^^^^^^^^^^^^^^
  File "C:\Users\ABDULLAH RIZWAN\OneDrive\Desktop\Data Sciences\MLOPS\DataScienceProject\.venv\Lib\site-packages\mlflow\store\tracking\rest_store.py", line 90, in _call_endpoint
    return call_endpoint(self.get_host_creds(), endpoint, method, json_body, response_proto)
           ^^^^^^^^^^^^^^^^^^^^^^^^^^^^^^^^^^^^^^^^^^^^^^^^^^^^^^^^^^^^^^^^^^^^^^^^^^^^^^^^^
  File "C:\Users\ABDULLAH RIZWAN\OneDrive\Desktop\Data Sciences\MLOPS\DataScienceProject\.venv\Lib\site-packages\mlflow\utils\rest_utils.py", line 402, in call_endpoint
    response = verify_rest_response(response, endpoint)
               ^^^^^^^^^^^^^^^^^^^^^^^^^^^^^^^^^^^^^^^^
  File "C:\Users\ABDULLAH RIZWAN\OneDrive\Desktop\Data Sciences\MLOPS\DataScienceProject\.venv\Lib\site-packages\mlflow\utils\rest_utils.py", line 265, in verify_rest_response
    raise MlflowException(
mlflow.exceptions.MlflowException: API request to endpoint /api/2.0/mlflow/runs/create failed with error code 403 != 200. Response body: ''
[2025-08-24 09:06:24,403: INFO: main: >>>>> stage Data Ingestion Stage started >>>>>]
[2025-08-24 09:06:24,415: INFO: common: Yaml file: config\config.yaml is loaded successfully]
[2025-08-24 09:06:24,420: INFO: common: Yaml file: params.yaml is loaded successfully]
[2025-08-24 09:06:24,427: INFO: common: Yaml file: schema.yaml is loaded successfully]
[2025-08-24 09:06:24,556: INFO: common: Directory created at artifacts]
[2025-08-24 09:06:24,559: INFO: common: Directory created at artifacts/data_ingestion]
[2025-08-24 09:06:24,575: INFO: data_ingestion: File already exists]
[2025-08-24 09:06:24,600: INFO: main: >>>>> stage Data Ingestion Stage completed >>>>>]
[2025-08-24 09:06:24,642: INFO: main: Alhumdullillah sb okay h boss!]
[2025-08-24 09:06:24,681: INFO: main: >>>>> stage Data Validation Stage started >>>>>]
[2025-08-24 09:06:24,732: INFO: common: Yaml file: config\config.yaml is loaded successfully]
[2025-08-24 09:06:24,739: INFO: common: Yaml file: params.yaml is loaded successfully]
[2025-08-24 09:06:24,761: INFO: common: Yaml file: schema.yaml is loaded successfully]
[2025-08-24 09:06:24,782: INFO: common: Directory created at artifacts]
[2025-08-24 09:06:24,789: INFO: common: Directory created at artifacts/data_validation]
[2025-08-24 09:06:24,922: INFO: main: >>>>> stage Data Validation Stage completed >>>>>]
[2025-08-24 09:06:24,929: INFO: main: >>>>> stage Data Transformation Stage started >>>>>]
[2025-08-24 09:06:24,940: INFO: common: Yaml file: config\config.yaml is loaded successfully]
[2025-08-24 09:06:24,964: INFO: common: Yaml file: params.yaml is loaded successfully]
[2025-08-24 09:06:25,005: INFO: common: Yaml file: schema.yaml is loaded successfully]
[2025-08-24 09:06:25,027: INFO: common: Directory created at artifacts]
[2025-08-24 09:06:25,041: INFO: common: Directory created at artifacts/data_transformation]
[2025-08-24 09:06:25,200: INFO: data_transformation: Spliting completed]
[2025-08-24 09:06:25,252: INFO: data_transformation: Train shape: (1199, 12)]
[2025-08-24 09:06:25,270: INFO: data_transformation: Test  shape: (400, 12)]
[2025-08-24 09:06:25,277: INFO: main: >>>>> stage Data Transformation Stage completed >>>>>]
[2025-08-24 09:06:25,284: INFO: main: >>>>> stage Model Training Stage started >>>>>]
[2025-08-24 09:06:25,316: INFO: common: Yaml file: config\config.yaml is loaded successfully]
[2025-08-24 09:06:25,340: INFO: common: Yaml file: params.yaml is loaded successfully]
[2025-08-24 09:06:25,367: INFO: common: Yaml file: schema.yaml is loaded successfully]
[2025-08-24 09:06:25,388: INFO: common: Directory created at artifacts]
[2025-08-24 09:06:25,407: INFO: common: Directory created at artifacts/model_trainer]
[2025-08-24 09:06:25,580: INFO: main: >>>>> stage Model Training Stage completed >>>>>]
[2025-08-24 09:06:25,581: INFO: main: >>>>> stage Model Evaluation Stage started >>>>>]
[2025-08-24 09:06:25,593: INFO: common: Yaml file: config\config.yaml is loaded successfully]
[2025-08-24 09:06:25,602: INFO: common: Yaml file: params.yaml is loaded successfully]
[2025-08-24 09:06:25,613: INFO: common: Yaml file: schema.yaml is loaded successfully]
[2025-08-24 09:06:25,625: INFO: common: Directory created at artifacts]
[2025-08-24 09:06:25,632: INFO: common: Directory created at artifacts/model_evaluation]
[2025-08-24 09:06:30,195: ERROR: main: API request to endpoint /api/2.0/mlflow/runs/create failed with error code 403 != 200. Response body: '']
Traceback (most recent call last):
  File "C:\Users\ABDULLAH RIZWAN\OneDrive\Desktop\Data Sciences\MLOPS\DataScienceProject\main.py", line 63, in <module>
    obj.initiate_model_evaluation_pipeline()
  File "C:\Users\ABDULLAH RIZWAN\OneDrive\Desktop\Data Sciences\MLOPS\DataScienceProject\src\DataScienceProject\pipeline\ModelEvaluationPipeline.py", line 16, in initiate_model_evaluation_pipeline
    raise e
  File "C:\Users\ABDULLAH RIZWAN\OneDrive\Desktop\Data Sciences\MLOPS\DataScienceProject\src\DataScienceProject\pipeline\ModelEvaluationPipeline.py", line 14, in initiate_model_evaluation_pipeline
    model_evaluation.log_into_mlflow()
  File "C:\Users\ABDULLAH RIZWAN\OneDrive\Desktop\Data Sciences\MLOPS\DataScienceProject\src\DataScienceProject\components\model_evaluation.py", line 32, in log_into_mlflow
    with mlflow.start_run():
         ^^^^^^^^^^^^^^^^^^
  File "C:\Users\ABDULLAH RIZWAN\OneDrive\Desktop\Data Sciences\MLOPS\DataScienceProject\.venv\Lib\site-packages\mlflow\tracking\fluent.py", line 446, in start_run
    active_run_obj = client.create_run(
                     ^^^^^^^^^^^^^^^^^^
  File "C:\Users\ABDULLAH RIZWAN\OneDrive\Desktop\Data Sciences\MLOPS\DataScienceProject\.venv\Lib\site-packages\mlflow\tracking\client.py", line 418, in create_run
    return self._tracking_client.create_run(experiment_id, start_time, tags, run_name)
           ^^^^^^^^^^^^^^^^^^^^^^^^^^^^^^^^^^^^^^^^^^^^^^^^^^^^^^^^^^^^^^^^^^^^^^^^^^^
  File "C:\Users\ABDULLAH RIZWAN\OneDrive\Desktop\Data Sciences\MLOPS\DataScienceProject\.venv\Lib\site-packages\mlflow\tracking\_tracking_service\client.py", line 171, in create_run
    return self.store.create_run(
           ^^^^^^^^^^^^^^^^^^^^^^
  File "C:\Users\ABDULLAH RIZWAN\OneDrive\Desktop\Data Sciences\MLOPS\DataScienceProject\.venv\Lib\site-packages\mlflow\store\tracking\rest_store.py", line 220, in create_run
    response_proto = self._call_endpoint(CreateRun, req_body)
                     ^^^^^^^^^^^^^^^^^^^^^^^^^^^^^^^^^^^^^^^^
  File "C:\Users\ABDULLAH RIZWAN\OneDrive\Desktop\Data Sciences\MLOPS\DataScienceProject\.venv\Lib\site-packages\mlflow\store\tracking\rest_store.py", line 90, in _call_endpoint
    return call_endpoint(self.get_host_creds(), endpoint, method, json_body, response_proto)
           ^^^^^^^^^^^^^^^^^^^^^^^^^^^^^^^^^^^^^^^^^^^^^^^^^^^^^^^^^^^^^^^^^^^^^^^^^^^^^^^^^
  File "C:\Users\ABDULLAH RIZWAN\OneDrive\Desktop\Data Sciences\MLOPS\DataScienceProject\.venv\Lib\site-packages\mlflow\utils\rest_utils.py", line 402, in call_endpoint
    response = verify_rest_response(response, endpoint)
               ^^^^^^^^^^^^^^^^^^^^^^^^^^^^^^^^^^^^^^^^
  File "C:\Users\ABDULLAH RIZWAN\OneDrive\Desktop\Data Sciences\MLOPS\DataScienceProject\.venv\Lib\site-packages\mlflow\utils\rest_utils.py", line 265, in verify_rest_response
    raise MlflowException(
mlflow.exceptions.MlflowException: API request to endpoint /api/2.0/mlflow/runs/create failed with error code 403 != 200. Response body: ''
[2025-08-24 09:11:24,826: INFO: main: >>>>> stage Data Ingestion Stage started >>>>>]
[2025-08-24 09:11:24,834: INFO: common: Yaml file: config\config.yaml is loaded successfully]
[2025-08-24 09:11:24,841: INFO: common: Yaml file: params.yaml is loaded successfully]
[2025-08-24 09:11:24,844: INFO: common: Yaml file: schema.yaml is loaded successfully]
[2025-08-24 09:11:24,845: INFO: common: Directory created at artifacts]
[2025-08-24 09:11:24,847: INFO: common: Directory created at artifacts/data_ingestion]
[2025-08-24 09:11:24,848: INFO: data_ingestion: File already exists]
[2025-08-24 09:11:24,890: INFO: main: >>>>> stage Data Ingestion Stage completed >>>>>]
[2025-08-24 09:11:24,899: INFO: main: Alhumdullillah sb okay h boss!]
[2025-08-24 09:11:24,915: INFO: main: >>>>> stage Data Validation Stage started >>>>>]
[2025-08-24 09:11:24,939: INFO: common: Yaml file: config\config.yaml is loaded successfully]
[2025-08-24 09:11:25,026: INFO: common: Yaml file: params.yaml is loaded successfully]
[2025-08-24 09:11:25,093: INFO: common: Yaml file: schema.yaml is loaded successfully]
[2025-08-24 09:11:25,118: INFO: common: Directory created at artifacts]
[2025-08-24 09:11:25,163: INFO: common: Directory created at artifacts/data_validation]
[2025-08-24 09:11:25,342: INFO: main: >>>>> stage Data Validation Stage completed >>>>>]
[2025-08-24 09:11:25,343: INFO: main: >>>>> stage Data Transformation Stage started >>>>>]
[2025-08-24 09:11:25,374: INFO: common: Yaml file: config\config.yaml is loaded successfully]
[2025-08-24 09:11:25,402: INFO: common: Yaml file: params.yaml is loaded successfully]
[2025-08-24 09:11:25,421: INFO: common: Yaml file: schema.yaml is loaded successfully]
[2025-08-24 09:11:25,425: INFO: common: Directory created at artifacts]
[2025-08-24 09:11:25,429: INFO: common: Directory created at artifacts/data_transformation]
[2025-08-24 09:11:25,613: INFO: data_transformation: Spliting completed]
[2025-08-24 09:11:25,617: INFO: data_transformation: Train shape: (1199, 12)]
[2025-08-24 09:11:25,619: INFO: data_transformation: Test  shape: (400, 12)]
[2025-08-24 09:11:25,622: INFO: main: >>>>> stage Data Transformation Stage completed >>>>>]
[2025-08-24 09:11:25,623: INFO: main: >>>>> stage Model Training Stage started >>>>>]
[2025-08-24 09:11:25,647: INFO: common: Yaml file: config\config.yaml is loaded successfully]
[2025-08-24 09:11:25,661: INFO: common: Yaml file: params.yaml is loaded successfully]
[2025-08-24 09:11:25,681: INFO: common: Yaml file: schema.yaml is loaded successfully]
[2025-08-24 09:11:25,691: INFO: common: Directory created at artifacts]
[2025-08-24 09:11:25,704: INFO: common: Directory created at artifacts/model_trainer]
[2025-08-24 09:11:25,962: INFO: main: >>>>> stage Model Training Stage completed >>>>>]
[2025-08-24 09:11:25,966: INFO: main: >>>>> stage Model Evaluation Stage started >>>>>]
[2025-08-24 09:11:25,986: INFO: common: Yaml file: config\config.yaml is loaded successfully]
[2025-08-24 09:11:26,011: INFO: common: Yaml file: params.yaml is loaded successfully]
[2025-08-24 09:11:26,022: INFO: common: Yaml file: schema.yaml is loaded successfully]
[2025-08-24 09:11:26,027: INFO: common: Directory created at artifacts]
[2025-08-24 09:11:26,030: INFO: common: Directory created at artifacts/model_evaluation]
[2025-08-24 09:11:31,667: ERROR: main: API request to endpoint /api/2.0/mlflow/runs/create failed with error code 403 != 200. Response body: '']
Traceback (most recent call last):
  File "C:\Users\ABDULLAH RIZWAN\OneDrive\Desktop\Data Sciences\MLOPS\DataScienceProject\main.py", line 63, in <module>
    obj.initiate_model_evaluation_pipeline()
  File "C:\Users\ABDULLAH RIZWAN\OneDrive\Desktop\Data Sciences\MLOPS\DataScienceProject\src\DataScienceProject\pipeline\ModelEvaluationPipeline.py", line 16, in initiate_model_evaluation_pipeline
    raise e
  File "C:\Users\ABDULLAH RIZWAN\OneDrive\Desktop\Data Sciences\MLOPS\DataScienceProject\src\DataScienceProject\pipeline\ModelEvaluationPipeline.py", line 14, in initiate_model_evaluation_pipeline
    model_evaluation.log_into_mlflow()
  File "C:\Users\ABDULLAH RIZWAN\OneDrive\Desktop\Data Sciences\MLOPS\DataScienceProject\src\DataScienceProject\components\model_evaluation.py", line 36, in log_into_mlflow
    with mlflow.start_run():
         ^^^^^^^^^^^^^^^^^^
  File "C:\Users\ABDULLAH RIZWAN\OneDrive\Desktop\Data Sciences\MLOPS\DataScienceProject\.venv\Lib\site-packages\mlflow\tracking\fluent.py", line 446, in start_run
    active_run_obj = client.create_run(
                     ^^^^^^^^^^^^^^^^^^
  File "C:\Users\ABDULLAH RIZWAN\OneDrive\Desktop\Data Sciences\MLOPS\DataScienceProject\.venv\Lib\site-packages\mlflow\tracking\client.py", line 418, in create_run
    return self._tracking_client.create_run(experiment_id, start_time, tags, run_name)
           ^^^^^^^^^^^^^^^^^^^^^^^^^^^^^^^^^^^^^^^^^^^^^^^^^^^^^^^^^^^^^^^^^^^^^^^^^^^
  File "C:\Users\ABDULLAH RIZWAN\OneDrive\Desktop\Data Sciences\MLOPS\DataScienceProject\.venv\Lib\site-packages\mlflow\tracking\_tracking_service\client.py", line 171, in create_run
    return self.store.create_run(
           ^^^^^^^^^^^^^^^^^^^^^^
  File "C:\Users\ABDULLAH RIZWAN\OneDrive\Desktop\Data Sciences\MLOPS\DataScienceProject\.venv\Lib\site-packages\mlflow\store\tracking\rest_store.py", line 220, in create_run
    response_proto = self._call_endpoint(CreateRun, req_body)
                     ^^^^^^^^^^^^^^^^^^^^^^^^^^^^^^^^^^^^^^^^
  File "C:\Users\ABDULLAH RIZWAN\OneDrive\Desktop\Data Sciences\MLOPS\DataScienceProject\.venv\Lib\site-packages\mlflow\store\tracking\rest_store.py", line 90, in _call_endpoint
    return call_endpoint(self.get_host_creds(), endpoint, method, json_body, response_proto)
           ^^^^^^^^^^^^^^^^^^^^^^^^^^^^^^^^^^^^^^^^^^^^^^^^^^^^^^^^^^^^^^^^^^^^^^^^^^^^^^^^^
  File "C:\Users\ABDULLAH RIZWAN\OneDrive\Desktop\Data Sciences\MLOPS\DataScienceProject\.venv\Lib\site-packages\mlflow\utils\rest_utils.py", line 402, in call_endpoint
    response = verify_rest_response(response, endpoint)
               ^^^^^^^^^^^^^^^^^^^^^^^^^^^^^^^^^^^^^^^^
  File "C:\Users\ABDULLAH RIZWAN\OneDrive\Desktop\Data Sciences\MLOPS\DataScienceProject\.venv\Lib\site-packages\mlflow\utils\rest_utils.py", line 265, in verify_rest_response
    raise MlflowException(
mlflow.exceptions.MlflowException: API request to endpoint /api/2.0/mlflow/runs/create failed with error code 403 != 200. Response body: ''
[2025-08-24 09:16:46,329: INFO: main: >>>>> stage Data Ingestion Stage started >>>>>]
[2025-08-24 09:16:46,339: INFO: common: Yaml file: config\config.yaml is loaded successfully]
[2025-08-24 09:16:46,346: INFO: common: Yaml file: params.yaml is loaded successfully]
[2025-08-24 09:16:46,353: INFO: common: Yaml file: schema.yaml is loaded successfully]
[2025-08-24 09:16:46,355: INFO: common: Directory created at artifacts]
[2025-08-24 09:16:46,357: INFO: common: Directory created at artifacts/data_ingestion]
[2025-08-24 09:16:46,357: INFO: data_ingestion: File already exists]
[2025-08-24 09:16:46,380: INFO: main: >>>>> stage Data Ingestion Stage completed >>>>>]
[2025-08-24 09:16:46,381: INFO: main: Alhumdullillah sb okay h boss!]
[2025-08-24 09:16:46,383: INFO: main: >>>>> stage Data Validation Stage started >>>>>]
[2025-08-24 09:16:46,406: INFO: common: Yaml file: config\config.yaml is loaded successfully]
[2025-08-24 09:16:46,413: INFO: common: Yaml file: params.yaml is loaded successfully]
[2025-08-24 09:16:46,432: INFO: common: Yaml file: schema.yaml is loaded successfully]
[2025-08-24 09:16:46,437: INFO: common: Directory created at artifacts]
[2025-08-24 09:16:46,442: INFO: common: Directory created at artifacts/data_validation]
[2025-08-24 09:16:46,550: INFO: main: >>>>> stage Data Validation Stage completed >>>>>]
[2025-08-24 09:16:46,557: INFO: main: >>>>> stage Data Transformation Stage started >>>>>]
[2025-08-24 09:16:46,570: INFO: common: Yaml file: config\config.yaml is loaded successfully]
[2025-08-24 09:16:46,575: INFO: common: Yaml file: params.yaml is loaded successfully]
[2025-08-24 09:16:46,582: INFO: common: Yaml file: schema.yaml is loaded successfully]
[2025-08-24 09:16:46,587: INFO: common: Directory created at artifacts]
[2025-08-24 09:16:46,589: INFO: common: Directory created at artifacts/data_transformation]
[2025-08-24 09:16:46,720: INFO: data_transformation: Spliting completed]
[2025-08-24 09:16:46,721: INFO: data_transformation: Train shape: (1199, 12)]
[2025-08-24 09:16:46,722: INFO: data_transformation: Test  shape: (400, 12)]
[2025-08-24 09:16:46,723: INFO: main: >>>>> stage Data Transformation Stage completed >>>>>]
[2025-08-24 09:16:46,724: INFO: main: >>>>> stage Model Training Stage started >>>>>]
[2025-08-24 09:16:46,731: INFO: common: Yaml file: config\config.yaml is loaded successfully]
[2025-08-24 09:16:46,734: INFO: common: Yaml file: params.yaml is loaded successfully]
[2025-08-24 09:16:46,738: INFO: common: Yaml file: schema.yaml is loaded successfully]
[2025-08-24 09:16:46,741: INFO: common: Directory created at artifacts]
[2025-08-24 09:16:46,744: INFO: common: Directory created at artifacts/model_trainer]
[2025-08-24 09:16:46,862: INFO: main: >>>>> stage Model Training Stage completed >>>>>]
[2025-08-24 09:16:46,863: INFO: main: >>>>> stage Model Evaluation Stage started >>>>>]
[2025-08-24 09:16:46,871: INFO: common: Yaml file: config\config.yaml is loaded successfully]
[2025-08-24 09:16:46,879: INFO: common: Yaml file: params.yaml is loaded successfully]
[2025-08-24 09:16:46,890: INFO: common: Yaml file: schema.yaml is loaded successfully]
[2025-08-24 09:16:46,901: INFO: common: Directory created at artifacts]
[2025-08-24 09:16:46,909: INFO: common: Directory created at artifacts/model_evaluation]
[2025-08-24 09:16:51,242: ERROR: main: API request to endpoint /api/2.0/mlflow/runs/create failed with error code 403 != 200. Response body: '']
Traceback (most recent call last):
  File "C:\Users\ABDULLAH RIZWAN\OneDrive\Desktop\Data Sciences\MLOPS\DataScienceProject\main.py", line 63, in <module>
    obj.initiate_model_evaluation_pipeline()
  File "C:\Users\ABDULLAH RIZWAN\OneDrive\Desktop\Data Sciences\MLOPS\DataScienceProject\src\DataScienceProject\pipeline\ModelEvaluationPipeline.py", line 16, in initiate_model_evaluation_pipeline
    raise e
  File "C:\Users\ABDULLAH RIZWAN\OneDrive\Desktop\Data Sciences\MLOPS\DataScienceProject\src\DataScienceProject\pipeline\ModelEvaluationPipeline.py", line 14, in initiate_model_evaluation_pipeline
    model_evaluation.log_into_mlflow()
  File "C:\Users\ABDULLAH RIZWAN\OneDrive\Desktop\Data Sciences\MLOPS\DataScienceProject\src\DataScienceProject\components\model_evaluation.py", line 36, in log_into_mlflow
    with mlflow.start_run():
         ^^^^^^^^^^^^^^^^^^
  File "C:\Users\ABDULLAH RIZWAN\OneDrive\Desktop\Data Sciences\MLOPS\DataScienceProject\.venv\Lib\site-packages\mlflow\tracking\fluent.py", line 446, in start_run
    active_run_obj = client.create_run(
                     ^^^^^^^^^^^^^^^^^^
  File "C:\Users\ABDULLAH RIZWAN\OneDrive\Desktop\Data Sciences\MLOPS\DataScienceProject\.venv\Lib\site-packages\mlflow\tracking\client.py", line 418, in create_run
    return self._tracking_client.create_run(experiment_id, start_time, tags, run_name)
           ^^^^^^^^^^^^^^^^^^^^^^^^^^^^^^^^^^^^^^^^^^^^^^^^^^^^^^^^^^^^^^^^^^^^^^^^^^^
  File "C:\Users\ABDULLAH RIZWAN\OneDrive\Desktop\Data Sciences\MLOPS\DataScienceProject\.venv\Lib\site-packages\mlflow\tracking\_tracking_service\client.py", line 171, in create_run
    return self.store.create_run(
           ^^^^^^^^^^^^^^^^^^^^^^
  File "C:\Users\ABDULLAH RIZWAN\OneDrive\Desktop\Data Sciences\MLOPS\DataScienceProject\.venv\Lib\site-packages\mlflow\store\tracking\rest_store.py", line 220, in create_run
    response_proto = self._call_endpoint(CreateRun, req_body)
                     ^^^^^^^^^^^^^^^^^^^^^^^^^^^^^^^^^^^^^^^^
  File "C:\Users\ABDULLAH RIZWAN\OneDrive\Desktop\Data Sciences\MLOPS\DataScienceProject\.venv\Lib\site-packages\mlflow\store\tracking\rest_store.py", line 90, in _call_endpoint
    return call_endpoint(self.get_host_creds(), endpoint, method, json_body, response_proto)
           ^^^^^^^^^^^^^^^^^^^^^^^^^^^^^^^^^^^^^^^^^^^^^^^^^^^^^^^^^^^^^^^^^^^^^^^^^^^^^^^^^
  File "C:\Users\ABDULLAH RIZWAN\OneDrive\Desktop\Data Sciences\MLOPS\DataScienceProject\.venv\Lib\site-packages\mlflow\utils\rest_utils.py", line 402, in call_endpoint
    response = verify_rest_response(response, endpoint)
               ^^^^^^^^^^^^^^^^^^^^^^^^^^^^^^^^^^^^^^^^
  File "C:\Users\ABDULLAH RIZWAN\OneDrive\Desktop\Data Sciences\MLOPS\DataScienceProject\.venv\Lib\site-packages\mlflow\utils\rest_utils.py", line 265, in verify_rest_response
    raise MlflowException(
mlflow.exceptions.MlflowException: API request to endpoint /api/2.0/mlflow/runs/create failed with error code 403 != 200. Response body: ''
